[2025-09-03 15:51:31] [ERROR] [django.request] Internal Server Error: /api/auth/refresh/
Traceback (most recent call last):
  File "C:\Users\HP\Desktop\projects\safeNetAi\backend\venv\Lib\site-packages\django\core\handlers\exception.py", line 55, in inner
    response = get_response(request)
               ^^^^^^^^^^^^^^^^^^^^^
  File "C:\Users\HP\Desktop\projects\safeNetAi\backend\venv\Lib\site-packages\django\core\handlers\base.py", line 197, in _get_response
    response = wrapped_callback(request, *callback_args, **callback_kwargs)
               ^^^^^^^^^^^^^^^^^^^^^^^^^^^^^^^^^^^^^^^^^^^^^^^^^^^^^^^^^^^^
  File "C:\Users\HP\Desktop\projects\safeNetAi\backend\venv\Lib\site-packages\django\views\decorators\csrf.py", line 65, in _view_wrapper
    return view_func(request, *args, **kwargs)
           ^^^^^^^^^^^^^^^^^^^^^^^^^^^^^^^^^^^
  File "C:\Users\HP\Desktop\projects\safeNetAi\backend\venv\Lib\site-packages\django\views\generic\base.py", line 105, in view
    return self.dispatch(request, *args, **kwargs)
           ^^^^^^^^^^^^^^^^^^^^^^^^^^^^^^^^^^^^^^^
  File "C:\Users\HP\Desktop\projects\safeNetAi\backend\venv\Lib\site-packages\rest_framework\views.py", line 515, in dispatch
    response = self.handle_exception(exc)
               ^^^^^^^^^^^^^^^^^^^^^^^^^^
  File "C:\Users\HP\Desktop\projects\safeNetAi\backend\venv\Lib\site-packages\rest_framework\views.py", line 475, in handle_exception
    self.raise_uncaught_exception(exc)
  File "C:\Users\HP\Desktop\projects\safeNetAi\backend\venv\Lib\site-packages\rest_framework\views.py", line 486, in raise_uncaught_exception
    raise exc
  File "C:\Users\HP\Desktop\projects\safeNetAi\backend\venv\Lib\site-packages\rest_framework\views.py", line 512, in dispatch
    response = handler(request, *args, **kwargs)
               ^^^^^^^^^^^^^^^^^^^^^^^^^^^^^^^^^
  File "C:\Users\HP\Desktop\projects\safeNetAi\backend\venv\Lib\site-packages\rest_framework_simplejwt\views.py", line 46, in post
    serializer.is_valid(raise_exception=True)
  File "C:\Users\HP\Desktop\projects\safeNetAi\backend\venv\Lib\site-packages\rest_framework\serializers.py", line 225, in is_valid
    self._validated_data = self.run_validation(self.initial_data)
                           ^^^^^^^^^^^^^^^^^^^^^^^^^^^^^^^^^^^^^^
  File "C:\Users\HP\Desktop\projects\safeNetAi\backend\venv\Lib\site-packages\rest_framework\serializers.py", line 447, in run_validation
    value = self.validate(value)
            ^^^^^^^^^^^^^^^^^^^^
  File "C:\Users\HP\Desktop\projects\safeNetAi\backend\venv\Lib\site-packages\rest_framework_simplejwt\serializers.py", line 116, in validate
    user := get_user_model().objects.get(
            ^^^^^^^^^^^^^^^^^^^^^^^^^^^^^
  File "C:\Users\HP\Desktop\projects\safeNetAi\backend\venv\Lib\site-packages\django\db\models\manager.py", line 87, in manager_method
    return getattr(self.get_queryset(), name)(*args, **kwargs)
           ^^^^^^^^^^^^^^^^^^^^^^^^^^^^^^^^^^^^^^^^^^^^^^^^^^^
  File "C:\Users\HP\Desktop\projects\safeNetAi\backend\venv\Lib\site-packages\django\db\models\query.py", line 633, in get
    raise self.model.DoesNotExist(
apps.users.models.User.DoesNotExist: User matching query does not exist.
[2025-09-03 15:51:31] [ERROR] [django.server] "POST /api/auth/refresh/ HTTP/1.1" 500 134297
[2025-09-03 16:35:03] [CRITICAL] [rules] MANDATORY OTP REQUIRED: Distance-based fraud detection triggered for transaction 300
[2025-09-03 16:35:03] [CRITICAL] [rules] Distance-based OTP enforcement: Transaction 300 requires mandatory OTP
[2025-09-03 16:35:03] [CRITICAL] [rules] MANDATORY OTP REQUIRED: Distance-based fraud detection triggered for transaction 300
[2025-09-03 16:35:03] [CRITICAL] [rules] Distance-based OTP enforcement: Transaction 300 requires mandatory OTP
[2025-09-03 17:08:45] [ERROR] [transactions] Error creating transaction: cannot access local variable 'requires_otp' where it is not associated with a value
[2025-09-03 17:08:45] [ERROR] [django.request] Internal Server Error: /api/client/transactions/
[2025-09-03 17:08:45] [ERROR] [django.server] "POST /api/client/transactions/ HTTP/1.1" 500 39
[2025-09-03 17:09:45] [ERROR] [transactions] Error creating transaction: cannot access local variable 'requires_otp' where it is not associated with a value
[2025-09-03 17:09:45] [ERROR] [django.request] Internal Server Error: /api/client/transactions/
[2025-09-03 17:09:45] [ERROR] [django.server] "POST /api/client/transactions/ HTTP/1.1" 500 39
