[2025-09-04 13:56:33] [CRITICAL] [rules] MANDATORY OTP REQUIRED: Enhanced distance-based fraud detection triggered for transaction 315 - Location 66.70km from HOME exceeds 50.0km threshold
[2025-09-04 13:56:33] [CRITICAL] [rules] MANDATORY OTP REQUIRED: Enhanced distance-based fraud detection triggered for transaction 315 - Location 66.70km from HOME exceeds 50.0km threshold
[2025-09-04 13:59:13] [CRITICAL] [rules] MANDATORY OTP REQUIRED: Enhanced distance-based fraud detection triggered for transaction 316 - Location 66.70km from HOME exceeds 50.0km threshold
[2025-09-04 13:59:13] [CRITICAL] [rules] MANDATORY OTP REQUIRED: Enhanced distance-based fraud detection triggered for transaction 316 - Location 66.70km from HOME exceeds 50.0km threshold
[2025-09-04 14:01:00] [CRITICAL] [rules] MANDATORY OTP REQUIRED: Enhanced distance-based fraud detection triggered for transaction 317 - Location 66.70km from HOME exceeds 50.0km threshold
[2025-09-04 14:01:00] [CRITICAL] [rules] MANDATORY OTP REQUIRED: Enhanced distance-based fraud detection triggered for transaction 317 - Location 66.70km from HOME exceeds 50.0km threshold
[2025-09-04 14:31:20] [ERROR] [django.request] Internal Server Error: /api/auth/refresh/
Traceback (most recent call last):
  File "C:\Users\HP\Desktop\projects\safeNetAi\backend\venv\Lib\site-packages\django\core\handlers\exception.py", line 55, in inner
    response = get_response(request)
               ^^^^^^^^^^^^^^^^^^^^^
  File "C:\Users\HP\Desktop\projects\safeNetAi\backend\venv\Lib\site-packages\django\core\handlers\base.py", line 197, in _get_response
    response = wrapped_callback(request, *callback_args, **callback_kwargs)
               ^^^^^^^^^^^^^^^^^^^^^^^^^^^^^^^^^^^^^^^^^^^^^^^^^^^^^^^^^^^^
  File "C:\Users\HP\Desktop\projects\safeNetAi\backend\venv\Lib\site-packages\django\views\decorators\csrf.py", line 65, in _view_wrapper
    return view_func(request, *args, **kwargs)
           ^^^^^^^^^^^^^^^^^^^^^^^^^^^^^^^^^^^
  File "C:\Users\HP\Desktop\projects\safeNetAi\backend\venv\Lib\site-packages\django\views\generic\base.py", line 105, in view
    return self.dispatch(request, *args, **kwargs)
           ^^^^^^^^^^^^^^^^^^^^^^^^^^^^^^^^^^^^^^^
  File "C:\Users\HP\Desktop\projects\safeNetAi\backend\venv\Lib\site-packages\rest_framework\views.py", line 515, in dispatch
    response = self.handle_exception(exc)
               ^^^^^^^^^^^^^^^^^^^^^^^^^^
  File "C:\Users\HP\Desktop\projects\safeNetAi\backend\venv\Lib\site-packages\rest_framework\views.py", line 475, in handle_exception
    self.raise_uncaught_exception(exc)
  File "C:\Users\HP\Desktop\projects\safeNetAi\backend\venv\Lib\site-packages\rest_framework\views.py", line 486, in raise_uncaught_exception
    raise exc
  File "C:\Users\HP\Desktop\projects\safeNetAi\backend\venv\Lib\site-packages\rest_framework\views.py", line 512, in dispatch
    response = handler(request, *args, **kwargs)
               ^^^^^^^^^^^^^^^^^^^^^^^^^^^^^^^^^
  File "C:\Users\HP\Desktop\projects\safeNetAi\backend\venv\Lib\site-packages\rest_framework_simplejwt\views.py", line 46, in post
    serializer.is_valid(raise_exception=True)
  File "C:\Users\HP\Desktop\projects\safeNetAi\backend\venv\Lib\site-packages\rest_framework\serializers.py", line 225, in is_valid
    self._validated_data = self.run_validation(self.initial_data)
                           ^^^^^^^^^^^^^^^^^^^^^^^^^^^^^^^^^^^^^^
  File "C:\Users\HP\Desktop\projects\safeNetAi\backend\venv\Lib\site-packages\rest_framework\serializers.py", line 447, in run_validation
    value = self.validate(value)
            ^^^^^^^^^^^^^^^^^^^^
  File "C:\Users\HP\Desktop\projects\safeNetAi\backend\venv\Lib\site-packages\rest_framework_simplejwt\serializers.py", line 116, in validate
    user := get_user_model().objects.get(
            ^^^^^^^^^^^^^^^^^^^^^^^^^^^^^
  File "C:\Users\HP\Desktop\projects\safeNetAi\backend\venv\Lib\site-packages\django\db\models\manager.py", line 87, in manager_method
    return getattr(self.get_queryset(), name)(*args, **kwargs)
           ^^^^^^^^^^^^^^^^^^^^^^^^^^^^^^^^^^^^^^^^^^^^^^^^^^^
  File "C:\Users\HP\Desktop\projects\safeNetAi\backend\venv\Lib\site-packages\django\db\models\query.py", line 633, in get
    raise self.model.DoesNotExist(
apps.users.models.User.DoesNotExist: User matching query does not exist.
[2025-09-04 14:31:20] [ERROR] [django.server] "POST /api/auth/refresh/ HTTP/1.1" 500 134465
[2025-09-04 14:31:20] [ERROR] [django.request] Internal Server Error: /api/auth/refresh/
Traceback (most recent call last):
  File "C:\Users\HP\Desktop\projects\safeNetAi\backend\venv\Lib\site-packages\django\core\handlers\exception.py", line 55, in inner
    response = get_response(request)
               ^^^^^^^^^^^^^^^^^^^^^
  File "C:\Users\HP\Desktop\projects\safeNetAi\backend\venv\Lib\site-packages\django\core\handlers\base.py", line 197, in _get_response
    response = wrapped_callback(request, *callback_args, **callback_kwargs)
               ^^^^^^^^^^^^^^^^^^^^^^^^^^^^^^^^^^^^^^^^^^^^^^^^^^^^^^^^^^^^
  File "C:\Users\HP\Desktop\projects\safeNetAi\backend\venv\Lib\site-packages\django\views\decorators\csrf.py", line 65, in _view_wrapper
    return view_func(request, *args, **kwargs)
           ^^^^^^^^^^^^^^^^^^^^^^^^^^^^^^^^^^^
  File "C:\Users\HP\Desktop\projects\safeNetAi\backend\venv\Lib\site-packages\django\views\generic\base.py", line 105, in view
    return self.dispatch(request, *args, **kwargs)
           ^^^^^^^^^^^^^^^^^^^^^^^^^^^^^^^^^^^^^^^
  File "C:\Users\HP\Desktop\projects\safeNetAi\backend\venv\Lib\site-packages\rest_framework\views.py", line 515, in dispatch
    response = self.handle_exception(exc)
               ^^^^^^^^^^^^^^^^^^^^^^^^^^
  File "C:\Users\HP\Desktop\projects\safeNetAi\backend\venv\Lib\site-packages\rest_framework\views.py", line 475, in handle_exception
    self.raise_uncaught_exception(exc)
  File "C:\Users\HP\Desktop\projects\safeNetAi\backend\venv\Lib\site-packages\rest_framework\views.py", line 486, in raise_uncaught_exception
    raise exc
  File "C:\Users\HP\Desktop\projects\safeNetAi\backend\venv\Lib\site-packages\rest_framework\views.py", line 512, in dispatch
    response = handler(request, *args, **kwargs)
               ^^^^^^^^^^^^^^^^^^^^^^^^^^^^^^^^^
  File "C:\Users\HP\Desktop\projects\safeNetAi\backend\venv\Lib\site-packages\rest_framework_simplejwt\views.py", line 46, in post
    serializer.is_valid(raise_exception=True)
  File "C:\Users\HP\Desktop\projects\safeNetAi\backend\venv\Lib\site-packages\rest_framework\serializers.py", line 225, in is_valid
    self._validated_data = self.run_validation(self.initial_data)
                           ^^^^^^^^^^^^^^^^^^^^^^^^^^^^^^^^^^^^^^
  File "C:\Users\HP\Desktop\projects\safeNetAi\backend\venv\Lib\site-packages\rest_framework\serializers.py", line 447, in run_validation
    value = self.validate(value)
            ^^^^^^^^^^^^^^^^^^^^
  File "C:\Users\HP\Desktop\projects\safeNetAi\backend\venv\Lib\site-packages\rest_framework_simplejwt\serializers.py", line 116, in validate
    user := get_user_model().objects.get(
            ^^^^^^^^^^^^^^^^^^^^^^^^^^^^^
  File "C:\Users\HP\Desktop\projects\safeNetAi\backend\venv\Lib\site-packages\django\db\models\manager.py", line 87, in manager_method
    return getattr(self.get_queryset(), name)(*args, **kwargs)
           ^^^^^^^^^^^^^^^^^^^^^^^^^^^^^^^^^^^^^^^^^^^^^^^^^^^
  File "C:\Users\HP\Desktop\projects\safeNetAi\backend\venv\Lib\site-packages\django\db\models\query.py", line 633, in get
    raise self.model.DoesNotExist(
apps.users.models.User.DoesNotExist: User matching query does not exist.
[2025-09-04 14:31:20] [ERROR] [django.server] "POST /api/auth/refresh/ HTTP/1.1" 500 134465
[2025-09-04 14:31:20] [ERROR] [django.request] Internal Server Error: /api/auth/refresh/
Traceback (most recent call last):
  File "C:\Users\HP\Desktop\projects\safeNetAi\backend\venv\Lib\site-packages\django\core\handlers\exception.py", line 55, in inner
    response = get_response(request)
               ^^^^^^^^^^^^^^^^^^^^^
  File "C:\Users\HP\Desktop\projects\safeNetAi\backend\venv\Lib\site-packages\django\core\handlers\base.py", line 197, in _get_response
    response = wrapped_callback(request, *callback_args, **callback_kwargs)
               ^^^^^^^^^^^^^^^^^^^^^^^^^^^^^^^^^^^^^^^^^^^^^^^^^^^^^^^^^^^^
  File "C:\Users\HP\Desktop\projects\safeNetAi\backend\venv\Lib\site-packages\django\views\decorators\csrf.py", line 65, in _view_wrapper
    return view_func(request, *args, **kwargs)
           ^^^^^^^^^^^^^^^^^^^^^^^^^^^^^^^^^^^
  File "C:\Users\HP\Desktop\projects\safeNetAi\backend\venv\Lib\site-packages\django\views\generic\base.py", line 105, in view
    return self.dispatch(request, *args, **kwargs)
           ^^^^^^^^^^^^^^^^^^^^^^^^^^^^^^^^^^^^^^^
  File "C:\Users\HP\Desktop\projects\safeNetAi\backend\venv\Lib\site-packages\rest_framework\views.py", line 515, in dispatch
    response = self.handle_exception(exc)
               ^^^^^^^^^^^^^^^^^^^^^^^^^^
  File "C:\Users\HP\Desktop\projects\safeNetAi\backend\venv\Lib\site-packages\rest_framework\views.py", line 475, in handle_exception
    self.raise_uncaught_exception(exc)
  File "C:\Users\HP\Desktop\projects\safeNetAi\backend\venv\Lib\site-packages\rest_framework\views.py", line 486, in raise_uncaught_exception
    raise exc
  File "C:\Users\HP\Desktop\projects\safeNetAi\backend\venv\Lib\site-packages\rest_framework\views.py", line 512, in dispatch
    response = handler(request, *args, **kwargs)
               ^^^^^^^^^^^^^^^^^^^^^^^^^^^^^^^^^
  File "C:\Users\HP\Desktop\projects\safeNetAi\backend\venv\Lib\site-packages\rest_framework_simplejwt\views.py", line 46, in post
    serializer.is_valid(raise_exception=True)
  File "C:\Users\HP\Desktop\projects\safeNetAi\backend\venv\Lib\site-packages\rest_framework\serializers.py", line 225, in is_valid
    self._validated_data = self.run_validation(self.initial_data)
                           ^^^^^^^^^^^^^^^^^^^^^^^^^^^^^^^^^^^^^^
  File "C:\Users\HP\Desktop\projects\safeNetAi\backend\venv\Lib\site-packages\rest_framework\serializers.py", line 447, in run_validation
    value = self.validate(value)
            ^^^^^^^^^^^^^^^^^^^^
  File "C:\Users\HP\Desktop\projects\safeNetAi\backend\venv\Lib\site-packages\rest_framework_simplejwt\serializers.py", line 116, in validate
    user := get_user_model().objects.get(
            ^^^^^^^^^^^^^^^^^^^^^^^^^^^^^
  File "C:\Users\HP\Desktop\projects\safeNetAi\backend\venv\Lib\site-packages\django\db\models\manager.py", line 87, in manager_method
    return getattr(self.get_queryset(), name)(*args, **kwargs)
           ^^^^^^^^^^^^^^^^^^^^^^^^^^^^^^^^^^^^^^^^^^^^^^^^^^^
  File "C:\Users\HP\Desktop\projects\safeNetAi\backend\venv\Lib\site-packages\django\db\models\query.py", line 633, in get
    raise self.model.DoesNotExist(
apps.users.models.User.DoesNotExist: User matching query does not exist.
[2025-09-04 14:37:44] [ERROR] [ai] Error making ML prediction for transaction 318: X has 9 features, but StandardScaler is expecting 7 features as input.
[2025-09-04 14:37:44] [ERROR] [system] System event: Error making ML prediction | Component: fraud_ml_model | Severity: ERROR | Data: {"transaction_id": 318, "error": "X has 9 features, but StandardScaler is expecting 7 features as input."}
[2025-09-04 14:39:55] [CRITICAL] [rules] 🔐 MANDATORY OTP REQUIRED: Effective distance 159.83km exceeds 50.0km threshold for transaction 319
[2025-09-04 14:39:55] [CRITICAL] [rules] 🔐 Effective distance-based OTP enforcement: Transaction 319 requires mandatory OTP
[2025-09-04 14:39:55] [CRITICAL] [rules] 🔐 MANDATORY OTP REQUIRED: Effective distance 159.83km exceeds 50.0km threshold for transaction 319
[2025-09-04 14:39:55] [CRITICAL] [rules] 🔐 Effective distance-based OTP enforcement: Transaction 319 requires mandatory OTP
[2025-09-04 14:39:56] [ERROR] [ai] Error making ML prediction for transaction 319: X has 9 features, but StandardScaler is expecting 7 features as input.
[2025-09-04 14:39:56] [ERROR] [system] System event: Error making ML prediction | Component: fraud_ml_model | Severity: ERROR | Data: {"transaction_id": 319, "error": "X has 9 features, but StandardScaler is expecting 7 features as input."}
[2025-09-04 14:42:00] [CRITICAL] [rules] 🔐 MANDATORY OTP REQUIRED: Effective distance 159.83km exceeds 60.0km threshold for transaction 320
[2025-09-04 14:42:00] [CRITICAL] [rules] 🔐 Effective distance-based OTP enforcement: Transaction 320 requires mandatory OTP
[2025-09-04 14:42:00] [CRITICAL] [rules] 🔐 MANDATORY OTP REQUIRED: Effective distance 159.83km exceeds 60.0km threshold for transaction 320
[2025-09-04 14:42:00] [CRITICAL] [rules] 🔐 Effective distance-based OTP enforcement: Transaction 320 requires mandatory OTP
[2025-09-04 14:42:00] [ERROR] [ai] Error making ML prediction for transaction 320: X has 9 features, but StandardScaler is expecting 7 features as input.
[2025-09-04 14:42:00] [ERROR] [system] System event: Error making ML prediction | Component: fraud_ml_model | Severity: ERROR | Data: {"transaction_id": 320, "error": "X has 9 features, but StandardScaler is expecting 7 features as input."}
[2025-09-04 14:43:20] [CRITICAL] [rules] 🔐 MANDATORY OTP REQUIRED: Effective distance 159.83km exceeds 60.0km threshold for transaction 321
[2025-09-04 14:43:20] [CRITICAL] [rules] 🔐 Effective distance-based OTP enforcement: Transaction 321 requires mandatory OTP
[2025-09-04 14:43:20] [CRITICAL] [rules] 🔐 MANDATORY OTP REQUIRED: Effective distance 159.83km exceeds 60.0km threshold for transaction 321
[2025-09-04 14:43:20] [CRITICAL] [rules] 🔐 Effective distance-based OTP enforcement: Transaction 321 requires mandatory OTP
[2025-09-04 14:43:20] [ERROR] [ai] Error making ML prediction for transaction 321: X has 9 features, but StandardScaler is expecting 7 features as input.
[2025-09-04 14:43:20] [ERROR] [system] System event: Error making ML prediction | Component: fraud_ml_model | Severity: ERROR | Data: {"transaction_id": 321, "error": "X has 9 features, but StandardScaler is expecting 7 features as input."}
[2025-09-04 15:49:12] [ERROR] [django.request] Internal Server Error: /api/client/transactions/
Traceback (most recent call last):
  File "C:\Users\HP\Desktop\projects\safeNetAi\backend\venv\Lib\site-packages\django\db\backends\utils.py", line 105, in _execute
    return self.cursor.execute(sql, params)
           ^^^^^^^^^^^^^^^^^^^^^^^^^^^^^^^^
  File "C:\Users\HP\Desktop\projects\safeNetAi\backend\venv\Lib\site-packages\django\db\backends\sqlite3\base.py", line 360, in execute
    return super().execute(query, params)
           ^^^^^^^^^^^^^^^^^^^^^^^^^^^^^^
sqlite3.OperationalError: no such column: transactions_transaction.current_lat

The above exception was the direct cause of the following exception:

Traceback (most recent call last):
  File "C:\Users\HP\Desktop\projects\safeNetAi\backend\venv\Lib\site-packages\django\core\handlers\exception.py", line 55, in inner
    response = get_response(request)
               ^^^^^^^^^^^^^^^^^^^^^
  File "C:\Users\HP\Desktop\projects\safeNetAi\backend\venv\Lib\site-packages\django\core\handlers\base.py", line 197, in _get_response
    response = wrapped_callback(request, *callback_args, **callback_kwargs)
               ^^^^^^^^^^^^^^^^^^^^^^^^^^^^^^^^^^^^^^^^^^^^^^^^^^^^^^^^^^^^
  File "C:\Users\HP\Desktop\projects\safeNetAi\backend\venv\Lib\site-packages\django\views\decorators\csrf.py", line 65, in _view_wrapper
    return view_func(request, *args, **kwargs)
           ^^^^^^^^^^^^^^^^^^^^^^^^^^^^^^^^^^^
  File "C:\Users\HP\Desktop\projects\safeNetAi\backend\venv\Lib\site-packages\rest_framework\viewsets.py", line 125, in view
    return self.dispatch(request, *args, **kwargs)
           ^^^^^^^^^^^^^^^^^^^^^^^^^^^^^^^^^^^^^^^
  File "C:\Users\HP\Desktop\projects\safeNetAi\backend\venv\Lib\site-packages\rest_framework\views.py", line 515, in dispatch
    response = self.handle_exception(exc)
               ^^^^^^^^^^^^^^^^^^^^^^^^^^
  File "C:\Users\HP\Desktop\projects\safeNetAi\backend\venv\Lib\site-packages\rest_framework\views.py", line 475, in handle_exception
    self.raise_uncaught_exception(exc)
  File "C:\Users\HP\Desktop\projects\safeNetAi\backend\venv\Lib\site-packages\rest_framework\views.py", line 486, in raise_uncaught_exception
    raise exc
  File "C:\Users\HP\Desktop\projects\safeNetAi\backend\venv\Lib\site-packages\rest_framework\views.py", line 512, in dispatch
    response = handler(request, *args, **kwargs)
               ^^^^^^^^^^^^^^^^^^^^^^^^^^^^^^^^^
  File "C:\Users\HP\Desktop\projects\safeNetAi\backend\venv\Lib\site-packages\rest_framework\mixins.py", line 46, in list
    return Response(serializer.data)
                    ^^^^^^^^^^^^^^^
  File "C:\Users\HP\Desktop\projects\safeNetAi\backend\venv\Lib\site-packages\rest_framework\serializers.py", line 797, in data
    ret = super().data
          ^^^^^^^^^^^^
  File "C:\Users\HP\Desktop\projects\safeNetAi\backend\venv\Lib\site-packages\rest_framework\serializers.py", line 251, in data
    self._data = self.to_representation(self.instance)
                 ^^^^^^^^^^^^^^^^^^^^^^^^^^^^^^^^^^^^^
  File "C:\Users\HP\Desktop\projects\safeNetAi\backend\venv\Lib\site-packages\rest_framework\serializers.py", line 715, in to_representation
    return [
           ^
  File "C:\Users\HP\Desktop\projects\safeNetAi\backend\venv\Lib\site-packages\django\db\models\query.py", line 384, in __iter__
    self._fetch_all()
  File "C:\Users\HP\Desktop\projects\safeNetAi\backend\venv\Lib\site-packages\django\db\models\query.py", line 1949, in _fetch_all
    self._result_cache = list(self._iterable_class(self))
                         ^^^^^^^^^^^^^^^^^^^^^^^^^^^^^^^^
  File "C:\Users\HP\Desktop\projects\safeNetAi\backend\venv\Lib\site-packages\django\db\models\query.py", line 91, in __iter__
    results = compiler.execute_sql(
              ^^^^^^^^^^^^^^^^^^^^^
  File "C:\Users\HP\Desktop\projects\safeNetAi\backend\venv\Lib\site-packages\django\db\models\sql\compiler.py", line 1623, in execute_sql
    cursor.execute(sql, params)
  File "C:\Users\HP\Desktop\projects\safeNetAi\backend\venv\Lib\site-packages\django\db\backends\utils.py", line 122, in execute
    return super().execute(sql, params)
           ^^^^^^^^^^^^^^^^^^^^^^^^^^^^
  File "C:\Users\HP\Desktop\projects\safeNetAi\backend\venv\Lib\site-packages\django\db\backends\utils.py", line 79, in execute
    return self._execute_with_wrappers(
           ^^^^^^^^^^^^^^^^^^^^^^^^^^^^
  File "C:\Users\HP\Desktop\projects\safeNetAi\backend\venv\Lib\site-packages\django\db\backends\utils.py", line 92, in _execute_with_wrappers
    return executor(sql, params, many, context)
           ^^^^^^^^^^^^^^^^^^^^^^^^^^^^^^^^^^^^
  File "C:\Users\HP\Desktop\projects\safeNetAi\backend\venv\Lib\site-packages\django\db\backends\utils.py", line 100, in _execute
    with self.db.wrap_database_errors:
  File "C:\Users\HP\Desktop\projects\safeNetAi\backend\venv\Lib\site-packages\django\db\utils.py", line 91, in __exit__
    raise dj_exc_value.with_traceback(traceback) from exc_value
  File "C:\Users\HP\Desktop\projects\safeNetAi\backend\venv\Lib\site-packages\django\db\backends\utils.py", line 105, in _execute
    return self.cursor.execute(sql, params)
           ^^^^^^^^^^^^^^^^^^^^^^^^^^^^^^^^
  File "C:\Users\HP\Desktop\projects\safeNetAi\backend\venv\Lib\site-packages\django\db\backends\sqlite3\base.py", line 360, in execute
    return super().execute(query, params)
           ^^^^^^^^^^^^^^^^^^^^^^^^^^^^^^
django.db.utils.OperationalError: no such column: transactions_transaction.current_lat
[2025-09-04 15:49:12] [ERROR] [django.server] "GET /api/client/transactions/ HTTP/1.1" 500 192380
[2025-09-04 15:49:12] [ERROR] [django.request] Internal Server Error: /api/client/transactions/
Traceback (most recent call last):
  File "C:\Users\HP\Desktop\projects\safeNetAi\backend\venv\Lib\site-packages\django\db\backends\utils.py", line 105, in _execute
    return self.cursor.execute(sql, params)
           ^^^^^^^^^^^^^^^^^^^^^^^^^^^^^^^^
  File "C:\Users\HP\Desktop\projects\safeNetAi\backend\venv\Lib\site-packages\django\db\backends\sqlite3\base.py", line 360, in execute
    return super().execute(query, params)
           ^^^^^^^^^^^^^^^^^^^^^^^^^^^^^^
sqlite3.OperationalError: no such column: transactions_transaction.current_lat

The above exception was the direct cause of the following exception:

Traceback (most recent call last):
  File "C:\Users\HP\Desktop\projects\safeNetAi\backend\venv\Lib\site-packages\django\core\handlers\exception.py", line 55, in inner
    response = get_response(request)
               ^^^^^^^^^^^^^^^^^^^^^
  File "C:\Users\HP\Desktop\projects\safeNetAi\backend\venv\Lib\site-packages\django\core\handlers\base.py", line 197, in _get_response
    response = wrapped_callback(request, *callback_args, **callback_kwargs)
               ^^^^^^^^^^^^^^^^^^^^^^^^^^^^^^^^^^^^^^^^^^^^^^^^^^^^^^^^^^^^
  File "C:\Users\HP\Desktop\projects\safeNetAi\backend\venv\Lib\site-packages\django\views\decorators\csrf.py", line 65, in _view_wrapper
    return view_func(request, *args, **kwargs)
           ^^^^^^^^^^^^^^^^^^^^^^^^^^^^^^^^^^^
  File "C:\Users\HP\Desktop\projects\safeNetAi\backend\venv\Lib\site-packages\rest_framework\viewsets.py", line 125, in view
    return self.dispatch(request, *args, **kwargs)
           ^^^^^^^^^^^^^^^^^^^^^^^^^^^^^^^^^^^^^^^
  File "C:\Users\HP\Desktop\projects\safeNetAi\backend\venv\Lib\site-packages\rest_framework\views.py", line 515, in dispatch
    response = self.handle_exception(exc)
               ^^^^^^^^^^^^^^^^^^^^^^^^^^
  File "C:\Users\HP\Desktop\projects\safeNetAi\backend\venv\Lib\site-packages\rest_framework\views.py", line 475, in handle_exception
    self.raise_uncaught_exception(exc)
  File "C:\Users\HP\Desktop\projects\safeNetAi\backend\venv\Lib\site-packages\rest_framework\views.py", line 486, in raise_uncaught_exception
    raise exc
  File "C:\Users\HP\Desktop\projects\safeNetAi\backend\venv\Lib\site-packages\rest_framework\views.py", line 512, in dispatch
    response = handler(request, *args, **kwargs)
               ^^^^^^^^^^^^^^^^^^^^^^^^^^^^^^^^^
  File "C:\Users\HP\Desktop\projects\safeNetAi\backend\venv\Lib\site-packages\rest_framework\mixins.py", line 46, in list
    return Response(serializer.data)
                    ^^^^^^^^^^^^^^^
  File "C:\Users\HP\Desktop\projects\safeNetAi\backend\venv\Lib\site-packages\rest_framework\serializers.py", line 797, in data
    ret = super().data
          ^^^^^^^^^^^^
  File "C:\Users\HP\Desktop\projects\safeNetAi\backend\venv\Lib\site-packages\rest_framework\serializers.py", line 251, in data
    self._data = self.to_representation(self.instance)
                 ^^^^^^^^^^^^^^^^^^^^^^^^^^^^^^^^^^^^^
  File "C:\Users\HP\Desktop\projects\safeNetAi\backend\venv\Lib\site-packages\rest_framework\serializers.py", line 715, in to_representation
    return [
           ^
  File "C:\Users\HP\Desktop\projects\safeNetAi\backend\venv\Lib\site-packages\django\db\models\query.py", line 384, in __iter__
    self._fetch_all()
  File "C:\Users\HP\Desktop\projects\safeNetAi\backend\venv\Lib\site-packages\django\db\models\query.py", line 1949, in _fetch_all
    self._result_cache = list(self._iterable_class(self))
                         ^^^^^^^^^^^^^^^^^^^^^^^^^^^^^^^^
  File "C:\Users\HP\Desktop\projects\safeNetAi\backend\venv\Lib\site-packages\django\db\models\query.py", line 91, in __iter__
    results = compiler.execute_sql(
              ^^^^^^^^^^^^^^^^^^^^^
  File "C:\Users\HP\Desktop\projects\safeNetAi\backend\venv\Lib\site-packages\django\db\models\sql\compiler.py", line 1623, in execute_sql
    cursor.execute(sql, params)
  File "C:\Users\HP\Desktop\projects\safeNetAi\backend\venv\Lib\site-packages\django\db\backends\utils.py", line 122, in execute
    return super().execute(sql, params)
           ^^^^^^^^^^^^^^^^^^^^^^^^^^^^
  File "C:\Users\HP\Desktop\projects\safeNetAi\backend\venv\Lib\site-packages\django\db\backends\utils.py", line 79, in execute
    return self._execute_with_wrappers(
           ^^^^^^^^^^^^^^^^^^^^^^^^^^^^
  File "C:\Users\HP\Desktop\projects\safeNetAi\backend\venv\Lib\site-packages\django\db\backends\utils.py", line 92, in _execute_with_wrappers
    return executor(sql, params, many, context)
           ^^^^^^^^^^^^^^^^^^^^^^^^^^^^^^^^^^^^
  File "C:\Users\HP\Desktop\projects\safeNetAi\backend\venv\Lib\site-packages\django\db\backends\utils.py", line 100, in _execute
    with self.db.wrap_database_errors:
  File "C:\Users\HP\Desktop\projects\safeNetAi\backend\venv\Lib\site-packages\django\db\utils.py", line 91, in __exit__
    raise dj_exc_value.with_traceback(traceback) from exc_value
  File "C:\Users\HP\Desktop\projects\safeNetAi\backend\venv\Lib\site-packages\django\db\backends\utils.py", line 105, in _execute
    return self.cursor.execute(sql, params)
           ^^^^^^^^^^^^^^^^^^^^^^^^^^^^^^^^
  File "C:\Users\HP\Desktop\projects\safeNetAi\backend\venv\Lib\site-packages\django\db\backends\sqlite3\base.py", line 360, in execute
    return super().execute(query, params)
           ^^^^^^^^^^^^^^^^^^^^^^^^^^^^^^
django.db.utils.OperationalError: no such column: transactions_transaction.current_lat
[2025-09-04 15:49:12] [ERROR] [django.server] "GET /api/client/transactions/ HTTP/1.1" 500 192380
[2025-09-04 15:49:19] [ERROR] [django.request] Internal Server Error: /api/client/transactions/
Traceback (most recent call last):
  File "C:\Users\HP\Desktop\projects\safeNetAi\backend\venv\Lib\site-packages\django\db\backends\utils.py", line 105, in _execute
    return self.cursor.execute(sql, params)
           ^^^^^^^^^^^^^^^^^^^^^^^^^^^^^^^^
  File "C:\Users\HP\Desktop\projects\safeNetAi\backend\venv\Lib\site-packages\django\db\backends\sqlite3\base.py", line 360, in execute
    return super().execute(query, params)
           ^^^^^^^^^^^^^^^^^^^^^^^^^^^^^^
sqlite3.OperationalError: no such column: transactions_transaction.current_lat

The above exception was the direct cause of the following exception:

Traceback (most recent call last):
  File "C:\Users\HP\Desktop\projects\safeNetAi\backend\venv\Lib\site-packages\django\core\handlers\exception.py", line 55, in inner
    response = get_response(request)
               ^^^^^^^^^^^^^^^^^^^^^
  File "C:\Users\HP\Desktop\projects\safeNetAi\backend\venv\Lib\site-packages\django\core\handlers\base.py", line 197, in _get_response
    response = wrapped_callback(request, *callback_args, **callback_kwargs)
               ^^^^^^^^^^^^^^^^^^^^^^^^^^^^^^^^^^^^^^^^^^^^^^^^^^^^^^^^^^^^
  File "C:\Users\HP\Desktop\projects\safeNetAi\backend\venv\Lib\site-packages\django\views\decorators\csrf.py", line 65, in _view_wrapper
    return view_func(request, *args, **kwargs)
           ^^^^^^^^^^^^^^^^^^^^^^^^^^^^^^^^^^^
  File "C:\Users\HP\Desktop\projects\safeNetAi\backend\venv\Lib\site-packages\rest_framework\viewsets.py", line 125, in view
    return self.dispatch(request, *args, **kwargs)
           ^^^^^^^^^^^^^^^^^^^^^^^^^^^^^^^^^^^^^^^
  File "C:\Users\HP\Desktop\projects\safeNetAi\backend\venv\Lib\site-packages\rest_framework\views.py", line 515, in dispatch
    response = self.handle_exception(exc)
               ^^^^^^^^^^^^^^^^^^^^^^^^^^
  File "C:\Users\HP\Desktop\projects\safeNetAi\backend\venv\Lib\site-packages\rest_framework\views.py", line 475, in handle_exception
    self.raise_uncaught_exception(exc)
  File "C:\Users\HP\Desktop\projects\safeNetAi\backend\venv\Lib\site-packages\rest_framework\views.py", line 486, in raise_uncaught_exception
    raise exc
  File "C:\Users\HP\Desktop\projects\safeNetAi\backend\venv\Lib\site-packages\rest_framework\views.py", line 512, in dispatch
    response = handler(request, *args, **kwargs)
               ^^^^^^^^^^^^^^^^^^^^^^^^^^^^^^^^^
  File "C:\Users\HP\Desktop\projects\safeNetAi\backend\venv\Lib\site-packages\rest_framework\mixins.py", line 46, in list
    return Response(serializer.data)
                    ^^^^^^^^^^^^^^^
  File "C:\Users\HP\Desktop\projects\safeNetAi\backend\venv\Lib\site-packages\rest_framework\serializers.py", line 797, in data
    ret = super().data
          ^^^^^^^^^^^^
  File "C:\Users\HP\Desktop\projects\safeNetAi\backend\venv\Lib\site-packages\rest_framework\serializers.py", line 251, in data
    self._data = self.to_representation(self.instance)
                 ^^^^^^^^^^^^^^^^^^^^^^^^^^^^^^^^^^^^^
  File "C:\Users\HP\Desktop\projects\safeNetAi\backend\venv\Lib\site-packages\rest_framework\serializers.py", line 715, in to_representation
    return [
           ^
  File "C:\Users\HP\Desktop\projects\safeNetAi\backend\venv\Lib\site-packages\django\db\models\query.py", line 384, in __iter__
    self._fetch_all()
  File "C:\Users\HP\Desktop\projects\safeNetAi\backend\venv\Lib\site-packages\django\db\models\query.py", line 1949, in _fetch_all
    self._result_cache = list(self._iterable_class(self))
                         ^^^^^^^^^^^^^^^^^^^^^^^^^^^^^^^^
  File "C:\Users\HP\Desktop\projects\safeNetAi\backend\venv\Lib\site-packages\django\db\models\query.py", line 91, in __iter__
    results = compiler.execute_sql(
              ^^^^^^^^^^^^^^^^^^^^^
  File "C:\Users\HP\Desktop\projects\safeNetAi\backend\venv\Lib\site-packages\django\db\models\sql\compiler.py", line 1623, in execute_sql
    cursor.execute(sql, params)
  File "C:\Users\HP\Desktop\projects\safeNetAi\backend\venv\Lib\site-packages\django\db\backends\utils.py", line 122, in execute
    return super().execute(sql, params)
           ^^^^^^^^^^^^^^^^^^^^^^^^^^^^
  File "C:\Users\HP\Desktop\projects\safeNetAi\backend\venv\Lib\site-packages\django\db\backends\utils.py", line 79, in execute
    return self._execute_with_wrappers(
           ^^^^^^^^^^^^^^^^^^^^^^^^^^^^
  File "C:\Users\HP\Desktop\projects\safeNetAi\backend\venv\Lib\site-packages\django\db\backends\utils.py", line 92, in _execute_with_wrappers
    return executor(sql, params, many, context)
           ^^^^^^^^^^^^^^^^^^^^^^^^^^^^^^^^^^^^
  File "C:\Users\HP\Desktop\projects\safeNetAi\backend\venv\Lib\site-packages\django\db\backends\utils.py", line 100, in _execute
    with self.db.wrap_database_errors:
  File "C:\Users\HP\Desktop\projects\safeNetAi\backend\venv\Lib\site-packages\django\db\utils.py", line 91, in __exit__
    raise dj_exc_value.with_traceback(traceback) from exc_value
  File "C:\Users\HP\Desktop\projects\safeNetAi\backend\venv\Lib\site-packages\django\db\backends\utils.py", line 105, in _execute
    return self.cursor.execute(sql, params)
           ^^^^^^^^^^^^^^^^^^^^^^^^^^^^^^^^
  File "C:\Users\HP\Desktop\projects\safeNetAi\backend\venv\Lib\site-packages\django\db\backends\sqlite3\base.py", line 360, in execute
    return super().execute(query, params)
           ^^^^^^^^^^^^^^^^^^^^^^^^^^^^^^
django.db.utils.OperationalError: no such column: transactions_transaction.current_lat
[2025-09-04 15:49:19] [ERROR] [django.server] "GET /api/client/transactions/ HTTP/1.1" 500 192380
[2025-09-04 15:49:19] [ERROR] [django.request] Internal Server Error: /api/client/transactions/
Traceback (most recent call last):
  File "C:\Users\HP\Desktop\projects\safeNetAi\backend\venv\Lib\site-packages\django\db\backends\utils.py", line 105, in _execute
    return self.cursor.execute(sql, params)
           ^^^^^^^^^^^^^^^^^^^^^^^^^^^^^^^^
  File "C:\Users\HP\Desktop\projects\safeNetAi\backend\venv\Lib\site-packages\django\db\backends\sqlite3\base.py", line 360, in execute
    return super().execute(query, params)
           ^^^^^^^^^^^^^^^^^^^^^^^^^^^^^^
sqlite3.OperationalError: no such column: transactions_transaction.current_lat

The above exception was the direct cause of the following exception:

Traceback (most recent call last):
  File "C:\Users\HP\Desktop\projects\safeNetAi\backend\venv\Lib\site-packages\django\core\handlers\exception.py", line 55, in inner
    response = get_response(request)
               ^^^^^^^^^^^^^^^^^^^^^
  File "C:\Users\HP\Desktop\projects\safeNetAi\backend\venv\Lib\site-packages\django\core\handlers\base.py", line 197, in _get_response
    response = wrapped_callback(request, *callback_args, **callback_kwargs)
               ^^^^^^^^^^^^^^^^^^^^^^^^^^^^^^^^^^^^^^^^^^^^^^^^^^^^^^^^^^^^
  File "C:\Users\HP\Desktop\projects\safeNetAi\backend\venv\Lib\site-packages\django\views\decorators\csrf.py", line 65, in _view_wrapper
    return view_func(request, *args, **kwargs)
           ^^^^^^^^^^^^^^^^^^^^^^^^^^^^^^^^^^^
  File "C:\Users\HP\Desktop\projects\safeNetAi\backend\venv\Lib\site-packages\rest_framework\viewsets.py", line 125, in view
    return self.dispatch(request, *args, **kwargs)
           ^^^^^^^^^^^^^^^^^^^^^^^^^^^^^^^^^^^^^^^
  File "C:\Users\HP\Desktop\projects\safeNetAi\backend\venv\Lib\site-packages\rest_framework\views.py", line 515, in dispatch
    response = self.handle_exception(exc)
               ^^^^^^^^^^^^^^^^^^^^^^^^^^
  File "C:\Users\HP\Desktop\projects\safeNetAi\backend\venv\Lib\site-packages\rest_framework\views.py", line 475, in handle_exception
    self.raise_uncaught_exception(exc)
  File "C:\Users\HP\Desktop\projects\safeNetAi\backend\venv\Lib\site-packages\rest_framework\views.py", line 486, in raise_uncaught_exception
    raise exc
  File "C:\Users\HP\Desktop\projects\safeNetAi\backend\venv\Lib\site-packages\rest_framework\views.py", line 512, in dispatch
    response = handler(request, *args, **kwargs)
               ^^^^^^^^^^^^^^^^^^^^^^^^^^^^^^^^^
  File "C:\Users\HP\Desktop\projects\safeNetAi\backend\venv\Lib\site-packages\rest_framework\mixins.py", line 46, in list
    return Response(serializer.data)
                    ^^^^^^^^^^^^^^^
  File "C:\Users\HP\Desktop\projects\safeNetAi\backend\venv\Lib\site-packages\rest_framework\serializers.py", line 797, in data
    ret = super().data
          ^^^^^^^^^^^^
  File "C:\Users\HP\Desktop\projects\safeNetAi\backend\venv\Lib\site-packages\rest_framework\serializers.py", line 251, in data
    self._data = self.to_representation(self.instance)
                 ^^^^^^^^^^^^^^^^^^^^^^^^^^^^^^^^^^^^^
  File "C:\Users\HP\Desktop\projects\safeNetAi\backend\venv\Lib\site-packages\rest_framework\serializers.py", line 715, in to_representation
    return [
           ^
  File "C:\Users\HP\Desktop\projects\safeNetAi\backend\venv\Lib\site-packages\django\db\models\query.py", line 384, in __iter__
    self._fetch_all()
  File "C:\Users\HP\Desktop\projects\safeNetAi\backend\venv\Lib\site-packages\django\db\models\query.py", line 1949, in _fetch_all
    self._result_cache = list(self._iterable_class(self))
                         ^^^^^^^^^^^^^^^^^^^^^^^^^^^^^^^^
  File "C:\Users\HP\Desktop\projects\safeNetAi\backend\venv\Lib\site-packages\django\db\models\query.py", line 91, in __iter__
    results = compiler.execute_sql(
              ^^^^^^^^^^^^^^^^^^^^^
  File "C:\Users\HP\Desktop\projects\safeNetAi\backend\venv\Lib\site-packages\django\db\models\sql\compiler.py", line 1623, in execute_sql
    cursor.execute(sql, params)
  File "C:\Users\HP\Desktop\projects\safeNetAi\backend\venv\Lib\site-packages\django\db\backends\utils.py", line 122, in execute
    return super().execute(sql, params)
           ^^^^^^^^^^^^^^^^^^^^^^^^^^^^
  File "C:\Users\HP\Desktop\projects\safeNetAi\backend\venv\Lib\site-packages\django\db\backends\utils.py", line 79, in execute
    return self._execute_with_wrappers(
           ^^^^^^^^^^^^^^^^^^^^^^^^^^^^
  File "C:\Users\HP\Desktop\projects\safeNetAi\backend\venv\Lib\site-packages\django\db\backends\utils.py", line 92, in _execute_with_wrappers
    return executor(sql, params, many, context)
           ^^^^^^^^^^^^^^^^^^^^^^^^^^^^^^^^^^^^
  File "C:\Users\HP\Desktop\projects\safeNetAi\backend\venv\Lib\site-packages\django\db\backends\utils.py", line 100, in _execute
    with self.db.wrap_database_errors:
  File "C:\Users\HP\Desktop\projects\safeNetAi\backend\venv\Lib\site-packages\django\db\utils.py", line 91, in __exit__
    raise dj_exc_value.with_traceback(traceback) from exc_value
  File "C:\Users\HP\Desktop\projects\safeNetAi\backend\venv\Lib\site-packages\django\db\backends\utils.py", line 105, in _execute
    return self.cursor.execute(sql, params)
           ^^^^^^^^^^^^^^^^^^^^^^^^^^^^^^^^
  File "C:\Users\HP\Desktop\projects\safeNetAi\backend\venv\Lib\site-packages\django\db\backends\sqlite3\base.py", line 360, in execute
    return super().execute(query, params)
           ^^^^^^^^^^^^^^^^^^^^^^^^^^^^^^
django.db.utils.OperationalError: no such column: transactions_transaction.current_lat
[2025-09-04 15:49:19] [ERROR] [django.server] "GET /api/client/transactions/ HTTP/1.1" 500 192380
[2025-09-04 15:49:58] [ERROR] [django.request] Internal Server Error: /admin/users/user/
Traceback (most recent call last):
  File "C:\Users\HP\Desktop\projects\safeNetAi\backend\venv\Lib\site-packages\django\db\backends\utils.py", line 105, in _execute
    return self.cursor.execute(sql, params)
           ^^^^^^^^^^^^^^^^^^^^^^^^^^^^^^^^
  File "C:\Users\HP\Desktop\projects\safeNetAi\backend\venv\Lib\site-packages\django\db\backends\sqlite3\base.py", line 360, in execute
    return super().execute(query, params)
           ^^^^^^^^^^^^^^^^^^^^^^^^^^^^^^
sqlite3.OperationalError: no such column: transactions_transaction.current_lat

The above exception was the direct cause of the following exception:

Traceback (most recent call last):
  File "C:\Users\HP\Desktop\projects\safeNetAi\backend\venv\Lib\site-packages\django\core\handlers\exception.py", line 55, in inner
    response = get_response(request)
               ^^^^^^^^^^^^^^^^^^^^^
  File "C:\Users\HP\Desktop\projects\safeNetAi\backend\venv\Lib\site-packages\django\core\handlers\base.py", line 197, in _get_response
    response = wrapped_callback(request, *callback_args, **callback_kwargs)
               ^^^^^^^^^^^^^^^^^^^^^^^^^^^^^^^^^^^^^^^^^^^^^^^^^^^^^^^^^^^^
  File "C:\Users\HP\Desktop\projects\safeNetAi\backend\venv\Lib\site-packages\django\contrib\admin\options.py", line 719, in wrapper
    return self.admin_site.admin_view(view)(*args, **kwargs)
           ^^^^^^^^^^^^^^^^^^^^^^^^^^^^^^^^^^^^^^^^^^^^^^^^^
  File "C:\Users\HP\Desktop\projects\safeNetAi\backend\venv\Lib\site-packages\django\utils\decorators.py", line 192, in _view_wrapper
    result = _process_exception(request, e)
             ^^^^^^^^^^^^^^^^^^^^^^^^^^^^^^
  File "C:\Users\HP\Desktop\projects\safeNetAi\backend\venv\Lib\site-packages\django\utils\decorators.py", line 190, in _view_wrapper
    response = view_func(request, *args, **kwargs)
               ^^^^^^^^^^^^^^^^^^^^^^^^^^^^^^^^^^^
  File "C:\Users\HP\Desktop\projects\safeNetAi\backend\venv\Lib\site-packages\django\views\decorators\cache.py", line 80, in _view_wrapper
    response = view_func(request, *args, **kwargs)
               ^^^^^^^^^^^^^^^^^^^^^^^^^^^^^^^^^^^
  File "C:\Users\HP\Desktop\projects\safeNetAi\backend\venv\Lib\site-packages\django\contrib\admin\sites.py", line 246, in inner
    return view(request, *args, **kwargs)
           ^^^^^^^^^^^^^^^^^^^^^^^^^^^^^^
  File "C:\Users\HP\Desktop\projects\safeNetAi\backend\venv\Lib\site-packages\django\utils\decorators.py", line 48, in _wrapper
    return bound_method(*args, **kwargs)
           ^^^^^^^^^^^^^^^^^^^^^^^^^^^^^
  File "C:\Users\HP\Desktop\projects\safeNetAi\backend\venv\Lib\site-packages\django\utils\decorators.py", line 192, in _view_wrapper
    result = _process_exception(request, e)
             ^^^^^^^^^^^^^^^^^^^^^^^^^^^^^^
  File "C:\Users\HP\Desktop\projects\safeNetAi\backend\venv\Lib\site-packages\django\utils\decorators.py", line 190, in _view_wrapper
    response = view_func(request, *args, **kwargs)
               ^^^^^^^^^^^^^^^^^^^^^^^^^^^^^^^^^^^
  File "C:\Users\HP\Desktop\projects\safeNetAi\backend\venv\Lib\site-packages\django\contrib\admin\options.py", line 2057, in changelist_view
    response = self.response_action(
               ^^^^^^^^^^^^^^^^^^^^^
  File "C:\Users\HP\Desktop\projects\safeNetAi\backend\venv\Lib\site-packages\django\contrib\admin\options.py", line 1686, in response_action
    response = func(self, request, queryset)
               ^^^^^^^^^^^^^^^^^^^^^^^^^^^^^
  File "C:\Users\HP\Desktop\projects\safeNetAi\backend\venv\Lib\site-packages\django\contrib\admin\actions.py", line 39, in delete_selected
    ) = modeladmin.get_deleted_objects(queryset, request)
        ^^^^^^^^^^^^^^^^^^^^^^^^^^^^^^^^^^^^^^^^^^^^^^^^^
  File "C:\Users\HP\Desktop\projects\safeNetAi\backend\venv\Lib\site-packages\django\contrib\admin\options.py", line 2199, in get_deleted_objects
    return get_deleted_objects(objs, request, self.admin_site)
           ^^^^^^^^^^^^^^^^^^^^^^^^^^^^^^^^^^^^^^^^^^^^^^^^^^^
  File "C:\Users\HP\Desktop\projects\safeNetAi\backend\venv\Lib\site-packages\django\contrib\admin\utils.py", line 138, in get_deleted_objects
    collector.collect(objs)
  File "C:\Users\HP\Desktop\projects\safeNetAi\backend\venv\Lib\site-packages\django\contrib\admin\utils.py", line 205, in collect
    return super().collect(objs, source_attr=source_attr, **kwargs)
           ^^^^^^^^^^^^^^^^^^^^^^^^^^^^^^^^^^^^^^^^^^^^^^^^^^^^^^^^
  File "C:\Users\HP\Desktop\projects\safeNetAi\backend\venv\Lib\site-packages\django\db\models\deletion.py", line 345, in collect
    on_delete(self, field, sub_objs, self.using)
  File "C:\Users\HP\Desktop\projects\safeNetAi\backend\venv\Lib\site-packages\django\db\models\deletion.py", line 23, in CASCADE
    collector.collect(
  File "C:\Users\HP\Desktop\projects\safeNetAi\backend\venv\Lib\site-packages\django\contrib\admin\utils.py", line 205, in collect
    return super().collect(objs, source_attr=source_attr, **kwargs)
           ^^^^^^^^^^^^^^^^^^^^^^^^^^^^^^^^^^^^^^^^^^^^^^^^^^^^^^^^
  File "C:\Users\HP\Desktop\projects\safeNetAi\backend\venv\Lib\site-packages\django\db\models\deletion.py", line 343, in collect
    if getattr(on_delete, "lazy_sub_objs", False) or sub_objs:
  File "C:\Users\HP\Desktop\projects\safeNetAi\backend\venv\Lib\site-packages\django\db\models\query.py", line 398, in __bool__
    self._fetch_all()
  File "C:\Users\HP\Desktop\projects\safeNetAi\backend\venv\Lib\site-packages\django\db\models\query.py", line 1949, in _fetch_all
    self._result_cache = list(self._iterable_class(self))
                         ^^^^^^^^^^^^^^^^^^^^^^^^^^^^^^^^
  File "C:\Users\HP\Desktop\projects\safeNetAi\backend\venv\Lib\site-packages\django\db\models\query.py", line 91, in __iter__
    results = compiler.execute_sql(
              ^^^^^^^^^^^^^^^^^^^^^
  File "C:\Users\HP\Desktop\projects\safeNetAi\backend\venv\Lib\site-packages\django\db\models\sql\compiler.py", line 1623, in execute_sql
    cursor.execute(sql, params)
  File "C:\Users\HP\Desktop\projects\safeNetAi\backend\venv\Lib\site-packages\django\db\backends\utils.py", line 122, in execute
    return super().execute(sql, params)
           ^^^^^^^^^^^^^^^^^^^^^^^^^^^^
  File "C:\Users\HP\Desktop\projects\safeNetAi\backend\venv\Lib\site-packages\django\db\backends\utils.py", line 79, in execute
    return self._execute_with_wrappers(
           ^^^^^^^^^^^^^^^^^^^^^^^^^^^^
  File "C:\Users\HP\Desktop\projects\safeNetAi\backend\venv\Lib\site-packages\django\db\backends\utils.py", line 92, in _execute_with_wrappers
    return executor(sql, params, many, context)
           ^^^^^^^^^^^^^^^^^^^^^^^^^^^^^^^^^^^^
  File "C:\Users\HP\Desktop\projects\safeNetAi\backend\venv\Lib\site-packages\django\db\backends\utils.py", line 100, in _execute
    with self.db.wrap_database_errors:
  File "C:\Users\HP\Desktop\projects\safeNetAi\backend\venv\Lib\site-packages\django\db\utils.py", line 91, in __exit__
    raise dj_exc_value.with_traceback(traceback) from exc_value
  File "C:\Users\HP\Desktop\projects\safeNetAi\backend\venv\Lib\site-packages\django\db\backends\utils.py", line 105, in _execute
    return self.cursor.execute(sql, params)
           ^^^^^^^^^^^^^^^^^^^^^^^^^^^^^^^^
  File "C:\Users\HP\Desktop\projects\safeNetAi\backend\venv\Lib\site-packages\django\db\backends\sqlite3\base.py", line 360, in execute
    return super().execute(query, params)
           ^^^^^^^^^^^^^^^^^^^^^^^^^^^^^^
django.db.utils.OperationalError: no such column: transactions_transaction.current_lat
[2025-09-04 15:49:58] [ERROR] [django.server] "POST /admin/users/user/ HTTP/1.1" 500 257525
[2025-09-04 15:50:27] [ERROR] [django.request] Internal Server Error: /admin/users/user/
Traceback (most recent call last):
  File "C:\Users\HP\Desktop\projects\safeNetAi\backend\venv\Lib\site-packages\django\db\backends\utils.py", line 105, in _execute
    return self.cursor.execute(sql, params)
           ^^^^^^^^^^^^^^^^^^^^^^^^^^^^^^^^
  File "C:\Users\HP\Desktop\projects\safeNetAi\backend\venv\Lib\site-packages\django\db\backends\sqlite3\base.py", line 360, in execute
    return super().execute(query, params)
           ^^^^^^^^^^^^^^^^^^^^^^^^^^^^^^
sqlite3.OperationalError: no such column: transactions_transaction.current_lat

The above exception was the direct cause of the following exception:

Traceback (most recent call last):
  File "C:\Users\HP\Desktop\projects\safeNetAi\backend\venv\Lib\site-packages\django\core\handlers\exception.py", line 55, in inner
    response = get_response(request)
               ^^^^^^^^^^^^^^^^^^^^^
  File "C:\Users\HP\Desktop\projects\safeNetAi\backend\venv\Lib\site-packages\django\core\handlers\base.py", line 197, in _get_response
    response = wrapped_callback(request, *callback_args, **callback_kwargs)
               ^^^^^^^^^^^^^^^^^^^^^^^^^^^^^^^^^^^^^^^^^^^^^^^^^^^^^^^^^^^^
  File "C:\Users\HP\Desktop\projects\safeNetAi\backend\venv\Lib\site-packages\django\contrib\admin\options.py", line 719, in wrapper
    return self.admin_site.admin_view(view)(*args, **kwargs)
           ^^^^^^^^^^^^^^^^^^^^^^^^^^^^^^^^^^^^^^^^^^^^^^^^^
  File "C:\Users\HP\Desktop\projects\safeNetAi\backend\venv\Lib\site-packages\django\utils\decorators.py", line 192, in _view_wrapper
    result = _process_exception(request, e)
             ^^^^^^^^^^^^^^^^^^^^^^^^^^^^^^
  File "C:\Users\HP\Desktop\projects\safeNetAi\backend\venv\Lib\site-packages\django\utils\decorators.py", line 190, in _view_wrapper
    response = view_func(request, *args, **kwargs)
               ^^^^^^^^^^^^^^^^^^^^^^^^^^^^^^^^^^^
  File "C:\Users\HP\Desktop\projects\safeNetAi\backend\venv\Lib\site-packages\django\views\decorators\cache.py", line 80, in _view_wrapper
    response = view_func(request, *args, **kwargs)
               ^^^^^^^^^^^^^^^^^^^^^^^^^^^^^^^^^^^
  File "C:\Users\HP\Desktop\projects\safeNetAi\backend\venv\Lib\site-packages\django\contrib\admin\sites.py", line 246, in inner
    return view(request, *args, **kwargs)
           ^^^^^^^^^^^^^^^^^^^^^^^^^^^^^^
  File "C:\Users\HP\Desktop\projects\safeNetAi\backend\venv\Lib\site-packages\django\utils\decorators.py", line 48, in _wrapper
    return bound_method(*args, **kwargs)
           ^^^^^^^^^^^^^^^^^^^^^^^^^^^^^
  File "C:\Users\HP\Desktop\projects\safeNetAi\backend\venv\Lib\site-packages\django\utils\decorators.py", line 192, in _view_wrapper
    result = _process_exception(request, e)
             ^^^^^^^^^^^^^^^^^^^^^^^^^^^^^^
  File "C:\Users\HP\Desktop\projects\safeNetAi\backend\venv\Lib\site-packages\django\utils\decorators.py", line 190, in _view_wrapper
    response = view_func(request, *args, **kwargs)
               ^^^^^^^^^^^^^^^^^^^^^^^^^^^^^^^^^^^
  File "C:\Users\HP\Desktop\projects\safeNetAi\backend\venv\Lib\site-packages\django\contrib\admin\options.py", line 2057, in changelist_view
    response = self.response_action(
               ^^^^^^^^^^^^^^^^^^^^^
  File "C:\Users\HP\Desktop\projects\safeNetAi\backend\venv\Lib\site-packages\django\contrib\admin\options.py", line 1686, in response_action
    response = func(self, request, queryset)
               ^^^^^^^^^^^^^^^^^^^^^^^^^^^^^
  File "C:\Users\HP\Desktop\projects\safeNetAi\backend\venv\Lib\site-packages\django\contrib\admin\actions.py", line 39, in delete_selected
    ) = modeladmin.get_deleted_objects(queryset, request)
        ^^^^^^^^^^^^^^^^^^^^^^^^^^^^^^^^^^^^^^^^^^^^^^^^^
  File "C:\Users\HP\Desktop\projects\safeNetAi\backend\venv\Lib\site-packages\django\contrib\admin\options.py", line 2199, in get_deleted_objects
    return get_deleted_objects(objs, request, self.admin_site)
           ^^^^^^^^^^^^^^^^^^^^^^^^^^^^^^^^^^^^^^^^^^^^^^^^^^^
  File "C:\Users\HP\Desktop\projects\safeNetAi\backend\venv\Lib\site-packages\django\contrib\admin\utils.py", line 138, in get_deleted_objects
    collector.collect(objs)
  File "C:\Users\HP\Desktop\projects\safeNetAi\backend\venv\Lib\site-packages\django\contrib\admin\utils.py", line 205, in collect
    return super().collect(objs, source_attr=source_attr, **kwargs)
           ^^^^^^^^^^^^^^^^^^^^^^^^^^^^^^^^^^^^^^^^^^^^^^^^^^^^^^^^
  File "C:\Users\HP\Desktop\projects\safeNetAi\backend\venv\Lib\site-packages\django\db\models\deletion.py", line 345, in collect
    on_delete(self, field, sub_objs, self.using)
  File "C:\Users\HP\Desktop\projects\safeNetAi\backend\venv\Lib\site-packages\django\db\models\deletion.py", line 23, in CASCADE
    collector.collect(
  File "C:\Users\HP\Desktop\projects\safeNetAi\backend\venv\Lib\site-packages\django\contrib\admin\utils.py", line 205, in collect
    return super().collect(objs, source_attr=source_attr, **kwargs)
           ^^^^^^^^^^^^^^^^^^^^^^^^^^^^^^^^^^^^^^^^^^^^^^^^^^^^^^^^
  File "C:\Users\HP\Desktop\projects\safeNetAi\backend\venv\Lib\site-packages\django\db\models\deletion.py", line 343, in collect
    if getattr(on_delete, "lazy_sub_objs", False) or sub_objs:
  File "C:\Users\HP\Desktop\projects\safeNetAi\backend\venv\Lib\site-packages\django\db\models\query.py", line 398, in __bool__
    self._fetch_all()
  File "C:\Users\HP\Desktop\projects\safeNetAi\backend\venv\Lib\site-packages\django\db\models\query.py", line 1949, in _fetch_all
    self._result_cache = list(self._iterable_class(self))
                         ^^^^^^^^^^^^^^^^^^^^^^^^^^^^^^^^
  File "C:\Users\HP\Desktop\projects\safeNetAi\backend\venv\Lib\site-packages\django\db\models\query.py", line 91, in __iter__
    results = compiler.execute_sql(
              ^^^^^^^^^^^^^^^^^^^^^
  File "C:\Users\HP\Desktop\projects\safeNetAi\backend\venv\Lib\site-packages\django\db\models\sql\compiler.py", line 1623, in execute_sql
    cursor.execute(sql, params)
  File "C:\Users\HP\Desktop\projects\safeNetAi\backend\venv\Lib\site-packages\django\db\backends\utils.py", line 122, in execute
    return super().execute(sql, params)
           ^^^^^^^^^^^^^^^^^^^^^^^^^^^^
  File "C:\Users\HP\Desktop\projects\safeNetAi\backend\venv\Lib\site-packages\django\db\backends\utils.py", line 79, in execute
    return self._execute_with_wrappers(
           ^^^^^^^^^^^^^^^^^^^^^^^^^^^^
  File "C:\Users\HP\Desktop\projects\safeNetAi\backend\venv\Lib\site-packages\django\db\backends\utils.py", line 92, in _execute_with_wrappers
    return executor(sql, params, many, context)
           ^^^^^^^^^^^^^^^^^^^^^^^^^^^^^^^^^^^^
  File "C:\Users\HP\Desktop\projects\safeNetAi\backend\venv\Lib\site-packages\django\db\backends\utils.py", line 100, in _execute
    with self.db.wrap_database_errors:
  File "C:\Users\HP\Desktop\projects\safeNetAi\backend\venv\Lib\site-packages\django\db\utils.py", line 91, in __exit__
    raise dj_exc_value.with_traceback(traceback) from exc_value
  File "C:\Users\HP\Desktop\projects\safeNetAi\backend\venv\Lib\site-packages\django\db\backends\utils.py", line 105, in _execute
    return self.cursor.execute(sql, params)
           ^^^^^^^^^^^^^^^^^^^^^^^^^^^^^^^^
  File "C:\Users\HP\Desktop\projects\safeNetAi\backend\venv\Lib\site-packages\django\db\backends\sqlite3\base.py", line 360, in execute
    return super().execute(query, params)
           ^^^^^^^^^^^^^^^^^^^^^^^^^^^^^^
django.db.utils.OperationalError: no such column: transactions_transaction.current_lat
[2025-09-04 15:50:27] [ERROR] [django.server] "POST /admin/users/user/ HTTP/1.1" 500 257655
[2025-09-04 15:53:48] [ERROR] [django.request] Internal Server Error: /admin/transactions/transaction/
Traceback (most recent call last):
  File "C:\Users\HP\Desktop\projects\safeNetAi\backend\venv\Lib\site-packages\django\db\backends\utils.py", line 105, in _execute
    return self.cursor.execute(sql, params)
           ^^^^^^^^^^^^^^^^^^^^^^^^^^^^^^^^
  File "C:\Users\HP\Desktop\projects\safeNetAi\backend\venv\Lib\site-packages\django\db\backends\sqlite3\base.py", line 360, in execute
    return super().execute(query, params)
           ^^^^^^^^^^^^^^^^^^^^^^^^^^^^^^
sqlite3.OperationalError: no such column: transactions_transaction.current_lat

The above exception was the direct cause of the following exception:

Traceback (most recent call last):
  File "C:\Users\HP\Desktop\projects\safeNetAi\backend\venv\Lib\site-packages\django\core\handlers\exception.py", line 55, in inner
    response = get_response(request)
               ^^^^^^^^^^^^^^^^^^^^^
  File "C:\Users\HP\Desktop\projects\safeNetAi\backend\venv\Lib\site-packages\django\core\handlers\base.py", line 197, in _get_response
    response = wrapped_callback(request, *callback_args, **callback_kwargs)
               ^^^^^^^^^^^^^^^^^^^^^^^^^^^^^^^^^^^^^^^^^^^^^^^^^^^^^^^^^^^^
  File "C:\Users\HP\Desktop\projects\safeNetAi\backend\venv\Lib\site-packages\django\contrib\admin\options.py", line 719, in wrapper
    return self.admin_site.admin_view(view)(*args, **kwargs)
           ^^^^^^^^^^^^^^^^^^^^^^^^^^^^^^^^^^^^^^^^^^^^^^^^^
  File "C:\Users\HP\Desktop\projects\safeNetAi\backend\venv\Lib\site-packages\django\utils\decorators.py", line 192, in _view_wrapper
    result = _process_exception(request, e)
             ^^^^^^^^^^^^^^^^^^^^^^^^^^^^^^
  File "C:\Users\HP\Desktop\projects\safeNetAi\backend\venv\Lib\site-packages\django\utils\decorators.py", line 190, in _view_wrapper
    response = view_func(request, *args, **kwargs)
               ^^^^^^^^^^^^^^^^^^^^^^^^^^^^^^^^^^^
  File "C:\Users\HP\Desktop\projects\safeNetAi\backend\venv\Lib\site-packages\django\views\decorators\cache.py", line 80, in _view_wrapper
    response = view_func(request, *args, **kwargs)
               ^^^^^^^^^^^^^^^^^^^^^^^^^^^^^^^^^^^
  File "C:\Users\HP\Desktop\projects\safeNetAi\backend\venv\Lib\site-packages\django\contrib\admin\sites.py", line 246, in inner
    return view(request, *args, **kwargs)
           ^^^^^^^^^^^^^^^^^^^^^^^^^^^^^^
  File "C:\Users\HP\Desktop\projects\safeNetAi\backend\venv\Lib\site-packages\django\utils\decorators.py", line 48, in _wrapper
    return bound_method(*args, **kwargs)
           ^^^^^^^^^^^^^^^^^^^^^^^^^^^^^
  File "C:\Users\HP\Desktop\projects\safeNetAi\backend\venv\Lib\site-packages\django\utils\decorators.py", line 192, in _view_wrapper
    result = _process_exception(request, e)
             ^^^^^^^^^^^^^^^^^^^^^^^^^^^^^^
  File "C:\Users\HP\Desktop\projects\safeNetAi\backend\venv\Lib\site-packages\django\utils\decorators.py", line 190, in _view_wrapper
    response = view_func(request, *args, **kwargs)
               ^^^^^^^^^^^^^^^^^^^^^^^^^^^^^^^^^^^
  File "C:\Users\HP\Desktop\projects\safeNetAi\backend\venv\Lib\site-packages\django\contrib\admin\options.py", line 2163, in changelist_view
    "selection_note": _("0 of %(cnt)s selected") % {"cnt": len(cl.result_list)},
                                                           ^^^^^^^^^^^^^^^^^^^
  File "C:\Users\HP\Desktop\projects\safeNetAi\backend\venv\Lib\site-packages\django\db\models\query.py", line 366, in __len__
    self._fetch_all()
  File "C:\Users\HP\Desktop\projects\safeNetAi\backend\venv\Lib\site-packages\django\db\models\query.py", line 1949, in _fetch_all
    self._result_cache = list(self._iterable_class(self))
                         ^^^^^^^^^^^^^^^^^^^^^^^^^^^^^^^^
  File "C:\Users\HP\Desktop\projects\safeNetAi\backend\venv\Lib\site-packages\django\db\models\query.py", line 91, in __iter__
    results = compiler.execute_sql(
              ^^^^^^^^^^^^^^^^^^^^^
  File "C:\Users\HP\Desktop\projects\safeNetAi\backend\venv\Lib\site-packages\django\db\models\sql\compiler.py", line 1623, in execute_sql
    cursor.execute(sql, params)
  File "C:\Users\HP\Desktop\projects\safeNetAi\backend\venv\Lib\site-packages\django\db\backends\utils.py", line 122, in execute
    return super().execute(sql, params)
           ^^^^^^^^^^^^^^^^^^^^^^^^^^^^
  File "C:\Users\HP\Desktop\projects\safeNetAi\backend\venv\Lib\site-packages\django\db\backends\utils.py", line 79, in execute
    return self._execute_with_wrappers(
           ^^^^^^^^^^^^^^^^^^^^^^^^^^^^
  File "C:\Users\HP\Desktop\projects\safeNetAi\backend\venv\Lib\site-packages\django\db\backends\utils.py", line 92, in _execute_with_wrappers
    return executor(sql, params, many, context)
           ^^^^^^^^^^^^^^^^^^^^^^^^^^^^^^^^^^^^
  File "C:\Users\HP\Desktop\projects\safeNetAi\backend\venv\Lib\site-packages\django\db\backends\utils.py", line 100, in _execute
    with self.db.wrap_database_errors:
  File "C:\Users\HP\Desktop\projects\safeNetAi\backend\venv\Lib\site-packages\django\db\utils.py", line 91, in __exit__
    raise dj_exc_value.with_traceback(traceback) from exc_value
  File "C:\Users\HP\Desktop\projects\safeNetAi\backend\venv\Lib\site-packages\django\db\backends\utils.py", line 105, in _execute
    return self.cursor.execute(sql, params)
           ^^^^^^^^^^^^^^^^^^^^^^^^^^^^^^^^
  File "C:\Users\HP\Desktop\projects\safeNetAi\backend\venv\Lib\site-packages\django\db\backends\sqlite3\base.py", line 360, in execute
    return super().execute(query, params)
           ^^^^^^^^^^^^^^^^^^^^^^^^^^^^^^
django.db.utils.OperationalError: no such column: transactions_transaction.current_lat
[2025-09-04 15:53:48] [ERROR] [django.server] "GET /admin/transactions/transaction/ HTTP/1.1" 500 208054
