[2025-09-04 13:53:00] [INFO] [django.utils.autoreload] Watching for file changes with StatReloader
[2025-09-04 13:53:49] [INFO] [django.server] "OPTIONS /api/client/transactions/ HTTP/1.1" 200 0
[2025-09-04 13:53:49] [INFO] [django.server] "OPTIONS /api/client/profile/me/ HTTP/1.1" 200 0
[2025-09-04 13:53:49] [INFO] [django.server] "OPTIONS /api/client/profile/me/ HTTP/1.1" 200 0
[2025-09-04 13:53:49] [INFO] [django.server] "OPTIONS /api/client/transactions/ HTTP/1.1" 200 0
[2025-09-04 13:53:50] [WARNING] [django.request] Unauthorized: /api/client/transactions/
[2025-09-04 13:53:50] [WARNING] [django.request] Unauthorized: /api/client/profile/me/
[2025-09-04 13:53:50] [WARNING] [django.server] "GET /api/client/profile/me/ HTTP/1.1" 401 172
[2025-09-04 13:53:50] [WARNING] [django.server] "GET /api/client/transactions/ HTTP/1.1" 401 172
[2025-09-04 13:53:50] [WARNING] [django.request] Unauthorized: /api/client/transactions/
[2025-09-04 13:53:50] [WARNING] [django.request] Unauthorized: /api/client/profile/me/
[2025-09-04 13:53:50] [INFO] [django.server] "OPTIONS /api/auth/refresh/ HTTP/1.1" 200 0
[2025-09-04 13:53:50] [INFO] [django.server] "OPTIONS /api/auth/refresh/ HTTP/1.1" 200 0
[2025-09-04 13:53:50] [WARNING] [django.server] "GET /api/client/profile/me/ HTTP/1.1" 401 172
[2025-09-04 13:53:50] [WARNING] [django.server] "GET /api/client/transactions/ HTTP/1.1" 401 172
[2025-09-04 13:53:50] [INFO] [django.server] "POST /api/auth/refresh/ HTTP/1.1" 200 245
[2025-09-04 13:53:50] [INFO] [django.server] "POST /api/auth/refresh/ HTTP/1.1" 200 245
[2025-09-04 13:53:50] [INFO] [django.server] "POST /api/auth/refresh/ HTTP/1.1" 200 245
[2025-09-04 13:53:50] [INFO] [django.server] "POST /api/auth/refresh/ HTTP/1.1" 200 245
[2025-09-04 13:53:50] [INFO] [django.server] "GET /api/client/profile/me/ HTTP/1.1" 200 477
[2025-09-04 13:53:50] [INFO] [django.server] "GET /api/client/transactions/ HTTP/1.1" 200 1484
[2025-09-04 13:53:50] [INFO] [django.server] "GET /api/client/profile/me/ HTTP/1.1" 200 477
[2025-09-04 13:53:50] [INFO] [django.server] "GET /api/client/transactions/ HTTP/1.1" 200 1484
[2025-09-04 13:53:59] [INFO] [django.server] "OPTIONS /api/auth/login/ HTTP/1.1" 200 0
[2025-09-04 13:54:00] [INFO] [django.server] "POST /api/auth/login/ HTTP/1.1" 200 638
[2025-09-04 13:54:00] [INFO] [django.server] "OPTIONS /api/admin/dashboard/stats/ HTTP/1.1" 200 0
[2025-09-04 13:54:00] [INFO] [django.server] "OPTIONS /api/admin/dashboard/recent_activity/ HTTP/1.1" 200 0
[2025-09-04 13:54:00] [INFO] [django.server] "OPTIONS /api/admin/dashboard/recent_activity/ HTTP/1.1" 200 0
[2025-09-04 13:54:00] [INFO] [system] Dashboard stats requested by admin admin@safenetai.com
[2025-09-04 13:54:00] [INFO] [django.server] "GET /api/admin/dashboard/stats/ HTTP/1.1" 200 245
[2025-09-04 13:54:00] [INFO] [system] Dashboard stats requested by admin admin@safenetai.com
[2025-09-04 13:54:00] [INFO] [django.server] "GET /api/admin/dashboard/stats/ HTTP/1.1" 200 245
[2025-09-04 13:54:00] [INFO] [system] Recent activity requested by admin admin@safenetai.com
[2025-09-04 13:54:00] [INFO] [django.server] "GET /api/admin/dashboard/recent_activity/ HTTP/1.1" 200 8264
[2025-09-04 13:54:00] [INFO] [system] Recent activity requested by admin admin@safenetai.com
[2025-09-04 13:54:00] [INFO] [django.server] "GET /api/admin/dashboard/recent_activity/ HTTP/1.1" 200 8264
[2025-09-04 13:54:05] [INFO] [django.server] "OPTIONS /api/admin/clients/ HTTP/1.1" 200 0
[2025-09-04 13:54:05] [INFO] [django.server] "OPTIONS /api/admin/clients/ HTTP/1.1" 200 0
[2025-09-04 13:54:05] [INFO] [django.server] "GET /api/admin/clients/ HTTP/1.1" 200 23935
[2025-09-04 13:54:05] [INFO] [django.server] "GET /api/admin/clients/ HTTP/1.1" 200 23935
[2025-09-04 13:54:08] [INFO] [django.server] "OPTIONS /api/admin/transactions/ HTTP/1.1" 200 0
[2025-09-04 13:54:08] [INFO] [django.server] "OPTIONS /api/admin/transactions/ HTTP/1.1" 200 0
[2025-09-04 13:54:08] [INFO] [django.server] "GET /api/admin/transactions/ HTTP/1.1" 200 17158
[2025-09-04 13:54:08] [INFO] [django.server] "GET /api/admin/transactions/ HTTP/1.1" 200 17158
[2025-09-04 13:54:13] [INFO] [django.server] "OPTIONS /api/admin/fraud-alerts/ HTTP/1.1" 200 0
[2025-09-04 13:54:13] [INFO] [django.server] "OPTIONS /api/admin/fraud-alerts/ HTTP/1.1" 200 0
[2025-09-04 13:54:13] [INFO] [django.server] "GET /api/admin/fraud-alerts/ HTTP/1.1" 200 15005
[2025-09-04 13:54:13] [INFO] [django.server] "GET /api/admin/fraud-alerts/ HTTP/1.1" 200 15005
[2025-09-04 13:54:26] [INFO] [django.server] "OPTIONS /api/admin/fraud-alerts/?status=Pending HTTP/1.1" 200 0
[2025-09-04 13:54:26] [INFO] [django.server] "GET /api/admin/fraud-alerts/?status=Pending HTTP/1.1" 200 2
[2025-09-04 13:54:29] [INFO] [django.server] "OPTIONS /api/admin/fraud-alerts/?status=Reviewed HTTP/1.1" 200 0
[2025-09-04 13:54:29] [INFO] [django.server] "GET /api/admin/fraud-alerts/?status=Reviewed HTTP/1.1" 200 3163
[2025-09-04 13:54:42] [INFO] [django.server] "OPTIONS /api/admin/fraud-alerts/?level=Medium&status=Reviewed HTTP/1.1" 200 0
[2025-09-04 13:54:42] [INFO] [django.server] "GET /api/admin/fraud-alerts/?level=Medium&status=Reviewed HTTP/1.1" 200 2
[2025-09-04 13:54:45] [INFO] [django.server] "GET /api/admin/fraud-alerts/?status=Reviewed HTTP/1.1" 200 3163
[2025-09-04 13:54:53] [INFO] [django.server] "GET /api/admin/fraud-alerts/ HTTP/1.1" 200 15005
[2025-09-04 13:55:29] [INFO] [django.server] "OPTIONS /api/admin/thresholds/ HTTP/1.1" 200 0
[2025-09-04 13:55:29] [INFO] [django.server] "OPTIONS /api/admin/rules/ HTTP/1.1" 200 0
[2025-09-04 13:55:29] [INFO] [django.server] "OPTIONS /api/admin/rules/ HTTP/1.1" 200 0
[2025-09-04 13:55:29] [INFO] [django.server] "GET /api/admin/thresholds/ HTTP/1.1" 200 1092
[2025-09-04 13:55:29] [INFO] [django.server] "GET /api/admin/rules/ HTTP/1.1" 200 574
[2025-09-04 13:55:29] [INFO] [django.server] "GET /api/admin/thresholds/ HTTP/1.1" 200 1092
[2025-09-04 13:55:29] [INFO] [django.server] "GET /api/admin/rules/ HTTP/1.1" 200 574
[2025-09-04 13:55:37] [INFO] [django.server] "OPTIONS /api/admin/thresholds/21/ HTTP/1.1" 200 0
[2025-09-04 13:55:37] [INFO] [django.server] "PATCH /api/admin/thresholds/21/ HTTP/1.1" 200 62
[2025-09-04 13:55:37] [INFO] [django.server] "GET /api/admin/thresholds/ HTTP/1.1" 200 1091
[2025-09-04 13:55:37] [INFO] [django.server] "GET /api/admin/rules/ HTTP/1.1" 200 574
[2025-09-04 13:56:00] [INFO] [django.server] "POST /api/auth/login/ HTTP/1.1" 200 647
[2025-09-04 13:56:00] [INFO] [django.server] "GET /api/client/profile/me/ HTTP/1.1" 200 469
[2025-09-04 13:56:00] [INFO] [django.server] "GET /api/client/profile/me/ HTTP/1.1" 200 469
[2025-09-04 13:56:00] [INFO] [django.server] "GET /api/client/transactions/ HTTP/1.1" 200 8476
[2025-09-04 13:56:00] [INFO] [django.server] "GET /api/client/transactions/ HTTP/1.1" 200 8476
[2025-09-04 13:56:33] [INFO] [system] System event: RiskEngine initialized | Component: risk_engine | Severity: INFO | Data: {"thresholds_count": 13, "rules_count": 4}
[2025-09-04 13:56:33] [INFO] [system] System event: RiskEngine initialized | Component: risk_engine | Severity: INFO | Data: {"thresholds_count": 13, "rules_count": 4}
[2025-09-04 13:56:39] [INFO] [system] System event: ML model loaded successfully | Component: fraud_ml_model | Severity: INFO | Data: {"model_path": "C:\\Users\\HP\\Desktop\\projects\\safeNetAi\\backend\\models\\fraud_isolation.joblib"}
[2025-09-04 13:56:51] [INFO] [system] System event: Security OTP email sent successfully | Component: email_service | Severity: INFO | Data: {"user_email": "abassi.loay@gmail.com", "user_id": 61, "transaction_id": 315, "otp_code": "212810"}
[2025-09-04 13:56:51] [INFO] [system] System event: Transaction OTP created and sent successfully | Component: transactions | Severity: INFO | Data: {"user_email": "abassi.loay@gmail.com", "user_id": 61, "transaction_id": 315, "otp_id": 27}
[2025-09-04 13:56:51] [WARNING] [system] System event: Transaction requires OTP verification due to risk rules or AI assessment | Component: transactions | Severity: WARNING | Data: {"transaction_id": 315, "risk_score": 71, "triggers": ["Enhanced distance rule: 66.70km from home > 50.0km threshold"], "ml_score": 0.5447760545624403, "user_id": 61, "distance_violation": false, "otp_reasons": ["Business rules triggered: 1", "High risk score: 71"], "reason": "risk_rules"}
[2025-09-04 13:56:52] [INFO] [django.server] "POST /api/client/transactions/ HTTP/1.1" 201 380
[2025-09-04 13:58:04] [INFO] [django.server] "OPTIONS /api/client/transactions/315/verify_otp/ HTTP/1.1" 200 0
[2025-09-04 13:58:04] [INFO] [system] System event: Transaction OTP verified successfully | Component: transactions | Severity: INFO | Data: {"user_email": "abassi.loay@gmail.com", "user_id": 61, "transaction_id": 315, "otp_id": 27}
[2025-09-04 13:58:17] [INFO] [system] System event: Transaction notification sent successfully | Component: email_service | Severity: INFO | Data: {"user_email": "abassi.loay@gmail.com", "user_id": 61, "transaction_id": 315, "status": "COMPLETED", "risk_level": "HIGH", "risk_score": 71}
[2025-09-04 13:58:17] [INFO] [django.server] "POST /api/client/transactions/315/verify_otp/ HTTP/1.1" 200 114
[2025-09-04 13:58:21] [INFO] [django.server] "GET /api/client/profile/me/ HTTP/1.1" 200 469
[2025-09-04 13:58:21] [INFO] [django.server] "GET /api/client/profile/me/ HTTP/1.1" 200 469
[2025-09-04 13:58:21] [INFO] [django.server] "GET /api/client/transactions/ HTTP/1.1" 200 8770
[2025-09-04 13:58:21] [INFO] [django.server] "GET /api/client/transactions/ HTTP/1.1" 200 8770
[2025-09-04 13:58:26] [INFO] [django.server] "GET /api/client/profile/me/ HTTP/1.1" 200 469
[2025-09-04 13:58:26] [INFO] [django.server] "GET /api/client/transactions/ HTTP/1.1" 200 8770
[2025-09-04 13:58:44] [INFO] [django.server] "GET /admin/ HTTP/1.1" 200 16310
[2025-09-04 13:58:44] [INFO] [django.server] "GET /static/admin/css/base.css HTTP/1.1" 304 0
[2025-09-04 13:58:44] [INFO] [django.server] "GET /static/admin/css/dark_mode.css HTTP/1.1" 304 0
[2025-09-04 13:58:44] [INFO] [django.server] "GET /static/admin/js/theme.js HTTP/1.1" 304 0
[2025-09-04 13:58:44] [INFO] [django.server] "GET /static/admin/css/responsive.css HTTP/1.1" 304 0
[2025-09-04 13:58:44] [INFO] [django.server] "GET /static/admin/css/nav_sidebar.css HTTP/1.1" 304 0
[2025-09-04 13:58:44] [INFO] [django.server] "GET /static/admin/css/dashboard.css HTTP/1.1" 304 0
[2025-09-04 13:58:44] [INFO] [django.server] "GET /static/admin/js/nav_sidebar.js HTTP/1.1" 304 0
[2025-09-04 13:58:44] [INFO] [django.server] "GET /static/admin/img/icon-addlink.svg HTTP/1.1" 304 0
[2025-09-04 13:58:44] [INFO] [django.server] "GET /static/admin/img/icon-changelink.svg HTTP/1.1" 304 0
[2025-09-04 13:58:44] [INFO] [django.server] "GET /static/admin/img/icon-deletelink.svg HTTP/1.1" 304 0
[2025-09-04 13:58:44] [WARNING] [django.request] Not Found: /favicon.ico
[2025-09-04 13:58:44] [WARNING] [django.server] "GET /favicon.ico HTTP/1.1" 404 3746
[2025-09-04 13:58:47] [INFO] [django.server] "GET /admin/risk/clientprofile/ HTTP/1.1" 200 48146
[2025-09-04 13:58:47] [INFO] [django.server] "GET /static/admin/js/jquery.init.js HTTP/1.1" 304 0
[2025-09-04 13:58:47] [INFO] [django.server] "GET /static/admin/js/core.js HTTP/1.1" 304 0
[2025-09-04 13:58:47] [INFO] [django.server] "GET /static/admin/css/changelists.css HTTP/1.1" 304 0
[2025-09-04 13:58:47] [INFO] [django.server] "GET /static/admin/js/actions.js HTTP/1.1" 304 0
[2025-09-04 13:58:47] [INFO] [django.server] "GET /static/admin/js/admin/RelatedObjectLookups.js HTTP/1.1" 304 0
[2025-09-04 13:58:47] [INFO] [django.server] "GET /static/admin/js/vendor/jquery/jquery.js HTTP/1.1" 304 0
[2025-09-04 13:58:47] [INFO] [django.server] "GET /static/admin/js/prepopulate.js HTTP/1.1" 304 0
[2025-09-04 13:58:47] [INFO] [django.server] "GET /static/admin/js/urlify.js HTTP/1.1" 304 0
[2025-09-04 13:58:47] [INFO] [django.server] "GET /static/admin/js/vendor/xregexp/xregexp.js HTTP/1.1" 304 0
[2025-09-04 13:58:47] [INFO] [django.server] "GET /admin/jsi18n/ HTTP/1.1" 200 3342
[2025-09-04 13:58:48] [INFO] [django.server] "GET /static/admin/img/search.svg HTTP/1.1" 304 0
[2025-09-04 13:58:48] [INFO] [django.server] "GET /static/admin/js/filters.js HTTP/1.1" 304 0
[2025-09-04 13:58:48] [INFO] [django.server] "GET /static/admin/img/tooltag-add.svg HTTP/1.1" 304 0
[2025-09-04 13:58:48] [INFO] [django.server] "GET /static/admin/img/sorting-icons.svg HTTP/1.1" 304 0
[2025-09-04 13:58:48] [INFO] [django.server] "GET /static/admin/img/icon-viewlink.svg HTTP/1.1" 304 0
[2025-09-04 13:58:50] [INFO] [django.server] "GET /admin/risk/clientprofile/80/change/ HTTP/1.1" 200 27961
[2025-09-04 13:58:50] [INFO] [django.server] "GET /static/admin/css/forms.css HTTP/1.1" 304 0
[2025-09-04 13:58:50] [INFO] [django.server] "GET /static/admin/js/prepopulate_init.js HTTP/1.1" 304 0
[2025-09-04 13:58:50] [INFO] [django.server] "GET /static/admin/css/widgets.css HTTP/1.1" 304 0
[2025-09-04 13:58:50] [INFO] [django.server] "GET /admin/jsi18n/ HTTP/1.1" 200 3342
[2025-09-04 13:58:50] [INFO] [django.server] "GET /static/admin/js/change_form.js HTTP/1.1" 304 0
[2025-09-04 13:59:13] [INFO] [system] System event: RiskEngine initialized | Component: risk_engine | Severity: INFO | Data: {"thresholds_count": 13, "rules_count": 4}
[2025-09-04 13:59:13] [INFO] [system] System event: RiskEngine initialized | Component: risk_engine | Severity: INFO | Data: {"thresholds_count": 13, "rules_count": 4}
[2025-09-04 13:59:13] [INFO] [system] System event: ML model loaded successfully | Component: fraud_ml_model | Severity: INFO | Data: {"model_path": "C:\\Users\\HP\\Desktop\\projects\\safeNetAi\\backend\\models\\fraud_isolation.joblib"}
[2025-09-04 13:59:20] [INFO] [system] System event: Security OTP email sent successfully | Component: email_service | Severity: INFO | Data: {"user_email": "abassi.loay@gmail.com", "user_id": 61, "transaction_id": 316, "otp_code": "832848"}
[2025-09-04 13:59:20] [INFO] [system] System event: Transaction OTP created and sent successfully | Component: transactions | Severity: INFO | Data: {"user_email": "abassi.loay@gmail.com", "user_id": 61, "transaction_id": 316, "otp_id": 28}
[2025-09-04 13:59:20] [WARNING] [system] System event: Transaction requires OTP verification due to risk rules or AI assessment | Component: transactions | Severity: WARNING | Data: {"transaction_id": 316, "risk_score": 69, "triggers": ["Enhanced distance rule: 66.70km from home > 50.0km threshold"], "ml_score": 0.4950104268254103, "user_id": 61, "distance_violation": false, "otp_reasons": ["Business rules triggered: 1"], "reason": "risk_rules"}
[2025-09-04 13:59:20] [INFO] [django.server] "POST /api/client/transactions/ HTTP/1.1" 201 358
[2025-09-04 14:01:00] [INFO] [system] System event: RiskEngine initialized | Component: risk_engine | Severity: INFO | Data: {"thresholds_count": 13, "rules_count": 4}
[2025-09-04 14:01:00] [INFO] [system] System event: RiskEngine initialized | Component: risk_engine | Severity: INFO | Data: {"thresholds_count": 13, "rules_count": 4}
[2025-09-04 14:01:00] [INFO] [system] System event: ML model loaded successfully | Component: fraud_ml_model | Severity: INFO | Data: {"model_path": "C:\\Users\\HP\\Desktop\\projects\\safeNetAi\\backend\\models\\fraud_isolation.joblib"}
[2025-09-04 14:01:05] [INFO] [system] System event: Security OTP email sent successfully | Component: email_service | Severity: INFO | Data: {"user_email": "abassi.loay@gmail.com", "user_id": 61, "transaction_id": 317, "otp_code": "657655"}
[2025-09-04 14:01:05] [INFO] [system] System event: Transaction OTP created and sent successfully | Component: transactions | Severity: INFO | Data: {"user_email": "abassi.loay@gmail.com", "user_id": 61, "transaction_id": 317, "otp_id": 29}
[2025-09-04 14:01:05] [WARNING] [system] System event: Transaction requires OTP verification due to risk rules or AI assessment | Component: transactions | Severity: WARNING | Data: {"transaction_id": 317, "risk_score": 69, "triggers": ["Enhanced distance rule: 66.70km from home > 50.0km threshold"], "ml_score": 0.4942724517815491, "user_id": 61, "distance_violation": false, "otp_reasons": ["Business rules triggered: 1"], "reason": "risk_rules"}
[2025-09-04 14:01:05] [INFO] [django.server] "POST /api/client/transactions/ HTTP/1.1" 201 358
[2025-09-04 14:01:24] [INFO] [django.server] "OPTIONS /api/client/transactions/317/verify_otp/ HTTP/1.1" 200 0
[2025-09-04 14:01:24] [INFO] [system] System event: Transaction OTP verified successfully | Component: transactions | Severity: INFO | Data: {"user_email": "abassi.loay@gmail.com", "user_id": 61, "transaction_id": 317, "otp_id": 29}
[2025-09-04 14:01:33] [INFO] [system] System event: Transaction notification sent successfully | Component: email_service | Severity: INFO | Data: {"user_email": "abassi.loay@gmail.com", "user_id": 61, "transaction_id": 317, "status": "COMPLETED", "risk_level": "MEDIUM", "risk_score": 69}
[2025-09-04 14:01:33] [INFO] [django.server] "POST /api/client/transactions/317/verify_otp/ HTTP/1.1" 200 114
[2025-09-04 14:01:39] [INFO] [django.server] "GET /api/client/profile/me/ HTTP/1.1" 200 469
[2025-09-04 14:01:39] [INFO] [django.server] "GET /api/client/profile/me/ HTTP/1.1" 200 469
[2025-09-04 14:01:39] [INFO] [django.server] "GET /api/client/transactions/ HTTP/1.1" 200 9352
[2025-09-04 14:01:39] [INFO] [django.server] "GET /api/client/transactions/ HTTP/1.1" 200 9352
[2025-09-04 14:08:18] [INFO] [django.utils.autoreload] C:\Users\HP\Desktop\projects\safeNetAi\backend\apps\risk\engine.py changed, reloading.
[2025-09-04 14:08:19] [INFO] [django.utils.autoreload] Watching for file changes with StatReloader
[2025-09-04 14:08:54] [INFO] [django.utils.autoreload] C:\Users\HP\Desktop\projects\safeNetAi\backend\apps\risk\engine.py changed, reloading.
[2025-09-04 14:08:55] [INFO] [django.utils.autoreload] Watching for file changes with StatReloader
[2025-09-04 14:09:31] [INFO] [django.utils.autoreload] C:\Users\HP\Desktop\projects\safeNetAi\backend\apps\risk\ml.py changed, reloading.
[2025-09-04 14:09:32] [INFO] [django.utils.autoreload] Watching for file changes with StatReloader
[2025-09-04 14:10:01] [INFO] [django.utils.autoreload] C:\Users\HP\Desktop\projects\safeNetAi\backend\apps\risk\ml.py changed, reloading.
[2025-09-04 14:10:02] [INFO] [django.utils.autoreload] Watching for file changes with StatReloader
[2025-09-04 14:13:43] [INFO] [django.utils.autoreload] C:\Users\HP\Desktop\projects\safeNetAi\backend\apps\risk\engine.py changed, reloading.
[2025-09-04 14:13:44] [INFO] [django.utils.autoreload] Watching for file changes with StatReloader
[2025-09-04 14:14:05] [INFO] [django.utils.autoreload] C:\Users\HP\Desktop\projects\safeNetAi\backend\apps\risk\engine.py changed, reloading.
[2025-09-04 14:14:06] [INFO] [django.utils.autoreload] Watching for file changes with StatReloader
[2025-09-04 14:14:32] [INFO] [django.utils.autoreload] C:\Users\HP\Desktop\projects\safeNetAi\backend\apps\risk\ml.py changed, reloading.
[2025-09-04 14:14:33] [INFO] [django.utils.autoreload] Watching for file changes with StatReloader
[2025-09-04 14:24:57] [INFO] [django.utils.autoreload] C:\Users\HP\Desktop\projects\safeNetAi\backend\apps\risk\engine.py changed, reloading.
[2025-09-04 14:24:59] [INFO] [django.utils.autoreload] Watching for file changes with StatReloader
[2025-09-04 14:25:15] [INFO] [django.server] "GET /admin/users/user/ HTTP/1.1" 200 50666
[2025-09-04 14:25:16] [INFO] [django.server] "GET /static/admin/img/icon-yes.svg HTTP/1.1" 304 0
[2025-09-04 14:25:16] [INFO] [django.server] "GET /admin/jsi18n/ HTTP/1.1" 200 3342
[2025-09-04 14:25:16] [INFO] [django.server] "GET /static/admin/img/icon-no.svg HTTP/1.1" 304 0
[2025-09-04 14:25:19] [INFO] [django.server] "GET /admin/users/user/61/change/ HTTP/1.1" 200 28780
[2025-09-04 14:25:19] [INFO] [django.server] "GET /static/admin/js/calendar.js HTTP/1.1" 304 0
[2025-09-04 14:25:19] [INFO] [django.server] "GET /static/admin/js/admin/DateTimeShortcuts.js HTTP/1.1" 304 0
[2025-09-04 14:25:19] [INFO] [django.server] "GET /static/admin/js/SelectBox.js HTTP/1.1" 304 0
[2025-09-04 14:25:19] [INFO] [django.server] "GET /static/admin/js/SelectFilter2.js HTTP/1.1" 304 0
[2025-09-04 14:25:19] [INFO] [django.server] "GET /admin/jsi18n/ HTTP/1.1" 200 3342
[2025-09-04 14:25:19] [INFO] [django.server] "GET /static/admin/img/selector-icons.svg HTTP/1.1" 304 0
[2025-09-04 14:25:19] [INFO] [django.server] "GET /static/admin/img/icon-calendar.svg HTTP/1.1" 304 0
[2025-09-04 14:25:19] [INFO] [django.server] "GET /static/admin/img/icon-clock.svg HTTP/1.1" 304 0
[2025-09-04 14:25:25] [INFO] [django.server] "GET /admin/users/user/61/delete/ HTTP/1.1" 200 20185
[2025-09-04 14:25:26] [INFO] [django.server] "GET /static/admin/js/cancel.js HTTP/1.1" 200 884
[2025-09-04 14:25:43] [INFO] [django.server] "GET /admin/users/user/61/change/ HTTP/1.1" 200 28780
[2025-09-04 14:25:44] [INFO] [django.server] "GET /admin/users/user/ HTTP/1.1" 200 50666
[2025-09-04 14:26:01] [INFO] [django.server] "GET /admin/users/ HTTP/1.1" 200 5928
[2025-09-04 14:26:03] [INFO] [django.server] "GET /admin/users/ HTTP/1.1" 200 5928
[2025-09-04 14:26:05] [INFO] [django.server] "GET /admin/ HTTP/1.1" 200 16310
[2025-09-04 14:26:08] [INFO] [django.server] "GET /admin/users/user/ HTTP/1.1" 200 50666
[2025-09-04 14:26:08] [INFO] [django.server] "GET /admin/jsi18n/ HTTP/1.1" 200 3342
[2025-09-04 14:26:22] [INFO] [django.server] "POST /admin/users/user/ HTTP/1.1" 200 20306
[2025-09-04 14:26:26] [INFO] [django.server] "POST /admin/users/user/ HTTP/1.1" 302 0
[2025-09-04 14:26:26] [INFO] [django.server] "GET /admin/users/user/ HTTP/1.1" 200 50170
[2025-09-04 14:26:26] [INFO] [django.server] "GET /admin/jsi18n/ HTTP/1.1" 200 3342
[2025-09-04 14:26:28] [INFO] [django.server] "GET /admin/risk/clientprofile/ HTTP/1.1" 200 47566
[2025-09-04 14:26:28] [INFO] [django.server] "GET /admin/jsi18n/ HTTP/1.1" 200 3342
[2025-09-04 14:26:32] [INFO] [django.server] "GET /admin/risk/clientprofile/add/ HTTP/1.1" 200 27476
[2025-09-04 14:26:32] [INFO] [django.server] "GET /admin/jsi18n/ HTTP/1.1" 200 3342
[2025-09-04 14:26:52] [INFO] [django.server] "POST /admin/risk/clientprofile/add/ HTTP/1.1" 302 0
[2025-09-04 14:26:52] [INFO] [django.server] "GET /admin/risk/clientprofile/ HTTP/1.1" 200 48356
[2025-09-04 14:26:52] [INFO] [django.server] "GET /admin/jsi18n/ HTTP/1.1" 200 3342
[2025-09-04 14:27:48] [INFO] [django.server] "OPTIONS /api/auth/register/ HTTP/1.1" 200 0
[2025-09-04 14:27:48] [WARNING] [django.request] Bad Request: /api/auth/register/
[2025-09-04 14:27:48] [WARNING] [django.server] "POST /api/auth/register/ HTTP/1.1" 400 68
[2025-09-04 14:28:17] [INFO] [django.server] "GET /admin/risk/clientprofile/88/change/ HTTP/1.1" 200 27828
[2025-09-04 14:28:17] [INFO] [django.server] "GET /admin/jsi18n/ HTTP/1.1" 200 3342
[2025-09-04 14:29:22] [INFO] [system] System event: OTP email sent successfully | Component: email_service | Severity: INFO | Data: {"user_email": "abassi.loay@gmail.com", "user_id": 69}
[2025-09-04 14:29:22] [INFO] [system] System event: OTP created and sent successfully | Component: email_service | Severity: INFO | Data: {"user_email": "abassi.loay@gmail.com", "user_id": 69, "otp_id": 18}
[2025-09-04 14:29:22] [INFO] [django.server] "POST /api/auth/register/ HTTP/1.1" 201 116
[2025-09-04 14:29:26] [INFO] [django.server] "GET /admin/risk/clientprofile/ HTTP/1.1" 200 48128
[2025-09-04 14:29:26] [INFO] [django.server] "GET /admin/jsi18n/ HTTP/1.1" 200 3342
[2025-09-04 14:29:28] [INFO] [django.server] "GET /admin/risk/clientprofile/88/change/ HTTP/1.1" 200 27881
[2025-09-04 14:29:28] [INFO] [django.server] "GET /admin/jsi18n/ HTTP/1.1" 200 3342
[2025-09-04 14:29:44] [INFO] [django.server] "OPTIONS /api/auth/verify-otp/ HTTP/1.1" 200 0
[2025-09-04 14:29:44] [INFO] [django.server] "POST /api/auth/verify-otp/ HTTP/1.1" 200 634
[2025-09-04 14:29:44] [INFO] [django.server] "GET /api/client/profile/me/ HTTP/1.1" 200 434
[2025-09-04 14:29:44] [INFO] [django.server] "GET /api/client/transactions/ HTTP/1.1" 200 2
[2025-09-04 14:29:44] [INFO] [django.server] "GET /api/client/profile/me/ HTTP/1.1" 200 434
[2025-09-04 14:29:44] [INFO] [django.server] "GET /api/client/transactions/ HTTP/1.1" 200 2
[2025-09-04 14:29:48] [INFO] [django.server] "GET /admin/risk/clientprofile/88/change/ HTTP/1.1" 200 27881
[2025-09-04 14:29:48] [INFO] [django.server] "GET /admin/jsi18n/ HTTP/1.1" 200 3342
[2025-09-04 14:30:02] [INFO] [django.server] "GET /admin/users/user/ HTTP/1.1" 200 50666
[2025-09-04 14:30:02] [INFO] [django.server] "GET /admin/jsi18n/ HTTP/1.1" 200 3342
[2025-09-04 14:30:07] [INFO] [django.server] "POST /admin/users/user/ HTTP/1.1" 200 12888
[2025-09-04 14:30:20] [INFO] [django.server] "POST /admin/users/user/ HTTP/1.1" 302 0
[2025-09-04 14:30:20] [INFO] [django.server] "GET /admin/users/user/ HTTP/1.1" 200 50170
[2025-09-04 14:30:20] [INFO] [django.server] "GET /admin/jsi18n/ HTTP/1.1" 200 3342
[2025-09-04 14:30:26] [INFO] [django.server] "GET /admin/risk/clientprofile/ HTTP/1.1" 200 47566
[2025-09-04 14:30:26] [INFO] [django.server] "GET /admin/jsi18n/ HTTP/1.1" 200 3342
[2025-09-04 14:30:40] [INFO] [django.server] "GET /admin/risk/clientprofile/add/ HTTP/1.1" 200 27476
[2025-09-04 14:30:40] [INFO] [django.server] "GET /admin/jsi18n/ HTTP/1.1" 200 3342
[2025-09-04 14:30:53] [INFO] [django.server] "POST /admin/risk/clientprofile/add/ HTTP/1.1" 200 27789
[2025-09-04 14:30:53] [INFO] [django.server] "GET /admin/jsi18n/ HTTP/1.1" 200 3342
[2025-09-04 14:31:06] [INFO] [django.server] "POST /admin/risk/clientprofile/add/ HTTP/1.1" 302 0
[2025-09-04 14:31:06] [INFO] [django.server] "GET /admin/risk/clientprofile/ HTTP/1.1" 200 48356
[2025-09-04 14:31:06] [INFO] [django.server] "GET /admin/jsi18n/ HTTP/1.1" 200 3342
[2025-09-04 14:31:10] [INFO] [django.server] "GET /admin/risk/clientprofile/89/change/ HTTP/1.1" 200 27828
[2025-09-04 14:31:10] [INFO] [django.server] "GET /admin/jsi18n/ HTTP/1.1" 200 3342
[2025-09-04 14:31:20] [WARNING] [django.request] Unauthorized: /api/client/profile/me/
[2025-09-04 14:31:20] [WARNING] [django.server] "GET /api/client/profile/me/ HTTP/1.1" 401 51
[2025-09-04 14:31:20] [WARNING] [django.request] Unauthorized: /api/client/transactions/
[2025-09-04 14:31:20] [WARNING] [django.server] "GET /api/client/transactions/ HTTP/1.1" 401 51
[2025-09-04 14:31:20] [WARNING] [django.request] Unauthorized: /api/client/profile/me/
[2025-09-04 14:31:20] [WARNING] [django.server] "GET /api/client/profile/me/ HTTP/1.1" 401 51
[2025-09-04 14:31:20] [ERROR] [django.request] Internal Server Error: /api/auth/refresh/
Traceback (most recent call last):
  File "C:\Users\HP\Desktop\projects\safeNetAi\backend\venv\Lib\site-packages\django\core\handlers\exception.py", line 55, in inner
    response = get_response(request)
               ^^^^^^^^^^^^^^^^^^^^^
  File "C:\Users\HP\Desktop\projects\safeNetAi\backend\venv\Lib\site-packages\django\core\handlers\base.py", line 197, in _get_response
    response = wrapped_callback(request, *callback_args, **callback_kwargs)
               ^^^^^^^^^^^^^^^^^^^^^^^^^^^^^^^^^^^^^^^^^^^^^^^^^^^^^^^^^^^^
  File "C:\Users\HP\Desktop\projects\safeNetAi\backend\venv\Lib\site-packages\django\views\decorators\csrf.py", line 65, in _view_wrapper
    return view_func(request, *args, **kwargs)
           ^^^^^^^^^^^^^^^^^^^^^^^^^^^^^^^^^^^
  File "C:\Users\HP\Desktop\projects\safeNetAi\backend\venv\Lib\site-packages\django\views\generic\base.py", line 105, in view
    return self.dispatch(request, *args, **kwargs)
           ^^^^^^^^^^^^^^^^^^^^^^^^^^^^^^^^^^^^^^^
  File "C:\Users\HP\Desktop\projects\safeNetAi\backend\venv\Lib\site-packages\rest_framework\views.py", line 515, in dispatch
    response = self.handle_exception(exc)
               ^^^^^^^^^^^^^^^^^^^^^^^^^^
  File "C:\Users\HP\Desktop\projects\safeNetAi\backend\venv\Lib\site-packages\rest_framework\views.py", line 475, in handle_exception
    self.raise_uncaught_exception(exc)
  File "C:\Users\HP\Desktop\projects\safeNetAi\backend\venv\Lib\site-packages\rest_framework\views.py", line 486, in raise_uncaught_exception
    raise exc
  File "C:\Users\HP\Desktop\projects\safeNetAi\backend\venv\Lib\site-packages\rest_framework\views.py", line 512, in dispatch
    response = handler(request, *args, **kwargs)
               ^^^^^^^^^^^^^^^^^^^^^^^^^^^^^^^^^
  File "C:\Users\HP\Desktop\projects\safeNetAi\backend\venv\Lib\site-packages\rest_framework_simplejwt\views.py", line 46, in post
    serializer.is_valid(raise_exception=True)
  File "C:\Users\HP\Desktop\projects\safeNetAi\backend\venv\Lib\site-packages\rest_framework\serializers.py", line 225, in is_valid
    self._validated_data = self.run_validation(self.initial_data)
                           ^^^^^^^^^^^^^^^^^^^^^^^^^^^^^^^^^^^^^^
  File "C:\Users\HP\Desktop\projects\safeNetAi\backend\venv\Lib\site-packages\rest_framework\serializers.py", line 447, in run_validation
    value = self.validate(value)
            ^^^^^^^^^^^^^^^^^^^^
  File "C:\Users\HP\Desktop\projects\safeNetAi\backend\venv\Lib\site-packages\rest_framework_simplejwt\serializers.py", line 116, in validate
    user := get_user_model().objects.get(
            ^^^^^^^^^^^^^^^^^^^^^^^^^^^^^
  File "C:\Users\HP\Desktop\projects\safeNetAi\backend\venv\Lib\site-packages\django\db\models\manager.py", line 87, in manager_method
    return getattr(self.get_queryset(), name)(*args, **kwargs)
           ^^^^^^^^^^^^^^^^^^^^^^^^^^^^^^^^^^^^^^^^^^^^^^^^^^^
  File "C:\Users\HP\Desktop\projects\safeNetAi\backend\venv\Lib\site-packages\django\db\models\query.py", line 633, in get
    raise self.model.DoesNotExist(
apps.users.models.User.DoesNotExist: User matching query does not exist.
[2025-09-04 14:31:20] [ERROR] [django.server] "POST /api/auth/refresh/ HTTP/1.1" 500 134465
[2025-09-04 14:31:20] [WARNING] [django.request] Unauthorized: /api/client/transactions/
[2025-09-04 14:31:20] [WARNING] [django.server] "GET /api/client/transactions/ HTTP/1.1" 401 51
[2025-09-04 14:31:20] [ERROR] [django.request] Internal Server Error: /api/auth/refresh/
Traceback (most recent call last):
  File "C:\Users\HP\Desktop\projects\safeNetAi\backend\venv\Lib\site-packages\django\core\handlers\exception.py", line 55, in inner
    response = get_response(request)
               ^^^^^^^^^^^^^^^^^^^^^
  File "C:\Users\HP\Desktop\projects\safeNetAi\backend\venv\Lib\site-packages\django\core\handlers\base.py", line 197, in _get_response
    response = wrapped_callback(request, *callback_args, **callback_kwargs)
               ^^^^^^^^^^^^^^^^^^^^^^^^^^^^^^^^^^^^^^^^^^^^^^^^^^^^^^^^^^^^
  File "C:\Users\HP\Desktop\projects\safeNetAi\backend\venv\Lib\site-packages\django\views\decorators\csrf.py", line 65, in _view_wrapper
    return view_func(request, *args, **kwargs)
           ^^^^^^^^^^^^^^^^^^^^^^^^^^^^^^^^^^^
  File "C:\Users\HP\Desktop\projects\safeNetAi\backend\venv\Lib\site-packages\django\views\generic\base.py", line 105, in view
    return self.dispatch(request, *args, **kwargs)
           ^^^^^^^^^^^^^^^^^^^^^^^^^^^^^^^^^^^^^^^
  File "C:\Users\HP\Desktop\projects\safeNetAi\backend\venv\Lib\site-packages\rest_framework\views.py", line 515, in dispatch
    response = self.handle_exception(exc)
               ^^^^^^^^^^^^^^^^^^^^^^^^^^
  File "C:\Users\HP\Desktop\projects\safeNetAi\backend\venv\Lib\site-packages\rest_framework\views.py", line 475, in handle_exception
    self.raise_uncaught_exception(exc)
  File "C:\Users\HP\Desktop\projects\safeNetAi\backend\venv\Lib\site-packages\rest_framework\views.py", line 486, in raise_uncaught_exception
    raise exc
  File "C:\Users\HP\Desktop\projects\safeNetAi\backend\venv\Lib\site-packages\rest_framework\views.py", line 512, in dispatch
    response = handler(request, *args, **kwargs)
               ^^^^^^^^^^^^^^^^^^^^^^^^^^^^^^^^^
  File "C:\Users\HP\Desktop\projects\safeNetAi\backend\venv\Lib\site-packages\rest_framework_simplejwt\views.py", line 46, in post
    serializer.is_valid(raise_exception=True)
  File "C:\Users\HP\Desktop\projects\safeNetAi\backend\venv\Lib\site-packages\rest_framework\serializers.py", line 225, in is_valid
    self._validated_data = self.run_validation(self.initial_data)
                           ^^^^^^^^^^^^^^^^^^^^^^^^^^^^^^^^^^^^^^
  File "C:\Users\HP\Desktop\projects\safeNetAi\backend\venv\Lib\site-packages\rest_framework\serializers.py", line 447, in run_validation
    value = self.validate(value)
            ^^^^^^^^^^^^^^^^^^^^
  File "C:\Users\HP\Desktop\projects\safeNetAi\backend\venv\Lib\site-packages\rest_framework_simplejwt\serializers.py", line 116, in validate
    user := get_user_model().objects.get(
            ^^^^^^^^^^^^^^^^^^^^^^^^^^^^^
  File "C:\Users\HP\Desktop\projects\safeNetAi\backend\venv\Lib\site-packages\django\db\models\manager.py", line 87, in manager_method
    return getattr(self.get_queryset(), name)(*args, **kwargs)
           ^^^^^^^^^^^^^^^^^^^^^^^^^^^^^^^^^^^^^^^^^^^^^^^^^^^
  File "C:\Users\HP\Desktop\projects\safeNetAi\backend\venv\Lib\site-packages\django\db\models\query.py", line 633, in get
    raise self.model.DoesNotExist(
apps.users.models.User.DoesNotExist: User matching query does not exist.
[2025-09-04 14:31:20] [ERROR] [django.server] "POST /api/auth/refresh/ HTTP/1.1" 500 134465
[2025-09-04 14:31:20] [ERROR] [django.request] Internal Server Error: /api/auth/refresh/
Traceback (most recent call last):
  File "C:\Users\HP\Desktop\projects\safeNetAi\backend\venv\Lib\site-packages\django\core\handlers\exception.py", line 55, in inner
    response = get_response(request)
               ^^^^^^^^^^^^^^^^^^^^^
  File "C:\Users\HP\Desktop\projects\safeNetAi\backend\venv\Lib\site-packages\django\core\handlers\base.py", line 197, in _get_response
    response = wrapped_callback(request, *callback_args, **callback_kwargs)
               ^^^^^^^^^^^^^^^^^^^^^^^^^^^^^^^^^^^^^^^^^^^^^^^^^^^^^^^^^^^^
  File "C:\Users\HP\Desktop\projects\safeNetAi\backend\venv\Lib\site-packages\django\views\decorators\csrf.py", line 65, in _view_wrapper
    return view_func(request, *args, **kwargs)
           ^^^^^^^^^^^^^^^^^^^^^^^^^^^^^^^^^^^
  File "C:\Users\HP\Desktop\projects\safeNetAi\backend\venv\Lib\site-packages\django\views\generic\base.py", line 105, in view
    return self.dispatch(request, *args, **kwargs)
           ^^^^^^^^^^^^^^^^^^^^^^^^^^^^^^^^^^^^^^^
  File "C:\Users\HP\Desktop\projects\safeNetAi\backend\venv\Lib\site-packages\rest_framework\views.py", line 515, in dispatch
    response = self.handle_exception(exc)
               ^^^^^^^^^^^^^^^^^^^^^^^^^^
  File "C:\Users\HP\Desktop\projects\safeNetAi\backend\venv\Lib\site-packages\rest_framework\views.py", line 475, in handle_exception
    self.raise_uncaught_exception(exc)
  File "C:\Users\HP\Desktop\projects\safeNetAi\backend\venv\Lib\site-packages\rest_framework\views.py", line 486, in raise_uncaught_exception
    raise exc
  File "C:\Users\HP\Desktop\projects\safeNetAi\backend\venv\Lib\site-packages\rest_framework\views.py", line 512, in dispatch
    response = handler(request, *args, **kwargs)
               ^^^^^^^^^^^^^^^^^^^^^^^^^^^^^^^^^
  File "C:\Users\HP\Desktop\projects\safeNetAi\backend\venv\Lib\site-packages\rest_framework_simplejwt\views.py", line 46, in post
    serializer.is_valid(raise_exception=True)
  File "C:\Users\HP\Desktop\projects\safeNetAi\backend\venv\Lib\site-packages\rest_framework\serializers.py", line 225, in is_valid
    self._validated_data = self.run_validation(self.initial_data)
                           ^^^^^^^^^^^^^^^^^^^^^^^^^^^^^^^^^^^^^^
  File "C:\Users\HP\Desktop\projects\safeNetAi\backend\venv\Lib\site-packages\rest_framework\serializers.py", line 447, in run_validation
    value = self.validate(value)
            ^^^^^^^^^^^^^^^^^^^^
  File "C:\Users\HP\Desktop\projects\safeNetAi\backend\venv\Lib\site-packages\rest_framework_simplejwt\serializers.py", line 116, in validate
    user := get_user_model().objects.get(
            ^^^^^^^^^^^^^^^^^^^^^^^^^^^^^
  File "C:\Users\HP\Desktop\projects\safeNetAi\backend\venv\Lib\site-packages\django\db\models\manager.py", line 87, in manager_method
    return getattr(self.get_queryset(), name)(*args, **kwargs)
           ^^^^^^^^^^^^^^^^^^^^^^^^^^^^^^^^^^^^^^^^^^^^^^^^^^^
  File "C:\Users\HP\Desktop\projects\safeNetAi\backend\venv\Lib\site-packages\django\db\models\query.py", line 633, in get
    raise self.model.DoesNotExist(
apps.users.models.User.DoesNotExist: User matching query does not exist.
[2025-09-04 14:31:20] [INFO] [django.server] - Broken pipe from ('127.0.0.1', 51453)
[2025-09-04 14:31:29] [WARNING] [django.request] Bad Request: /api/auth/login/
[2025-09-04 14:31:29] [WARNING] [django.server] "POST /api/auth/login/ HTTP/1.1" 400 44
[2025-09-04 14:32:07] [INFO] [system] System event: OTP email sent successfully | Component: email_service | Severity: INFO | Data: {"user_email": "abassi.loay@gmail.com", "user_id": 70}
[2025-09-04 14:32:07] [INFO] [system] System event: OTP created and sent successfully | Component: email_service | Severity: INFO | Data: {"user_email": "abassi.loay@gmail.com", "user_id": 70, "otp_id": 19}
[2025-09-04 14:32:07] [INFO] [django.server] "POST /api/auth/register/ HTTP/1.1" 201 116
[2025-09-04 14:32:12] [INFO] [django.server] "GET /admin/risk/clientprofile/ HTTP/1.1" 200 48128
[2025-09-04 14:32:12] [INFO] [django.server] "GET /admin/jsi18n/ HTTP/1.1" 200 3342
[2025-09-04 14:32:14] [INFO] [django.server] "GET /admin/risk/clientprofile/89/change/ HTTP/1.1" 200 27953
[2025-09-04 14:32:14] [INFO] [django.server] "GET /admin/jsi18n/ HTTP/1.1" 200 3342
[2025-09-04 14:32:42] [WARNING] [django.request] Bad Request: /api/auth/login/
[2025-09-04 14:32:42] [WARNING] [django.server] "POST /api/auth/login/ HTTP/1.1" 400 76
[2025-09-04 14:33:09] [INFO] [django.server] "GET /admin/users/user/ HTTP/1.1" 200 50666
[2025-09-04 14:33:09] [INFO] [django.server] "GET /admin/jsi18n/ HTTP/1.1" 200 3342
[2025-09-04 14:33:12] [INFO] [django.server] "POST /admin/users/user/ HTTP/1.1" 200 12752
[2025-09-04 14:33:14] [INFO] [django.server] "POST /admin/users/user/ HTTP/1.1" 302 0
[2025-09-04 14:33:14] [INFO] [django.server] "GET /admin/users/user/ HTTP/1.1" 200 50170
[2025-09-04 14:33:14] [INFO] [django.server] "GET /admin/jsi18n/ HTTP/1.1" 200 3342
[2025-09-04 14:33:23] [INFO] [django.server] "GET /admin/risk/clientprofile/ HTTP/1.1" 200 48128
[2025-09-04 14:33:23] [INFO] [django.server] "GET /admin/jsi18n/ HTTP/1.1" 200 3342
[2025-09-04 14:33:24] [INFO] [django.server] "GET /admin/risk/clientprofile/89/change/ HTTP/1.1" 200 27900
[2025-09-04 14:33:24] [INFO] [django.server] "GET /admin/jsi18n/ HTTP/1.1" 200 3342
[2025-09-04 14:33:31] [INFO] [django.server] "GET /admin/users/user/ HTTP/1.1" 200 50036
[2025-09-04 14:33:31] [INFO] [django.server] "GET /admin/jsi18n/ HTTP/1.1" 200 3342
[2025-09-04 14:33:33] [INFO] [django.server] "GET /admin/risk/clientprofile/ HTTP/1.1" 200 48128
[2025-09-04 14:33:33] [INFO] [django.server] "GET /admin/jsi18n/ HTTP/1.1" 200 3342
[2025-09-04 14:33:43] [INFO] [django.server] "GET /admin/risk/clientprofile/89/change/ HTTP/1.1" 200 27900
[2025-09-04 14:33:43] [INFO] [django.server] "GET /admin/jsi18n/ HTTP/1.1" 200 3342
[2025-09-04 14:34:06] [INFO] [django.server] "POST /admin/risk/clientprofile/89/change/ HTTP/1.1" 302 0
[2025-09-04 14:34:06] [INFO] [django.server] "GET /admin/risk/clientprofile/ HTTP/1.1" 200 48358
[2025-09-04 14:34:06] [INFO] [django.server] "GET /admin/jsi18n/ HTTP/1.1" 200 3342
[2025-09-04 14:34:08] [INFO] [django.server] "GET /admin/risk/clientprofile/89/change/ HTTP/1.1" 200 27900
[2025-09-04 14:34:08] [INFO] [django.server] "GET /admin/jsi18n/ HTTP/1.1" 200 3342
[2025-09-04 14:34:31] [INFO] [system] System event: OTP email sent successfully | Component: email_service | Severity: INFO | Data: {"user_email": "abassi.loay@gmail.com", "user_id": 71}
[2025-09-04 14:34:31] [INFO] [system] System event: OTP created and sent successfully | Component: email_service | Severity: INFO | Data: {"user_email": "abassi.loay@gmail.com", "user_id": 71, "otp_id": 20}
[2025-09-04 14:34:31] [INFO] [django.server] "POST /api/auth/register/ HTTP/1.1" 201 116
[2025-09-04 14:34:41] [INFO] [django.server] "POST /api/auth/verify-otp/ HTTP/1.1" 200 634
[2025-09-04 14:34:41] [INFO] [django.server] "GET /api/client/profile/me/ HTTP/1.1" 200 462
[2025-09-04 14:34:41] [INFO] [django.server] "GET /api/client/transactions/ HTTP/1.1" 200 2
[2025-09-04 14:34:41] [INFO] [django.server] "GET /api/client/profile/me/ HTTP/1.1" 200 462
[2025-09-04 14:34:41] [INFO] [django.server] "GET /api/client/transactions/ HTTP/1.1" 200 2
[2025-09-04 14:34:46] [INFO] [django.server] "GET /admin/risk/clientprofile/89/change/ HTTP/1.1" 200 27953
[2025-09-04 14:34:46] [INFO] [django.server] "GET /admin/jsi18n/ HTTP/1.1" 200 3342
[2025-09-04 14:35:41] [INFO] [django.server] "POST /api/auth/login/ HTTP/1.1" 200 638
[2025-09-04 14:35:41] [INFO] [system] Dashboard stats requested by admin admin@safenetai.com
[2025-09-04 14:35:41] [INFO] [django.server] "GET /api/admin/dashboard/stats/ HTTP/1.1" 200 246
[2025-09-04 14:35:41] [INFO] [system] Recent activity requested by admin admin@safenetai.com
[2025-09-04 14:35:41] [INFO] [django.server] "GET /api/admin/dashboard/recent_activity/ HTTP/1.1" 200 8318
[2025-09-04 14:35:41] [INFO] [system] Dashboard stats requested by admin admin@safenetai.com
[2025-09-04 14:35:41] [INFO] [django.server] "GET /api/admin/dashboard/stats/ HTTP/1.1" 200 246
[2025-09-04 14:35:41] [INFO] [system] Recent activity requested by admin admin@safenetai.com
[2025-09-04 14:35:41] [INFO] [django.server] "GET /api/admin/dashboard/recent_activity/ HTTP/1.1" 200 8318
[2025-09-04 14:35:47] [INFO] [django.server] "GET /api/admin/thresholds/ HTTP/1.1" 200 1091
[2025-09-04 14:35:47] [INFO] [django.server] "GET /api/admin/rules/ HTTP/1.1" 200 574
[2025-09-04 14:35:47] [INFO] [django.server] "GET /api/admin/thresholds/ HTTP/1.1" 200 1091
[2025-09-04 14:35:47] [INFO] [django.server] "GET /api/admin/rules/ HTTP/1.1" 200 574
[2025-09-04 14:36:05] [INFO] [django.server] "OPTIONS /api/admin/thresholds/29/ HTTP/1.1" 200 0
[2025-09-04 14:36:05] [INFO] [django.server] "PATCH /api/admin/thresholds/29/ HTTP/1.1" 200 98
[2025-09-04 14:36:05] [INFO] [django.server] "GET /api/admin/thresholds/ HTTP/1.1" 200 1091
[2025-09-04 14:36:05] [INFO] [django.server] "GET /api/admin/rules/ HTTP/1.1" 200 574
[2025-09-04 14:36:21] [INFO] [django.server] "GET /admin/users/user/ HTTP/1.1" 200 50666
[2025-09-04 14:36:21] [INFO] [django.server] "GET /admin/jsi18n/ HTTP/1.1" 200 3342
[2025-09-04 14:36:25] [INFO] [django.server] "GET /admin/risk/clientprofile/ HTTP/1.1" 200 48148
[2025-09-04 14:36:25] [INFO] [django.server] "GET /admin/jsi18n/ HTTP/1.1" 200 3342
[2025-09-04 14:37:19] [INFO] [django.server] "POST /api/auth/login/ HTTP/1.1" 200 647
[2025-09-04 14:37:19] [INFO] [django.server] "GET /api/client/profile/me/ HTTP/1.1" 200 462
[2025-09-04 14:37:19] [INFO] [django.server] "GET /api/client/transactions/ HTTP/1.1" 200 2
[2025-09-04 14:37:19] [INFO] [django.server] "GET /api/client/profile/me/ HTTP/1.1" 200 462
[2025-09-04 14:37:19] [INFO] [django.server] "GET /api/client/transactions/ HTTP/1.1" 200 2
[2025-09-04 14:37:42] [INFO] [system] System event: RiskEngine initialized | Component: risk_engine | Severity: INFO | Data: {"thresholds_count": 13, "rules_count": 4}
[2025-09-04 14:37:42] [INFO] [system] System event: RiskEngine initialized | Component: risk_engine | Severity: INFO | Data: {"thresholds_count": 13, "rules_count": 4}
[2025-09-04 14:37:44] [INFO] [system] System event: ML model loaded successfully | Component: fraud_ml_model | Severity: INFO | Data: {"model_path": "C:\\Users\\HP\\Desktop\\projects\\safeNetAi\\backend\\models\\fraud_isolation.joblib"}
[2025-09-04 14:37:44] [INFO] [system] System event: RiskEngine initialized | Component: risk_engine | Severity: INFO | Data: {"thresholds_count": 13, "rules_count": 4}
[2025-09-04 14:37:44] [INFO] [system] System event: RiskEngine initialized | Component: risk_engine | Severity: INFO | Data: {"thresholds_count": 13, "rules_count": 4}
[2025-09-04 14:37:44] [ERROR] [system] System event: Error making ML prediction | Component: fraud_ml_model | Severity: ERROR | Data: {"transaction_id": 318, "error": "X has 9 features, but StandardScaler is expecting 7 features as input."}
[2025-09-04 14:37:45] [INFO] [system] System event: Transaction notification sent successfully | Component: email_service | Severity: INFO | Data: {"user_email": "abassi.loay@gmail.com", "user_id": 71, "transaction_id": 318, "status": "COMPLETED", "risk_level": "LOW", "risk_score": 20}
[2025-09-04 14:37:45] [INFO] [django.server] "POST /api/client/transactions/ HTTP/1.1" 201 107
[2025-09-04 14:38:58] [INFO] [django.server] "GET /admin/risk/clientprofile/89/change/ HTTP/1.1" 200 27953
[2025-09-04 14:38:58] [INFO] [django.server] "GET /admin/jsi18n/ HTTP/1.1" 200 3342
[2025-09-04 14:39:42] [INFO] [django.server] "POST /admin/risk/clientprofile/89/change/ HTTP/1.1" 302 0
[2025-09-04 14:39:43] [INFO] [django.server] "GET /admin/risk/clientprofile/ HTTP/1.1" 200 48378
[2025-09-04 14:39:43] [INFO] [django.server] "GET /admin/jsi18n/ HTTP/1.1" 200 3342
[2025-09-04 14:39:55] [INFO] [system] System event: RiskEngine initialized | Component: risk_engine | Severity: INFO | Data: {"thresholds_count": 13, "rules_count": 4}
[2025-09-04 14:39:55] [INFO] [system] System event: RiskEngine initialized | Component: risk_engine | Severity: INFO | Data: {"thresholds_count": 13, "rules_count": 4}
[2025-09-04 14:39:56] [INFO] [system] System event: ML model loaded successfully | Component: fraud_ml_model | Severity: INFO | Data: {"model_path": "C:\\Users\\HP\\Desktop\\projects\\safeNetAi\\backend\\models\\fraud_isolation.joblib"}
[2025-09-04 14:39:56] [INFO] [system] System event: RiskEngine initialized | Component: risk_engine | Severity: INFO | Data: {"thresholds_count": 13, "rules_count": 4}
[2025-09-04 14:39:56] [INFO] [system] System event: RiskEngine initialized | Component: risk_engine | Severity: INFO | Data: {"thresholds_count": 13, "rules_count": 4}
[2025-09-04 14:39:56] [ERROR] [system] System event: Error making ML prediction | Component: fraud_ml_model | Severity: ERROR | Data: {"transaction_id": 319, "error": "X has 9 features, but StandardScaler is expecting 7 features as input."}
[2025-09-04 14:39:57] [INFO] [system] System event: Security OTP email sent successfully | Component: email_service | Severity: INFO | Data: {"user_email": "abassi.loay@gmail.com", "user_id": 71, "transaction_id": 319, "otp_code": "950298"}
[2025-09-04 14:39:57] [INFO] [system] System event: Transaction OTP created and sent successfully | Component: transactions | Severity: INFO | Data: {"user_email": "abassi.loay@gmail.com", "user_id": 71, "transaction_id": 319, "otp_id": 30}
[2025-09-04 14:39:57] [WARNING] [system] System event: Transaction requires OTP verification due to risk rules or AI assessment | Component: transactions | Severity: WARNING | Data: {"transaction_id": 319, "risk_score": 70, "triggers": ["\u26a0\ufe0f Effective distance violation: 159.83km > 50.0km threshold"], "ml_score": 0.5, "user_id": 71, "distance_violation": false, "otp_reasons": ["Business rules triggered: 1", "High risk score: 70", "Risk engine explicit requirement"], "reason": "risk_rules"}
[2025-09-04 14:39:57] [INFO] [django.server] "POST /api/client/transactions/ HTTP/1.1" 201 404
[2025-09-04 14:40:20] [INFO] [django.server] "POST /api/auth/login/ HTTP/1.1" 200 638
[2025-09-04 14:40:20] [INFO] [system] Dashboard stats requested by admin admin@safenetai.com
[2025-09-04 14:40:20] [INFO] [django.server] "GET /api/admin/dashboard/stats/ HTTP/1.1" 200 246
[2025-09-04 14:40:20] [INFO] [system] Dashboard stats requested by admin admin@safenetai.com
[2025-09-04 14:40:20] [INFO] [django.server] "GET /api/admin/dashboard/stats/ HTTP/1.1" 200 246
[2025-09-04 14:40:20] [INFO] [system] Recent activity requested by admin admin@safenetai.com
[2025-09-04 14:40:20] [INFO] [django.server] "GET /api/admin/dashboard/recent_activity/ HTTP/1.1" 200 8243
[2025-09-04 14:40:20] [INFO] [system] Recent activity requested by admin admin@safenetai.com
[2025-09-04 14:40:20] [INFO] [django.server] "GET /api/admin/dashboard/recent_activity/ HTTP/1.1" 200 8243
[2025-09-04 14:40:26] [INFO] [django.server] "GET /api/admin/rules/ HTTP/1.1" 200 574
[2025-09-04 14:40:26] [INFO] [django.server] "GET /api/admin/thresholds/ HTTP/1.1" 200 1091
[2025-09-04 14:40:26] [INFO] [django.server] "GET /api/admin/rules/ HTTP/1.1" 200 574
[2025-09-04 14:40:26] [INFO] [django.server] "GET /api/admin/thresholds/ HTTP/1.1" 200 1091
[2025-09-04 14:40:34] [INFO] [django.server] "OPTIONS /api/admin/thresholds/33/ HTTP/1.1" 200 0
[2025-09-04 14:40:34] [INFO] [django.server] "PATCH /api/admin/thresholds/33/ HTTP/1.1" 200 103
[2025-09-04 14:40:34] [INFO] [django.server] "GET /api/admin/rules/ HTTP/1.1" 200 574
[2025-09-04 14:40:34] [INFO] [django.server] "GET /api/admin/thresholds/ HTTP/1.1" 200 1091
[2025-09-04 14:40:49] [WARNING] [django.request] Bad Request: /api/auth/login/
[2025-09-04 14:40:49] [WARNING] [django.server] "POST /api/auth/login/ HTTP/1.1" 400 44
[2025-09-04 14:40:59] [INFO] [django.server] "POST /api/auth/login/ HTTP/1.1" 200 647
[2025-09-04 14:40:59] [INFO] [django.server] "GET /api/client/profile/me/ HTTP/1.1" 200 461
[2025-09-04 14:40:59] [INFO] [django.server] "GET /api/client/profile/me/ HTTP/1.1" 200 461
[2025-09-04 14:40:59] [INFO] [django.server] "GET /api/client/transactions/ HTTP/1.1" 200 585
[2025-09-04 14:40:59] [INFO] [django.server] "GET /api/client/transactions/ HTTP/1.1" 200 585
[2025-09-04 14:41:02] [INFO] [django.server] "GET /admin/risk/clientprofile/89/change/ HTTP/1.1" 200 27952
[2025-09-04 14:41:03] [INFO] [django.server] "GET /admin/jsi18n/ HTTP/1.1" 200 3342
[2025-09-04 14:41:52] [INFO] [django.server] "POST /admin/risk/clientprofile/89/change/ HTTP/1.1" 302 0
[2025-09-04 14:41:52] [INFO] [django.server] "GET /admin/risk/clientprofile/ HTTP/1.1" 200 48378
[2025-09-04 14:41:52] [INFO] [django.server] "GET /admin/jsi18n/ HTTP/1.1" 200 3342
[2025-09-04 14:42:00] [INFO] [system] System event: RiskEngine initialized | Component: risk_engine | Severity: INFO | Data: {"thresholds_count": 13, "rules_count": 4}
[2025-09-04 14:42:00] [INFO] [system] System event: RiskEngine initialized | Component: risk_engine | Severity: INFO | Data: {"thresholds_count": 13, "rules_count": 4}
[2025-09-04 14:42:00] [INFO] [system] System event: ML model loaded successfully | Component: fraud_ml_model | Severity: INFO | Data: {"model_path": "C:\\Users\\HP\\Desktop\\projects\\safeNetAi\\backend\\models\\fraud_isolation.joblib"}
[2025-09-04 14:42:00] [INFO] [system] System event: RiskEngine initialized | Component: risk_engine | Severity: INFO | Data: {"thresholds_count": 13, "rules_count": 4}
[2025-09-04 14:42:00] [INFO] [system] System event: RiskEngine initialized | Component: risk_engine | Severity: INFO | Data: {"thresholds_count": 13, "rules_count": 4}
[2025-09-04 14:42:00] [ERROR] [system] System event: Error making ML prediction | Component: fraud_ml_model | Severity: ERROR | Data: {"transaction_id": 320, "error": "X has 9 features, but StandardScaler is expecting 7 features as input."}
[2025-09-04 14:42:02] [INFO] [system] System event: Security OTP email sent successfully | Component: email_service | Severity: INFO | Data: {"user_email": "abassi.loay@gmail.com", "user_id": 71, "transaction_id": 320, "otp_code": "506187"}
[2025-09-04 14:42:02] [INFO] [system] System event: Transaction OTP created and sent successfully | Component: transactions | Severity: INFO | Data: {"user_email": "abassi.loay@gmail.com", "user_id": 71, "transaction_id": 320, "otp_id": 31}
[2025-09-04 14:42:02] [WARNING] [system] System event: Transaction requires OTP verification due to risk rules or AI assessment | Component: transactions | Severity: WARNING | Data: {"transaction_id": 320, "risk_score": 70, "triggers": ["\u26a0\ufe0f Effective distance violation: 159.83km > 60.0km threshold"], "ml_score": 0.5, "user_id": 71, "distance_violation": false, "otp_reasons": ["Business rules triggered: 1", "High risk score: 70", "Risk engine explicit requirement"], "reason": "risk_rules"}
[2025-09-04 14:42:02] [INFO] [django.server] "POST /api/client/transactions/ HTTP/1.1" 201 404
[2025-09-04 14:42:56] [INFO] [django.server] "GET /admin/risk/clientprofile/89/change/ HTTP/1.1" 200 27952
[2025-09-04 14:42:56] [INFO] [django.server] "GET /admin/jsi18n/ HTTP/1.1" 200 3342
[2025-09-04 14:43:03] [INFO] [django.server] "OPTIONS /api/client/transactions/320/verify_otp/ HTTP/1.1" 200 0
[2025-09-04 14:43:03] [INFO] [system] System event: Transaction OTP verified successfully | Component: transactions | Severity: INFO | Data: {"user_email": "abassi.loay@gmail.com", "user_id": 71, "transaction_id": 320, "otp_id": 31}
[2025-09-04 14:43:05] [INFO] [system] System event: Transaction notification sent successfully | Component: email_service | Severity: INFO | Data: {"user_email": "abassi.loay@gmail.com", "user_id": 71, "transaction_id": 320, "status": "COMPLETED", "risk_level": "HIGH", "risk_score": 70}
[2025-09-04 14:43:05] [INFO] [django.server] "POST /api/client/transactions/320/verify_otp/ HTTP/1.1" 200 114
[2025-09-04 14:43:09] [INFO] [django.server] "GET /api/client/profile/me/ HTTP/1.1" 200 464
[2025-09-04 14:43:09] [INFO] [django.server] "GET /api/client/transactions/ HTTP/1.1" 200 877
[2025-09-04 14:43:09] [INFO] [django.server] "GET /api/client/profile/me/ HTTP/1.1" 200 464
[2025-09-04 14:43:09] [INFO] [django.server] "GET /api/client/transactions/ HTTP/1.1" 200 877
[2025-09-04 14:43:20] [INFO] [system] System event: RiskEngine initialized | Component: risk_engine | Severity: INFO | Data: {"thresholds_count": 13, "rules_count": 4}
[2025-09-04 14:43:20] [INFO] [system] System event: RiskEngine initialized | Component: risk_engine | Severity: INFO | Data: {"thresholds_count": 13, "rules_count": 4}
[2025-09-04 14:43:20] [INFO] [system] System event: ML model loaded successfully | Component: fraud_ml_model | Severity: INFO | Data: {"model_path": "C:\\Users\\HP\\Desktop\\projects\\safeNetAi\\backend\\models\\fraud_isolation.joblib"}
[2025-09-04 14:43:20] [INFO] [system] System event: RiskEngine initialized | Component: risk_engine | Severity: INFO | Data: {"thresholds_count": 13, "rules_count": 4}
[2025-09-04 14:43:20] [INFO] [system] System event: RiskEngine initialized | Component: risk_engine | Severity: INFO | Data: {"thresholds_count": 13, "rules_count": 4}
[2025-09-04 14:43:20] [ERROR] [system] System event: Error making ML prediction | Component: fraud_ml_model | Severity: ERROR | Data: {"transaction_id": 321, "error": "X has 9 features, but StandardScaler is expecting 7 features as input."}
[2025-09-04 14:43:22] [INFO] [system] System event: Security OTP email sent successfully | Component: email_service | Severity: INFO | Data: {"user_email": "abassi.loay@gmail.com", "user_id": 71, "transaction_id": 321, "otp_code": "151127"}
[2025-09-04 14:43:22] [INFO] [system] System event: Transaction OTP created and sent successfully | Component: transactions | Severity: INFO | Data: {"user_email": "abassi.loay@gmail.com", "user_id": 71, "transaction_id": 321, "otp_id": 32}
[2025-09-04 14:43:22] [WARNING] [system] System event: Transaction requires OTP verification due to risk rules or AI assessment | Component: transactions | Severity: WARNING | Data: {"transaction_id": 321, "risk_score": 70, "triggers": ["\u26a0\ufe0f Effective distance violation: 159.83km > 60.0km threshold"], "ml_score": 0.5, "user_id": 71, "distance_violation": false, "otp_reasons": ["Business rules triggered: 1", "High risk score: 70", "Risk engine explicit requirement"], "reason": "risk_rules"}
[2025-09-04 14:43:22] [INFO] [django.server] "POST /api/client/transactions/ HTTP/1.1" 201 404
[2025-09-04 14:50:27] [INFO] [django.server] "POST /api/auth/login/ HTTP/1.1" 200 638
[2025-09-04 14:50:27] [INFO] [system] Dashboard stats requested by admin admin@safenetai.com
[2025-09-04 14:50:27] [INFO] [django.server] "GET /api/admin/dashboard/stats/ HTTP/1.1" 200 246
[2025-09-04 14:50:27] [INFO] [system] Recent activity requested by admin admin@safenetai.com
[2025-09-04 14:50:27] [INFO] [django.server] "GET /api/admin/dashboard/recent_activity/ HTTP/1.1" 200 8181
[2025-09-04 14:50:27] [INFO] [system] Dashboard stats requested by admin admin@safenetai.com
[2025-09-04 14:50:27] [INFO] [django.server] "GET /api/admin/dashboard/stats/ HTTP/1.1" 200 246
[2025-09-04 14:50:27] [INFO] [system] Recent activity requested by admin admin@safenetai.com
[2025-09-04 14:50:27] [INFO] [django.server] "GET /api/admin/dashboard/recent_activity/ HTTP/1.1" 200 8181
[2025-09-04 14:50:31] [INFO] [django.server] "GET /api/admin/transactions/ HTTP/1.1" 200 9851
[2025-09-04 14:50:31] [INFO] [django.server] "GET /api/admin/transactions/ HTTP/1.1" 200 9851
[2025-09-04 14:50:32] [INFO] [django.server] "GET /api/admin/thresholds/ HTTP/1.1" 200 1091
[2025-09-04 14:50:32] [INFO] [django.server] "GET /api/admin/rules/ HTTP/1.1" 200 574
[2025-09-04 14:50:32] [INFO] [django.server] "GET /api/admin/thresholds/ HTTP/1.1" 200 1091
[2025-09-04 14:50:32] [INFO] [django.server] "GET /api/admin/rules/ HTTP/1.1" 200 574
[2025-09-04 15:05:30] [INFO] [django.utils.autoreload] Watching for file changes with StatReloader
[2025-09-04 15:07:00] [INFO] [django.server] "GET /api/admin/thresholds/ HTTP/1.1" 200 1091
[2025-09-04 15:07:00] [INFO] [django.server] "GET /api/admin/rules/ HTTP/1.1" 200 574
[2025-09-04 15:07:00] [INFO] [django.server] "GET /api/admin/rules/ HTTP/1.1" 200 574
[2025-09-04 15:07:00] [INFO] [django.server] "GET /api/admin/thresholds/ HTTP/1.1" 200 1091
[2025-09-04 15:09:46] [INFO] [django.utils.autoreload] C:\Users\HP\Desktop\projects\safeNetAi\backend\apps\risk\engine.py changed, reloading.
[2025-09-04 15:09:47] [INFO] [django.utils.autoreload] Watching for file changes with StatReloader
[2025-09-04 15:10:03] [INFO] [django.utils.autoreload] C:\Users\HP\Desktop\projects\safeNetAi\backend\apps\risk\engine.py changed, reloading.
[2025-09-04 15:10:04] [INFO] [django.utils.autoreload] Watching for file changes with StatReloader
[2025-09-04 15:10:30] [INFO] [django.utils.autoreload] C:\Users\HP\Desktop\projects\safeNetAi\backend\apps\risk\engine.py changed, reloading.
[2025-09-04 15:10:30] [INFO] [django.utils.autoreload] Watching for file changes with StatReloader
[2025-09-04 15:10:44] [INFO] [django.utils.autoreload] C:\Users\HP\Desktop\projects\safeNetAi\backend\apps\risk\engine.py changed, reloading.
[2025-09-04 15:10:44] [INFO] [django.utils.autoreload] Watching for file changes with StatReloader
[2025-09-04 15:11:12] [INFO] [django.utils.autoreload] C:\Users\HP\Desktop\projects\safeNetAi\backend\apps\risk\engine.py changed, reloading.
[2025-09-04 15:11:13] [INFO] [django.utils.autoreload] Watching for file changes with StatReloader
[2025-09-04 15:11:28] [INFO] [django.utils.autoreload] C:\Users\HP\Desktop\projects\safeNetAi\backend\apps\risk\ml.py changed, reloading.
[2025-09-04 15:11:29] [INFO] [django.utils.autoreload] Watching for file changes with StatReloader
[2025-09-04 15:11:39] [INFO] [django.utils.autoreload] C:\Users\HP\Desktop\projects\safeNetAi\backend\apps\risk\ml.py changed, reloading.
[2025-09-04 15:11:40] [INFO] [django.utils.autoreload] Watching for file changes with StatReloader
[2025-09-04 15:12:04] [INFO] [django.utils.autoreload] C:\Users\HP\Desktop\projects\safeNetAi\backend\apps\risk\ml.py changed, reloading.
[2025-09-04 15:12:05] [INFO] [django.utils.autoreload] Watching for file changes with StatReloader
[2025-09-04 15:12:48] [INFO] [django.utils.autoreload] C:\Users\HP\Desktop\projects\safeNetAi\backend\apps\transactions\models.py changed, reloading.
[2025-09-04 15:12:49] [INFO] [django.utils.autoreload] Watching for file changes with StatReloader
[2025-09-04 15:48:10] [INFO] [django.utils.autoreload] Watching for file changes with StatReloader
[2025-09-04 15:48:42] [INFO] [django.server] "GET /api/admin/thresholds/ HTTP/1.1" 200 1091
[2025-09-04 15:48:42] [INFO] [django.server] "GET /api/admin/rules/ HTTP/1.1" 200 574
[2025-09-04 15:48:42] [INFO] [django.server] "GET /api/admin/thresholds/ HTTP/1.1" 200 1091
[2025-09-04 15:48:42] [INFO] [django.server] "GET /api/admin/rules/ HTTP/1.1" 200 574
[2025-09-04 15:48:54] [INFO] [django.server] "OPTIONS /api/admin/thresholds/27/ HTTP/1.1" 200 0
[2025-09-04 15:48:54] [INFO] [django.server] "PATCH /api/admin/thresholds/27/ HTTP/1.1" 200 92
[2025-09-04 15:48:54] [INFO] [django.server] "GET /api/admin/thresholds/ HTTP/1.1" 200 1090
[2025-09-04 15:48:54] [INFO] [django.server] "GET /api/admin/rules/ HTTP/1.1" 200 574
[2025-09-04 15:49:11] [INFO] [django.server] "POST /api/auth/login/ HTTP/1.1" 200 647
[2025-09-04 15:49:11] [INFO] [django.server] "GET /api/client/profile/me/ HTTP/1.1" 200 464
[2025-09-04 15:49:11] [INFO] [django.server] "GET /api/client/profile/me/ HTTP/1.1" 200 464
[2025-09-04 15:49:12] [ERROR] [django.request] Internal Server Error: /api/client/transactions/
Traceback (most recent call last):
  File "C:\Users\HP\Desktop\projects\safeNetAi\backend\venv\Lib\site-packages\django\db\backends\utils.py", line 105, in _execute
    return self.cursor.execute(sql, params)
           ^^^^^^^^^^^^^^^^^^^^^^^^^^^^^^^^
  File "C:\Users\HP\Desktop\projects\safeNetAi\backend\venv\Lib\site-packages\django\db\backends\sqlite3\base.py", line 360, in execute
    return super().execute(query, params)
           ^^^^^^^^^^^^^^^^^^^^^^^^^^^^^^
sqlite3.OperationalError: no such column: transactions_transaction.current_lat

The above exception was the direct cause of the following exception:

Traceback (most recent call last):
  File "C:\Users\HP\Desktop\projects\safeNetAi\backend\venv\Lib\site-packages\django\core\handlers\exception.py", line 55, in inner
    response = get_response(request)
               ^^^^^^^^^^^^^^^^^^^^^
  File "C:\Users\HP\Desktop\projects\safeNetAi\backend\venv\Lib\site-packages\django\core\handlers\base.py", line 197, in _get_response
    response = wrapped_callback(request, *callback_args, **callback_kwargs)
               ^^^^^^^^^^^^^^^^^^^^^^^^^^^^^^^^^^^^^^^^^^^^^^^^^^^^^^^^^^^^
  File "C:\Users\HP\Desktop\projects\safeNetAi\backend\venv\Lib\site-packages\django\views\decorators\csrf.py", line 65, in _view_wrapper
    return view_func(request, *args, **kwargs)
           ^^^^^^^^^^^^^^^^^^^^^^^^^^^^^^^^^^^
  File "C:\Users\HP\Desktop\projects\safeNetAi\backend\venv\Lib\site-packages\rest_framework\viewsets.py", line 125, in view
    return self.dispatch(request, *args, **kwargs)
           ^^^^^^^^^^^^^^^^^^^^^^^^^^^^^^^^^^^^^^^
  File "C:\Users\HP\Desktop\projects\safeNetAi\backend\venv\Lib\site-packages\rest_framework\views.py", line 515, in dispatch
    response = self.handle_exception(exc)
               ^^^^^^^^^^^^^^^^^^^^^^^^^^
  File "C:\Users\HP\Desktop\projects\safeNetAi\backend\venv\Lib\site-packages\rest_framework\views.py", line 475, in handle_exception
    self.raise_uncaught_exception(exc)
  File "C:\Users\HP\Desktop\projects\safeNetAi\backend\venv\Lib\site-packages\rest_framework\views.py", line 486, in raise_uncaught_exception
    raise exc
  File "C:\Users\HP\Desktop\projects\safeNetAi\backend\venv\Lib\site-packages\rest_framework\views.py", line 512, in dispatch
    response = handler(request, *args, **kwargs)
               ^^^^^^^^^^^^^^^^^^^^^^^^^^^^^^^^^
  File "C:\Users\HP\Desktop\projects\safeNetAi\backend\venv\Lib\site-packages\rest_framework\mixins.py", line 46, in list
    return Response(serializer.data)
                    ^^^^^^^^^^^^^^^
  File "C:\Users\HP\Desktop\projects\safeNetAi\backend\venv\Lib\site-packages\rest_framework\serializers.py", line 797, in data
    ret = super().data
          ^^^^^^^^^^^^
  File "C:\Users\HP\Desktop\projects\safeNetAi\backend\venv\Lib\site-packages\rest_framework\serializers.py", line 251, in data
    self._data = self.to_representation(self.instance)
                 ^^^^^^^^^^^^^^^^^^^^^^^^^^^^^^^^^^^^^
  File "C:\Users\HP\Desktop\projects\safeNetAi\backend\venv\Lib\site-packages\rest_framework\serializers.py", line 715, in to_representation
    return [
           ^
  File "C:\Users\HP\Desktop\projects\safeNetAi\backend\venv\Lib\site-packages\django\db\models\query.py", line 384, in __iter__
    self._fetch_all()
  File "C:\Users\HP\Desktop\projects\safeNetAi\backend\venv\Lib\site-packages\django\db\models\query.py", line 1949, in _fetch_all
    self._result_cache = list(self._iterable_class(self))
                         ^^^^^^^^^^^^^^^^^^^^^^^^^^^^^^^^
  File "C:\Users\HP\Desktop\projects\safeNetAi\backend\venv\Lib\site-packages\django\db\models\query.py", line 91, in __iter__
    results = compiler.execute_sql(
              ^^^^^^^^^^^^^^^^^^^^^
  File "C:\Users\HP\Desktop\projects\safeNetAi\backend\venv\Lib\site-packages\django\db\models\sql\compiler.py", line 1623, in execute_sql
    cursor.execute(sql, params)
  File "C:\Users\HP\Desktop\projects\safeNetAi\backend\venv\Lib\site-packages\django\db\backends\utils.py", line 122, in execute
    return super().execute(sql, params)
           ^^^^^^^^^^^^^^^^^^^^^^^^^^^^
  File "C:\Users\HP\Desktop\projects\safeNetAi\backend\venv\Lib\site-packages\django\db\backends\utils.py", line 79, in execute
    return self._execute_with_wrappers(
           ^^^^^^^^^^^^^^^^^^^^^^^^^^^^
  File "C:\Users\HP\Desktop\projects\safeNetAi\backend\venv\Lib\site-packages\django\db\backends\utils.py", line 92, in _execute_with_wrappers
    return executor(sql, params, many, context)
           ^^^^^^^^^^^^^^^^^^^^^^^^^^^^^^^^^^^^
  File "C:\Users\HP\Desktop\projects\safeNetAi\backend\venv\Lib\site-packages\django\db\backends\utils.py", line 100, in _execute
    with self.db.wrap_database_errors:
  File "C:\Users\HP\Desktop\projects\safeNetAi\backend\venv\Lib\site-packages\django\db\utils.py", line 91, in __exit__
    raise dj_exc_value.with_traceback(traceback) from exc_value
  File "C:\Users\HP\Desktop\projects\safeNetAi\backend\venv\Lib\site-packages\django\db\backends\utils.py", line 105, in _execute
    return self.cursor.execute(sql, params)
           ^^^^^^^^^^^^^^^^^^^^^^^^^^^^^^^^
  File "C:\Users\HP\Desktop\projects\safeNetAi\backend\venv\Lib\site-packages\django\db\backends\sqlite3\base.py", line 360, in execute
    return super().execute(query, params)
           ^^^^^^^^^^^^^^^^^^^^^^^^^^^^^^
django.db.utils.OperationalError: no such column: transactions_transaction.current_lat
[2025-09-04 15:49:12] [ERROR] [django.server] "GET /api/client/transactions/ HTTP/1.1" 500 192380
[2025-09-04 15:49:12] [ERROR] [django.request] Internal Server Error: /api/client/transactions/
Traceback (most recent call last):
  File "C:\Users\HP\Desktop\projects\safeNetAi\backend\venv\Lib\site-packages\django\db\backends\utils.py", line 105, in _execute
    return self.cursor.execute(sql, params)
           ^^^^^^^^^^^^^^^^^^^^^^^^^^^^^^^^
  File "C:\Users\HP\Desktop\projects\safeNetAi\backend\venv\Lib\site-packages\django\db\backends\sqlite3\base.py", line 360, in execute
    return super().execute(query, params)
           ^^^^^^^^^^^^^^^^^^^^^^^^^^^^^^
sqlite3.OperationalError: no such column: transactions_transaction.current_lat

The above exception was the direct cause of the following exception:

Traceback (most recent call last):
  File "C:\Users\HP\Desktop\projects\safeNetAi\backend\venv\Lib\site-packages\django\core\handlers\exception.py", line 55, in inner
    response = get_response(request)
               ^^^^^^^^^^^^^^^^^^^^^
  File "C:\Users\HP\Desktop\projects\safeNetAi\backend\venv\Lib\site-packages\django\core\handlers\base.py", line 197, in _get_response
    response = wrapped_callback(request, *callback_args, **callback_kwargs)
               ^^^^^^^^^^^^^^^^^^^^^^^^^^^^^^^^^^^^^^^^^^^^^^^^^^^^^^^^^^^^
  File "C:\Users\HP\Desktop\projects\safeNetAi\backend\venv\Lib\site-packages\django\views\decorators\csrf.py", line 65, in _view_wrapper
    return view_func(request, *args, **kwargs)
           ^^^^^^^^^^^^^^^^^^^^^^^^^^^^^^^^^^^
  File "C:\Users\HP\Desktop\projects\safeNetAi\backend\venv\Lib\site-packages\rest_framework\viewsets.py", line 125, in view
    return self.dispatch(request, *args, **kwargs)
           ^^^^^^^^^^^^^^^^^^^^^^^^^^^^^^^^^^^^^^^
  File "C:\Users\HP\Desktop\projects\safeNetAi\backend\venv\Lib\site-packages\rest_framework\views.py", line 515, in dispatch
    response = self.handle_exception(exc)
               ^^^^^^^^^^^^^^^^^^^^^^^^^^
  File "C:\Users\HP\Desktop\projects\safeNetAi\backend\venv\Lib\site-packages\rest_framework\views.py", line 475, in handle_exception
    self.raise_uncaught_exception(exc)
  File "C:\Users\HP\Desktop\projects\safeNetAi\backend\venv\Lib\site-packages\rest_framework\views.py", line 486, in raise_uncaught_exception
    raise exc
  File "C:\Users\HP\Desktop\projects\safeNetAi\backend\venv\Lib\site-packages\rest_framework\views.py", line 512, in dispatch
    response = handler(request, *args, **kwargs)
               ^^^^^^^^^^^^^^^^^^^^^^^^^^^^^^^^^
  File "C:\Users\HP\Desktop\projects\safeNetAi\backend\venv\Lib\site-packages\rest_framework\mixins.py", line 46, in list
    return Response(serializer.data)
                    ^^^^^^^^^^^^^^^
  File "C:\Users\HP\Desktop\projects\safeNetAi\backend\venv\Lib\site-packages\rest_framework\serializers.py", line 797, in data
    ret = super().data
          ^^^^^^^^^^^^
  File "C:\Users\HP\Desktop\projects\safeNetAi\backend\venv\Lib\site-packages\rest_framework\serializers.py", line 251, in data
    self._data = self.to_representation(self.instance)
                 ^^^^^^^^^^^^^^^^^^^^^^^^^^^^^^^^^^^^^
  File "C:\Users\HP\Desktop\projects\safeNetAi\backend\venv\Lib\site-packages\rest_framework\serializers.py", line 715, in to_representation
    return [
           ^
  File "C:\Users\HP\Desktop\projects\safeNetAi\backend\venv\Lib\site-packages\django\db\models\query.py", line 384, in __iter__
    self._fetch_all()
  File "C:\Users\HP\Desktop\projects\safeNetAi\backend\venv\Lib\site-packages\django\db\models\query.py", line 1949, in _fetch_all
    self._result_cache = list(self._iterable_class(self))
                         ^^^^^^^^^^^^^^^^^^^^^^^^^^^^^^^^
  File "C:\Users\HP\Desktop\projects\safeNetAi\backend\venv\Lib\site-packages\django\db\models\query.py", line 91, in __iter__
    results = compiler.execute_sql(
              ^^^^^^^^^^^^^^^^^^^^^
  File "C:\Users\HP\Desktop\projects\safeNetAi\backend\venv\Lib\site-packages\django\db\models\sql\compiler.py", line 1623, in execute_sql
    cursor.execute(sql, params)
  File "C:\Users\HP\Desktop\projects\safeNetAi\backend\venv\Lib\site-packages\django\db\backends\utils.py", line 122, in execute
    return super().execute(sql, params)
           ^^^^^^^^^^^^^^^^^^^^^^^^^^^^
  File "C:\Users\HP\Desktop\projects\safeNetAi\backend\venv\Lib\site-packages\django\db\backends\utils.py", line 79, in execute
    return self._execute_with_wrappers(
           ^^^^^^^^^^^^^^^^^^^^^^^^^^^^
  File "C:\Users\HP\Desktop\projects\safeNetAi\backend\venv\Lib\site-packages\django\db\backends\utils.py", line 92, in _execute_with_wrappers
    return executor(sql, params, many, context)
           ^^^^^^^^^^^^^^^^^^^^^^^^^^^^^^^^^^^^
  File "C:\Users\HP\Desktop\projects\safeNetAi\backend\venv\Lib\site-packages\django\db\backends\utils.py", line 100, in _execute
    with self.db.wrap_database_errors:
  File "C:\Users\HP\Desktop\projects\safeNetAi\backend\venv\Lib\site-packages\django\db\utils.py", line 91, in __exit__
    raise dj_exc_value.with_traceback(traceback) from exc_value
  File "C:\Users\HP\Desktop\projects\safeNetAi\backend\venv\Lib\site-packages\django\db\backends\utils.py", line 105, in _execute
    return self.cursor.execute(sql, params)
           ^^^^^^^^^^^^^^^^^^^^^^^^^^^^^^^^
  File "C:\Users\HP\Desktop\projects\safeNetAi\backend\venv\Lib\site-packages\django\db\backends\sqlite3\base.py", line 360, in execute
    return super().execute(query, params)
           ^^^^^^^^^^^^^^^^^^^^^^^^^^^^^^
django.db.utils.OperationalError: no such column: transactions_transaction.current_lat
[2025-09-04 15:49:12] [ERROR] [django.server] "GET /api/client/transactions/ HTTP/1.1" 500 192380
[2025-09-04 15:49:19] [INFO] [django.server] "GET /api/client/profile/me/ HTTP/1.1" 200 464
[2025-09-04 15:49:19] [INFO] [django.server] "GET /api/client/profile/me/ HTTP/1.1" 200 464
[2025-09-04 15:49:19] [ERROR] [django.request] Internal Server Error: /api/client/transactions/
Traceback (most recent call last):
  File "C:\Users\HP\Desktop\projects\safeNetAi\backend\venv\Lib\site-packages\django\db\backends\utils.py", line 105, in _execute
    return self.cursor.execute(sql, params)
           ^^^^^^^^^^^^^^^^^^^^^^^^^^^^^^^^
  File "C:\Users\HP\Desktop\projects\safeNetAi\backend\venv\Lib\site-packages\django\db\backends\sqlite3\base.py", line 360, in execute
    return super().execute(query, params)
           ^^^^^^^^^^^^^^^^^^^^^^^^^^^^^^
sqlite3.OperationalError: no such column: transactions_transaction.current_lat

The above exception was the direct cause of the following exception:

Traceback (most recent call last):
  File "C:\Users\HP\Desktop\projects\safeNetAi\backend\venv\Lib\site-packages\django\core\handlers\exception.py", line 55, in inner
    response = get_response(request)
               ^^^^^^^^^^^^^^^^^^^^^
  File "C:\Users\HP\Desktop\projects\safeNetAi\backend\venv\Lib\site-packages\django\core\handlers\base.py", line 197, in _get_response
    response = wrapped_callback(request, *callback_args, **callback_kwargs)
               ^^^^^^^^^^^^^^^^^^^^^^^^^^^^^^^^^^^^^^^^^^^^^^^^^^^^^^^^^^^^
  File "C:\Users\HP\Desktop\projects\safeNetAi\backend\venv\Lib\site-packages\django\views\decorators\csrf.py", line 65, in _view_wrapper
    return view_func(request, *args, **kwargs)
           ^^^^^^^^^^^^^^^^^^^^^^^^^^^^^^^^^^^
  File "C:\Users\HP\Desktop\projects\safeNetAi\backend\venv\Lib\site-packages\rest_framework\viewsets.py", line 125, in view
    return self.dispatch(request, *args, **kwargs)
           ^^^^^^^^^^^^^^^^^^^^^^^^^^^^^^^^^^^^^^^
  File "C:\Users\HP\Desktop\projects\safeNetAi\backend\venv\Lib\site-packages\rest_framework\views.py", line 515, in dispatch
    response = self.handle_exception(exc)
               ^^^^^^^^^^^^^^^^^^^^^^^^^^
  File "C:\Users\HP\Desktop\projects\safeNetAi\backend\venv\Lib\site-packages\rest_framework\views.py", line 475, in handle_exception
    self.raise_uncaught_exception(exc)
  File "C:\Users\HP\Desktop\projects\safeNetAi\backend\venv\Lib\site-packages\rest_framework\views.py", line 486, in raise_uncaught_exception
    raise exc
  File "C:\Users\HP\Desktop\projects\safeNetAi\backend\venv\Lib\site-packages\rest_framework\views.py", line 512, in dispatch
    response = handler(request, *args, **kwargs)
               ^^^^^^^^^^^^^^^^^^^^^^^^^^^^^^^^^
  File "C:\Users\HP\Desktop\projects\safeNetAi\backend\venv\Lib\site-packages\rest_framework\mixins.py", line 46, in list
    return Response(serializer.data)
                    ^^^^^^^^^^^^^^^
  File "C:\Users\HP\Desktop\projects\safeNetAi\backend\venv\Lib\site-packages\rest_framework\serializers.py", line 797, in data
    ret = super().data
          ^^^^^^^^^^^^
  File "C:\Users\HP\Desktop\projects\safeNetAi\backend\venv\Lib\site-packages\rest_framework\serializers.py", line 251, in data
    self._data = self.to_representation(self.instance)
                 ^^^^^^^^^^^^^^^^^^^^^^^^^^^^^^^^^^^^^
  File "C:\Users\HP\Desktop\projects\safeNetAi\backend\venv\Lib\site-packages\rest_framework\serializers.py", line 715, in to_representation
    return [
           ^
  File "C:\Users\HP\Desktop\projects\safeNetAi\backend\venv\Lib\site-packages\django\db\models\query.py", line 384, in __iter__
    self._fetch_all()
  File "C:\Users\HP\Desktop\projects\safeNetAi\backend\venv\Lib\site-packages\django\db\models\query.py", line 1949, in _fetch_all
    self._result_cache = list(self._iterable_class(self))
                         ^^^^^^^^^^^^^^^^^^^^^^^^^^^^^^^^
  File "C:\Users\HP\Desktop\projects\safeNetAi\backend\venv\Lib\site-packages\django\db\models\query.py", line 91, in __iter__
    results = compiler.execute_sql(
              ^^^^^^^^^^^^^^^^^^^^^
  File "C:\Users\HP\Desktop\projects\safeNetAi\backend\venv\Lib\site-packages\django\db\models\sql\compiler.py", line 1623, in execute_sql
    cursor.execute(sql, params)
  File "C:\Users\HP\Desktop\projects\safeNetAi\backend\venv\Lib\site-packages\django\db\backends\utils.py", line 122, in execute
    return super().execute(sql, params)
           ^^^^^^^^^^^^^^^^^^^^^^^^^^^^
  File "C:\Users\HP\Desktop\projects\safeNetAi\backend\venv\Lib\site-packages\django\db\backends\utils.py", line 79, in execute
    return self._execute_with_wrappers(
           ^^^^^^^^^^^^^^^^^^^^^^^^^^^^
  File "C:\Users\HP\Desktop\projects\safeNetAi\backend\venv\Lib\site-packages\django\db\backends\utils.py", line 92, in _execute_with_wrappers
    return executor(sql, params, many, context)
           ^^^^^^^^^^^^^^^^^^^^^^^^^^^^^^^^^^^^
  File "C:\Users\HP\Desktop\projects\safeNetAi\backend\venv\Lib\site-packages\django\db\backends\utils.py", line 100, in _execute
    with self.db.wrap_database_errors:
  File "C:\Users\HP\Desktop\projects\safeNetAi\backend\venv\Lib\site-packages\django\db\utils.py", line 91, in __exit__
    raise dj_exc_value.with_traceback(traceback) from exc_value
  File "C:\Users\HP\Desktop\projects\safeNetAi\backend\venv\Lib\site-packages\django\db\backends\utils.py", line 105, in _execute
    return self.cursor.execute(sql, params)
           ^^^^^^^^^^^^^^^^^^^^^^^^^^^^^^^^
  File "C:\Users\HP\Desktop\projects\safeNetAi\backend\venv\Lib\site-packages\django\db\backends\sqlite3\base.py", line 360, in execute
    return super().execute(query, params)
           ^^^^^^^^^^^^^^^^^^^^^^^^^^^^^^
django.db.utils.OperationalError: no such column: transactions_transaction.current_lat
[2025-09-04 15:49:19] [ERROR] [django.server] "GET /api/client/transactions/ HTTP/1.1" 500 192380
[2025-09-04 15:49:19] [ERROR] [django.request] Internal Server Error: /api/client/transactions/
Traceback (most recent call last):
  File "C:\Users\HP\Desktop\projects\safeNetAi\backend\venv\Lib\site-packages\django\db\backends\utils.py", line 105, in _execute
    return self.cursor.execute(sql, params)
           ^^^^^^^^^^^^^^^^^^^^^^^^^^^^^^^^
  File "C:\Users\HP\Desktop\projects\safeNetAi\backend\venv\Lib\site-packages\django\db\backends\sqlite3\base.py", line 360, in execute
    return super().execute(query, params)
           ^^^^^^^^^^^^^^^^^^^^^^^^^^^^^^
sqlite3.OperationalError: no such column: transactions_transaction.current_lat

The above exception was the direct cause of the following exception:

Traceback (most recent call last):
  File "C:\Users\HP\Desktop\projects\safeNetAi\backend\venv\Lib\site-packages\django\core\handlers\exception.py", line 55, in inner
    response = get_response(request)
               ^^^^^^^^^^^^^^^^^^^^^
  File "C:\Users\HP\Desktop\projects\safeNetAi\backend\venv\Lib\site-packages\django\core\handlers\base.py", line 197, in _get_response
    response = wrapped_callback(request, *callback_args, **callback_kwargs)
               ^^^^^^^^^^^^^^^^^^^^^^^^^^^^^^^^^^^^^^^^^^^^^^^^^^^^^^^^^^^^
  File "C:\Users\HP\Desktop\projects\safeNetAi\backend\venv\Lib\site-packages\django\views\decorators\csrf.py", line 65, in _view_wrapper
    return view_func(request, *args, **kwargs)
           ^^^^^^^^^^^^^^^^^^^^^^^^^^^^^^^^^^^
  File "C:\Users\HP\Desktop\projects\safeNetAi\backend\venv\Lib\site-packages\rest_framework\viewsets.py", line 125, in view
    return self.dispatch(request, *args, **kwargs)
           ^^^^^^^^^^^^^^^^^^^^^^^^^^^^^^^^^^^^^^^
  File "C:\Users\HP\Desktop\projects\safeNetAi\backend\venv\Lib\site-packages\rest_framework\views.py", line 515, in dispatch
    response = self.handle_exception(exc)
               ^^^^^^^^^^^^^^^^^^^^^^^^^^
  File "C:\Users\HP\Desktop\projects\safeNetAi\backend\venv\Lib\site-packages\rest_framework\views.py", line 475, in handle_exception
    self.raise_uncaught_exception(exc)
  File "C:\Users\HP\Desktop\projects\safeNetAi\backend\venv\Lib\site-packages\rest_framework\views.py", line 486, in raise_uncaught_exception
    raise exc
  File "C:\Users\HP\Desktop\projects\safeNetAi\backend\venv\Lib\site-packages\rest_framework\views.py", line 512, in dispatch
    response = handler(request, *args, **kwargs)
               ^^^^^^^^^^^^^^^^^^^^^^^^^^^^^^^^^
  File "C:\Users\HP\Desktop\projects\safeNetAi\backend\venv\Lib\site-packages\rest_framework\mixins.py", line 46, in list
    return Response(serializer.data)
                    ^^^^^^^^^^^^^^^
  File "C:\Users\HP\Desktop\projects\safeNetAi\backend\venv\Lib\site-packages\rest_framework\serializers.py", line 797, in data
    ret = super().data
          ^^^^^^^^^^^^
  File "C:\Users\HP\Desktop\projects\safeNetAi\backend\venv\Lib\site-packages\rest_framework\serializers.py", line 251, in data
    self._data = self.to_representation(self.instance)
                 ^^^^^^^^^^^^^^^^^^^^^^^^^^^^^^^^^^^^^
  File "C:\Users\HP\Desktop\projects\safeNetAi\backend\venv\Lib\site-packages\rest_framework\serializers.py", line 715, in to_representation
    return [
           ^
  File "C:\Users\HP\Desktop\projects\safeNetAi\backend\venv\Lib\site-packages\django\db\models\query.py", line 384, in __iter__
    self._fetch_all()
  File "C:\Users\HP\Desktop\projects\safeNetAi\backend\venv\Lib\site-packages\django\db\models\query.py", line 1949, in _fetch_all
    self._result_cache = list(self._iterable_class(self))
                         ^^^^^^^^^^^^^^^^^^^^^^^^^^^^^^^^
  File "C:\Users\HP\Desktop\projects\safeNetAi\backend\venv\Lib\site-packages\django\db\models\query.py", line 91, in __iter__
    results = compiler.execute_sql(
              ^^^^^^^^^^^^^^^^^^^^^
  File "C:\Users\HP\Desktop\projects\safeNetAi\backend\venv\Lib\site-packages\django\db\models\sql\compiler.py", line 1623, in execute_sql
    cursor.execute(sql, params)
  File "C:\Users\HP\Desktop\projects\safeNetAi\backend\venv\Lib\site-packages\django\db\backends\utils.py", line 122, in execute
    return super().execute(sql, params)
           ^^^^^^^^^^^^^^^^^^^^^^^^^^^^
  File "C:\Users\HP\Desktop\projects\safeNetAi\backend\venv\Lib\site-packages\django\db\backends\utils.py", line 79, in execute
    return self._execute_with_wrappers(
           ^^^^^^^^^^^^^^^^^^^^^^^^^^^^
  File "C:\Users\HP\Desktop\projects\safeNetAi\backend\venv\Lib\site-packages\django\db\backends\utils.py", line 92, in _execute_with_wrappers
    return executor(sql, params, many, context)
           ^^^^^^^^^^^^^^^^^^^^^^^^^^^^^^^^^^^^
  File "C:\Users\HP\Desktop\projects\safeNetAi\backend\venv\Lib\site-packages\django\db\backends\utils.py", line 100, in _execute
    with self.db.wrap_database_errors:
  File "C:\Users\HP\Desktop\projects\safeNetAi\backend\venv\Lib\site-packages\django\db\utils.py", line 91, in __exit__
    raise dj_exc_value.with_traceback(traceback) from exc_value
  File "C:\Users\HP\Desktop\projects\safeNetAi\backend\venv\Lib\site-packages\django\db\backends\utils.py", line 105, in _execute
    return self.cursor.execute(sql, params)
           ^^^^^^^^^^^^^^^^^^^^^^^^^^^^^^^^
  File "C:\Users\HP\Desktop\projects\safeNetAi\backend\venv\Lib\site-packages\django\db\backends\sqlite3\base.py", line 360, in execute
    return super().execute(query, params)
           ^^^^^^^^^^^^^^^^^^^^^^^^^^^^^^
django.db.utils.OperationalError: no such column: transactions_transaction.current_lat
[2025-09-04 15:49:19] [ERROR] [django.server] "GET /api/client/transactions/ HTTP/1.1" 500 192380
[2025-09-04 15:49:43] [INFO] [django.server] "GET /admin/ HTTP/1.1" 200 16257
[2025-09-04 15:49:49] [INFO] [django.server] "GET /admin/users/user/ HTTP/1.1" 200 50666
[2025-09-04 15:49:49] [INFO] [django.server] "GET /admin/jsi18n/ HTTP/1.1" 200 3342
[2025-09-04 15:49:58] [ERROR] [django.request] Internal Server Error: /admin/users/user/
Traceback (most recent call last):
  File "C:\Users\HP\Desktop\projects\safeNetAi\backend\venv\Lib\site-packages\django\db\backends\utils.py", line 105, in _execute
    return self.cursor.execute(sql, params)
           ^^^^^^^^^^^^^^^^^^^^^^^^^^^^^^^^
  File "C:\Users\HP\Desktop\projects\safeNetAi\backend\venv\Lib\site-packages\django\db\backends\sqlite3\base.py", line 360, in execute
    return super().execute(query, params)
           ^^^^^^^^^^^^^^^^^^^^^^^^^^^^^^
sqlite3.OperationalError: no such column: transactions_transaction.current_lat

The above exception was the direct cause of the following exception:

Traceback (most recent call last):
  File "C:\Users\HP\Desktop\projects\safeNetAi\backend\venv\Lib\site-packages\django\core\handlers\exception.py", line 55, in inner
    response = get_response(request)
               ^^^^^^^^^^^^^^^^^^^^^
  File "C:\Users\HP\Desktop\projects\safeNetAi\backend\venv\Lib\site-packages\django\core\handlers\base.py", line 197, in _get_response
    response = wrapped_callback(request, *callback_args, **callback_kwargs)
               ^^^^^^^^^^^^^^^^^^^^^^^^^^^^^^^^^^^^^^^^^^^^^^^^^^^^^^^^^^^^
  File "C:\Users\HP\Desktop\projects\safeNetAi\backend\venv\Lib\site-packages\django\contrib\admin\options.py", line 719, in wrapper
    return self.admin_site.admin_view(view)(*args, **kwargs)
           ^^^^^^^^^^^^^^^^^^^^^^^^^^^^^^^^^^^^^^^^^^^^^^^^^
  File "C:\Users\HP\Desktop\projects\safeNetAi\backend\venv\Lib\site-packages\django\utils\decorators.py", line 192, in _view_wrapper
    result = _process_exception(request, e)
             ^^^^^^^^^^^^^^^^^^^^^^^^^^^^^^
  File "C:\Users\HP\Desktop\projects\safeNetAi\backend\venv\Lib\site-packages\django\utils\decorators.py", line 190, in _view_wrapper
    response = view_func(request, *args, **kwargs)
               ^^^^^^^^^^^^^^^^^^^^^^^^^^^^^^^^^^^
  File "C:\Users\HP\Desktop\projects\safeNetAi\backend\venv\Lib\site-packages\django\views\decorators\cache.py", line 80, in _view_wrapper
    response = view_func(request, *args, **kwargs)
               ^^^^^^^^^^^^^^^^^^^^^^^^^^^^^^^^^^^
  File "C:\Users\HP\Desktop\projects\safeNetAi\backend\venv\Lib\site-packages\django\contrib\admin\sites.py", line 246, in inner
    return view(request, *args, **kwargs)
           ^^^^^^^^^^^^^^^^^^^^^^^^^^^^^^
  File "C:\Users\HP\Desktop\projects\safeNetAi\backend\venv\Lib\site-packages\django\utils\decorators.py", line 48, in _wrapper
    return bound_method(*args, **kwargs)
           ^^^^^^^^^^^^^^^^^^^^^^^^^^^^^
  File "C:\Users\HP\Desktop\projects\safeNetAi\backend\venv\Lib\site-packages\django\utils\decorators.py", line 192, in _view_wrapper
    result = _process_exception(request, e)
             ^^^^^^^^^^^^^^^^^^^^^^^^^^^^^^
  File "C:\Users\HP\Desktop\projects\safeNetAi\backend\venv\Lib\site-packages\django\utils\decorators.py", line 190, in _view_wrapper
    response = view_func(request, *args, **kwargs)
               ^^^^^^^^^^^^^^^^^^^^^^^^^^^^^^^^^^^
  File "C:\Users\HP\Desktop\projects\safeNetAi\backend\venv\Lib\site-packages\django\contrib\admin\options.py", line 2057, in changelist_view
    response = self.response_action(
               ^^^^^^^^^^^^^^^^^^^^^
  File "C:\Users\HP\Desktop\projects\safeNetAi\backend\venv\Lib\site-packages\django\contrib\admin\options.py", line 1686, in response_action
    response = func(self, request, queryset)
               ^^^^^^^^^^^^^^^^^^^^^^^^^^^^^
  File "C:\Users\HP\Desktop\projects\safeNetAi\backend\venv\Lib\site-packages\django\contrib\admin\actions.py", line 39, in delete_selected
    ) = modeladmin.get_deleted_objects(queryset, request)
        ^^^^^^^^^^^^^^^^^^^^^^^^^^^^^^^^^^^^^^^^^^^^^^^^^
  File "C:\Users\HP\Desktop\projects\safeNetAi\backend\venv\Lib\site-packages\django\contrib\admin\options.py", line 2199, in get_deleted_objects
    return get_deleted_objects(objs, request, self.admin_site)
           ^^^^^^^^^^^^^^^^^^^^^^^^^^^^^^^^^^^^^^^^^^^^^^^^^^^
  File "C:\Users\HP\Desktop\projects\safeNetAi\backend\venv\Lib\site-packages\django\contrib\admin\utils.py", line 138, in get_deleted_objects
    collector.collect(objs)
  File "C:\Users\HP\Desktop\projects\safeNetAi\backend\venv\Lib\site-packages\django\contrib\admin\utils.py", line 205, in collect
    return super().collect(objs, source_attr=source_attr, **kwargs)
           ^^^^^^^^^^^^^^^^^^^^^^^^^^^^^^^^^^^^^^^^^^^^^^^^^^^^^^^^
  File "C:\Users\HP\Desktop\projects\safeNetAi\backend\venv\Lib\site-packages\django\db\models\deletion.py", line 345, in collect
    on_delete(self, field, sub_objs, self.using)
  File "C:\Users\HP\Desktop\projects\safeNetAi\backend\venv\Lib\site-packages\django\db\models\deletion.py", line 23, in CASCADE
    collector.collect(
  File "C:\Users\HP\Desktop\projects\safeNetAi\backend\venv\Lib\site-packages\django\contrib\admin\utils.py", line 205, in collect
    return super().collect(objs, source_attr=source_attr, **kwargs)
           ^^^^^^^^^^^^^^^^^^^^^^^^^^^^^^^^^^^^^^^^^^^^^^^^^^^^^^^^
  File "C:\Users\HP\Desktop\projects\safeNetAi\backend\venv\Lib\site-packages\django\db\models\deletion.py", line 343, in collect
    if getattr(on_delete, "lazy_sub_objs", False) or sub_objs:
  File "C:\Users\HP\Desktop\projects\safeNetAi\backend\venv\Lib\site-packages\django\db\models\query.py", line 398, in __bool__
    self._fetch_all()
  File "C:\Users\HP\Desktop\projects\safeNetAi\backend\venv\Lib\site-packages\django\db\models\query.py", line 1949, in _fetch_all
    self._result_cache = list(self._iterable_class(self))
                         ^^^^^^^^^^^^^^^^^^^^^^^^^^^^^^^^
  File "C:\Users\HP\Desktop\projects\safeNetAi\backend\venv\Lib\site-packages\django\db\models\query.py", line 91, in __iter__
    results = compiler.execute_sql(
              ^^^^^^^^^^^^^^^^^^^^^
  File "C:\Users\HP\Desktop\projects\safeNetAi\backend\venv\Lib\site-packages\django\db\models\sql\compiler.py", line 1623, in execute_sql
    cursor.execute(sql, params)
  File "C:\Users\HP\Desktop\projects\safeNetAi\backend\venv\Lib\site-packages\django\db\backends\utils.py", line 122, in execute
    return super().execute(sql, params)
           ^^^^^^^^^^^^^^^^^^^^^^^^^^^^
  File "C:\Users\HP\Desktop\projects\safeNetAi\backend\venv\Lib\site-packages\django\db\backends\utils.py", line 79, in execute
    return self._execute_with_wrappers(
           ^^^^^^^^^^^^^^^^^^^^^^^^^^^^
  File "C:\Users\HP\Desktop\projects\safeNetAi\backend\venv\Lib\site-packages\django\db\backends\utils.py", line 92, in _execute_with_wrappers
    return executor(sql, params, many, context)
           ^^^^^^^^^^^^^^^^^^^^^^^^^^^^^^^^^^^^
  File "C:\Users\HP\Desktop\projects\safeNetAi\backend\venv\Lib\site-packages\django\db\backends\utils.py", line 100, in _execute
    with self.db.wrap_database_errors:
  File "C:\Users\HP\Desktop\projects\safeNetAi\backend\venv\Lib\site-packages\django\db\utils.py", line 91, in __exit__
    raise dj_exc_value.with_traceback(traceback) from exc_value
  File "C:\Users\HP\Desktop\projects\safeNetAi\backend\venv\Lib\site-packages\django\db\backends\utils.py", line 105, in _execute
    return self.cursor.execute(sql, params)
           ^^^^^^^^^^^^^^^^^^^^^^^^^^^^^^^^
  File "C:\Users\HP\Desktop\projects\safeNetAi\backend\venv\Lib\site-packages\django\db\backends\sqlite3\base.py", line 360, in execute
    return super().execute(query, params)
           ^^^^^^^^^^^^^^^^^^^^^^^^^^^^^^
django.db.utils.OperationalError: no such column: transactions_transaction.current_lat
[2025-09-04 15:49:58] [ERROR] [django.server] "POST /admin/users/user/ HTTP/1.1" 500 257525
[2025-09-04 15:50:06] [INFO] [django.server] "GET /admin/users/user/ HTTP/1.1" 200 50666
[2025-09-04 15:50:27] [ERROR] [django.request] Internal Server Error: /admin/users/user/
Traceback (most recent call last):
  File "C:\Users\HP\Desktop\projects\safeNetAi\backend\venv\Lib\site-packages\django\db\backends\utils.py", line 105, in _execute
    return self.cursor.execute(sql, params)
           ^^^^^^^^^^^^^^^^^^^^^^^^^^^^^^^^
  File "C:\Users\HP\Desktop\projects\safeNetAi\backend\venv\Lib\site-packages\django\db\backends\sqlite3\base.py", line 360, in execute
    return super().execute(query, params)
           ^^^^^^^^^^^^^^^^^^^^^^^^^^^^^^
sqlite3.OperationalError: no such column: transactions_transaction.current_lat

The above exception was the direct cause of the following exception:

Traceback (most recent call last):
  File "C:\Users\HP\Desktop\projects\safeNetAi\backend\venv\Lib\site-packages\django\core\handlers\exception.py", line 55, in inner
    response = get_response(request)
               ^^^^^^^^^^^^^^^^^^^^^
  File "C:\Users\HP\Desktop\projects\safeNetAi\backend\venv\Lib\site-packages\django\core\handlers\base.py", line 197, in _get_response
    response = wrapped_callback(request, *callback_args, **callback_kwargs)
               ^^^^^^^^^^^^^^^^^^^^^^^^^^^^^^^^^^^^^^^^^^^^^^^^^^^^^^^^^^^^
  File "C:\Users\HP\Desktop\projects\safeNetAi\backend\venv\Lib\site-packages\django\contrib\admin\options.py", line 719, in wrapper
    return self.admin_site.admin_view(view)(*args, **kwargs)
           ^^^^^^^^^^^^^^^^^^^^^^^^^^^^^^^^^^^^^^^^^^^^^^^^^
  File "C:\Users\HP\Desktop\projects\safeNetAi\backend\venv\Lib\site-packages\django\utils\decorators.py", line 192, in _view_wrapper
    result = _process_exception(request, e)
             ^^^^^^^^^^^^^^^^^^^^^^^^^^^^^^
  File "C:\Users\HP\Desktop\projects\safeNetAi\backend\venv\Lib\site-packages\django\utils\decorators.py", line 190, in _view_wrapper
    response = view_func(request, *args, **kwargs)
               ^^^^^^^^^^^^^^^^^^^^^^^^^^^^^^^^^^^
  File "C:\Users\HP\Desktop\projects\safeNetAi\backend\venv\Lib\site-packages\django\views\decorators\cache.py", line 80, in _view_wrapper
    response = view_func(request, *args, **kwargs)
               ^^^^^^^^^^^^^^^^^^^^^^^^^^^^^^^^^^^
  File "C:\Users\HP\Desktop\projects\safeNetAi\backend\venv\Lib\site-packages\django\contrib\admin\sites.py", line 246, in inner
    return view(request, *args, **kwargs)
           ^^^^^^^^^^^^^^^^^^^^^^^^^^^^^^
  File "C:\Users\HP\Desktop\projects\safeNetAi\backend\venv\Lib\site-packages\django\utils\decorators.py", line 48, in _wrapper
    return bound_method(*args, **kwargs)
           ^^^^^^^^^^^^^^^^^^^^^^^^^^^^^
  File "C:\Users\HP\Desktop\projects\safeNetAi\backend\venv\Lib\site-packages\django\utils\decorators.py", line 192, in _view_wrapper
    result = _process_exception(request, e)
             ^^^^^^^^^^^^^^^^^^^^^^^^^^^^^^
  File "C:\Users\HP\Desktop\projects\safeNetAi\backend\venv\Lib\site-packages\django\utils\decorators.py", line 190, in _view_wrapper
    response = view_func(request, *args, **kwargs)
               ^^^^^^^^^^^^^^^^^^^^^^^^^^^^^^^^^^^
  File "C:\Users\HP\Desktop\projects\safeNetAi\backend\venv\Lib\site-packages\django\contrib\admin\options.py", line 2057, in changelist_view
    response = self.response_action(
               ^^^^^^^^^^^^^^^^^^^^^
  File "C:\Users\HP\Desktop\projects\safeNetAi\backend\venv\Lib\site-packages\django\contrib\admin\options.py", line 1686, in response_action
    response = func(self, request, queryset)
               ^^^^^^^^^^^^^^^^^^^^^^^^^^^^^
  File "C:\Users\HP\Desktop\projects\safeNetAi\backend\venv\Lib\site-packages\django\contrib\admin\actions.py", line 39, in delete_selected
    ) = modeladmin.get_deleted_objects(queryset, request)
        ^^^^^^^^^^^^^^^^^^^^^^^^^^^^^^^^^^^^^^^^^^^^^^^^^
  File "C:\Users\HP\Desktop\projects\safeNetAi\backend\venv\Lib\site-packages\django\contrib\admin\options.py", line 2199, in get_deleted_objects
    return get_deleted_objects(objs, request, self.admin_site)
           ^^^^^^^^^^^^^^^^^^^^^^^^^^^^^^^^^^^^^^^^^^^^^^^^^^^
  File "C:\Users\HP\Desktop\projects\safeNetAi\backend\venv\Lib\site-packages\django\contrib\admin\utils.py", line 138, in get_deleted_objects
    collector.collect(objs)
  File "C:\Users\HP\Desktop\projects\safeNetAi\backend\venv\Lib\site-packages\django\contrib\admin\utils.py", line 205, in collect
    return super().collect(objs, source_attr=source_attr, **kwargs)
           ^^^^^^^^^^^^^^^^^^^^^^^^^^^^^^^^^^^^^^^^^^^^^^^^^^^^^^^^
  File "C:\Users\HP\Desktop\projects\safeNetAi\backend\venv\Lib\site-packages\django\db\models\deletion.py", line 345, in collect
    on_delete(self, field, sub_objs, self.using)
  File "C:\Users\HP\Desktop\projects\safeNetAi\backend\venv\Lib\site-packages\django\db\models\deletion.py", line 23, in CASCADE
    collector.collect(
  File "C:\Users\HP\Desktop\projects\safeNetAi\backend\venv\Lib\site-packages\django\contrib\admin\utils.py", line 205, in collect
    return super().collect(objs, source_attr=source_attr, **kwargs)
           ^^^^^^^^^^^^^^^^^^^^^^^^^^^^^^^^^^^^^^^^^^^^^^^^^^^^^^^^
  File "C:\Users\HP\Desktop\projects\safeNetAi\backend\venv\Lib\site-packages\django\db\models\deletion.py", line 343, in collect
    if getattr(on_delete, "lazy_sub_objs", False) or sub_objs:
  File "C:\Users\HP\Desktop\projects\safeNetAi\backend\venv\Lib\site-packages\django\db\models\query.py", line 398, in __bool__
    self._fetch_all()
  File "C:\Users\HP\Desktop\projects\safeNetAi\backend\venv\Lib\site-packages\django\db\models\query.py", line 1949, in _fetch_all
    self._result_cache = list(self._iterable_class(self))
                         ^^^^^^^^^^^^^^^^^^^^^^^^^^^^^^^^
  File "C:\Users\HP\Desktop\projects\safeNetAi\backend\venv\Lib\site-packages\django\db\models\query.py", line 91, in __iter__
    results = compiler.execute_sql(
              ^^^^^^^^^^^^^^^^^^^^^
  File "C:\Users\HP\Desktop\projects\safeNetAi\backend\venv\Lib\site-packages\django\db\models\sql\compiler.py", line 1623, in execute_sql
    cursor.execute(sql, params)
  File "C:\Users\HP\Desktop\projects\safeNetAi\backend\venv\Lib\site-packages\django\db\backends\utils.py", line 122, in execute
    return super().execute(sql, params)
           ^^^^^^^^^^^^^^^^^^^^^^^^^^^^
  File "C:\Users\HP\Desktop\projects\safeNetAi\backend\venv\Lib\site-packages\django\db\backends\utils.py", line 79, in execute
    return self._execute_with_wrappers(
           ^^^^^^^^^^^^^^^^^^^^^^^^^^^^
  File "C:\Users\HP\Desktop\projects\safeNetAi\backend\venv\Lib\site-packages\django\db\backends\utils.py", line 92, in _execute_with_wrappers
    return executor(sql, params, many, context)
           ^^^^^^^^^^^^^^^^^^^^^^^^^^^^^^^^^^^^
  File "C:\Users\HP\Desktop\projects\safeNetAi\backend\venv\Lib\site-packages\django\db\backends\utils.py", line 100, in _execute
    with self.db.wrap_database_errors:
  File "C:\Users\HP\Desktop\projects\safeNetAi\backend\venv\Lib\site-packages\django\db\utils.py", line 91, in __exit__
    raise dj_exc_value.with_traceback(traceback) from exc_value
  File "C:\Users\HP\Desktop\projects\safeNetAi\backend\venv\Lib\site-packages\django\db\backends\utils.py", line 105, in _execute
    return self.cursor.execute(sql, params)
           ^^^^^^^^^^^^^^^^^^^^^^^^^^^^^^^^
  File "C:\Users\HP\Desktop\projects\safeNetAi\backend\venv\Lib\site-packages\django\db\backends\sqlite3\base.py", line 360, in execute
    return super().execute(query, params)
           ^^^^^^^^^^^^^^^^^^^^^^^^^^^^^^
django.db.utils.OperationalError: no such column: transactions_transaction.current_lat
[2025-09-04 15:50:27] [ERROR] [django.server] "POST /admin/users/user/ HTTP/1.1" 500 257655
[2025-09-04 15:53:44] [INFO] [django.server] "GET /admin/users/user/ HTTP/1.1" 200 50666
[2025-09-04 15:53:48] [ERROR] [django.request] Internal Server Error: /admin/transactions/transaction/
Traceback (most recent call last):
  File "C:\Users\HP\Desktop\projects\safeNetAi\backend\venv\Lib\site-packages\django\db\backends\utils.py", line 105, in _execute
    return self.cursor.execute(sql, params)
           ^^^^^^^^^^^^^^^^^^^^^^^^^^^^^^^^
  File "C:\Users\HP\Desktop\projects\safeNetAi\backend\venv\Lib\site-packages\django\db\backends\sqlite3\base.py", line 360, in execute
    return super().execute(query, params)
           ^^^^^^^^^^^^^^^^^^^^^^^^^^^^^^
sqlite3.OperationalError: no such column: transactions_transaction.current_lat

The above exception was the direct cause of the following exception:

Traceback (most recent call last):
  File "C:\Users\HP\Desktop\projects\safeNetAi\backend\venv\Lib\site-packages\django\core\handlers\exception.py", line 55, in inner
    response = get_response(request)
               ^^^^^^^^^^^^^^^^^^^^^
  File "C:\Users\HP\Desktop\projects\safeNetAi\backend\venv\Lib\site-packages\django\core\handlers\base.py", line 197, in _get_response
    response = wrapped_callback(request, *callback_args, **callback_kwargs)
               ^^^^^^^^^^^^^^^^^^^^^^^^^^^^^^^^^^^^^^^^^^^^^^^^^^^^^^^^^^^^
  File "C:\Users\HP\Desktop\projects\safeNetAi\backend\venv\Lib\site-packages\django\contrib\admin\options.py", line 719, in wrapper
    return self.admin_site.admin_view(view)(*args, **kwargs)
           ^^^^^^^^^^^^^^^^^^^^^^^^^^^^^^^^^^^^^^^^^^^^^^^^^
  File "C:\Users\HP\Desktop\projects\safeNetAi\backend\venv\Lib\site-packages\django\utils\decorators.py", line 192, in _view_wrapper
    result = _process_exception(request, e)
             ^^^^^^^^^^^^^^^^^^^^^^^^^^^^^^
  File "C:\Users\HP\Desktop\projects\safeNetAi\backend\venv\Lib\site-packages\django\utils\decorators.py", line 190, in _view_wrapper
    response = view_func(request, *args, **kwargs)
               ^^^^^^^^^^^^^^^^^^^^^^^^^^^^^^^^^^^
  File "C:\Users\HP\Desktop\projects\safeNetAi\backend\venv\Lib\site-packages\django\views\decorators\cache.py", line 80, in _view_wrapper
    response = view_func(request, *args, **kwargs)
               ^^^^^^^^^^^^^^^^^^^^^^^^^^^^^^^^^^^
  File "C:\Users\HP\Desktop\projects\safeNetAi\backend\venv\Lib\site-packages\django\contrib\admin\sites.py", line 246, in inner
    return view(request, *args, **kwargs)
           ^^^^^^^^^^^^^^^^^^^^^^^^^^^^^^
  File "C:\Users\HP\Desktop\projects\safeNetAi\backend\venv\Lib\site-packages\django\utils\decorators.py", line 48, in _wrapper
    return bound_method(*args, **kwargs)
           ^^^^^^^^^^^^^^^^^^^^^^^^^^^^^
  File "C:\Users\HP\Desktop\projects\safeNetAi\backend\venv\Lib\site-packages\django\utils\decorators.py", line 192, in _view_wrapper
    result = _process_exception(request, e)
             ^^^^^^^^^^^^^^^^^^^^^^^^^^^^^^
  File "C:\Users\HP\Desktop\projects\safeNetAi\backend\venv\Lib\site-packages\django\utils\decorators.py", line 190, in _view_wrapper
    response = view_func(request, *args, **kwargs)
               ^^^^^^^^^^^^^^^^^^^^^^^^^^^^^^^^^^^
  File "C:\Users\HP\Desktop\projects\safeNetAi\backend\venv\Lib\site-packages\django\contrib\admin\options.py", line 2163, in changelist_view
    "selection_note": _("0 of %(cnt)s selected") % {"cnt": len(cl.result_list)},
                                                           ^^^^^^^^^^^^^^^^^^^
  File "C:\Users\HP\Desktop\projects\safeNetAi\backend\venv\Lib\site-packages\django\db\models\query.py", line 366, in __len__
    self._fetch_all()
  File "C:\Users\HP\Desktop\projects\safeNetAi\backend\venv\Lib\site-packages\django\db\models\query.py", line 1949, in _fetch_all
    self._result_cache = list(self._iterable_class(self))
                         ^^^^^^^^^^^^^^^^^^^^^^^^^^^^^^^^
  File "C:\Users\HP\Desktop\projects\safeNetAi\backend\venv\Lib\site-packages\django\db\models\query.py", line 91, in __iter__
    results = compiler.execute_sql(
              ^^^^^^^^^^^^^^^^^^^^^
  File "C:\Users\HP\Desktop\projects\safeNetAi\backend\venv\Lib\site-packages\django\db\models\sql\compiler.py", line 1623, in execute_sql
    cursor.execute(sql, params)
  File "C:\Users\HP\Desktop\projects\safeNetAi\backend\venv\Lib\site-packages\django\db\backends\utils.py", line 122, in execute
    return super().execute(sql, params)
           ^^^^^^^^^^^^^^^^^^^^^^^^^^^^
  File "C:\Users\HP\Desktop\projects\safeNetAi\backend\venv\Lib\site-packages\django\db\backends\utils.py", line 79, in execute
    return self._execute_with_wrappers(
           ^^^^^^^^^^^^^^^^^^^^^^^^^^^^
  File "C:\Users\HP\Desktop\projects\safeNetAi\backend\venv\Lib\site-packages\django\db\backends\utils.py", line 92, in _execute_with_wrappers
    return executor(sql, params, many, context)
           ^^^^^^^^^^^^^^^^^^^^^^^^^^^^^^^^^^^^
  File "C:\Users\HP\Desktop\projects\safeNetAi\backend\venv\Lib\site-packages\django\db\backends\utils.py", line 100, in _execute
    with self.db.wrap_database_errors:
  File "C:\Users\HP\Desktop\projects\safeNetAi\backend\venv\Lib\site-packages\django\db\utils.py", line 91, in __exit__
    raise dj_exc_value.with_traceback(traceback) from exc_value
  File "C:\Users\HP\Desktop\projects\safeNetAi\backend\venv\Lib\site-packages\django\db\backends\utils.py", line 105, in _execute
    return self.cursor.execute(sql, params)
           ^^^^^^^^^^^^^^^^^^^^^^^^^^^^^^^^
  File "C:\Users\HP\Desktop\projects\safeNetAi\backend\venv\Lib\site-packages\django\db\backends\sqlite3\base.py", line 360, in execute
    return super().execute(query, params)
           ^^^^^^^^^^^^^^^^^^^^^^^^^^^^^^
django.db.utils.OperationalError: no such column: transactions_transaction.current_lat
[2025-09-04 15:53:48] [ERROR] [django.server] "GET /admin/transactions/transaction/ HTTP/1.1" 500 208054
[2025-09-04 16:00:50] [INFO] [django.utils.autoreload] Watching for file changes with StatReloader
[2025-09-04 16:00:59] [INFO] [django.server] "GET /admin/ HTTP/1.1" 200 16257
[2025-09-04 16:01:02] [INFO] [django.server] "GET /admin/users/user/ HTTP/1.1" 200 50666
[2025-09-04 16:01:02] [INFO] [django.server] "GET /admin/jsi18n/ HTTP/1.1" 200 3342
[2025-09-04 16:01:05] [INFO] [django.server] "GET /admin/transactions/transaction/ HTTP/1.1" 200 33847
[2025-09-04 16:01:05] [INFO] [django.server] "GET /admin/jsi18n/ HTTP/1.1" 200 3342
[2025-09-04 16:01:08] [INFO] [django.server] "GET /admin/transactions/transaction/321/change/ HTTP/1.1" 200 23602
[2025-09-04 16:01:08] [INFO] [django.server] "GET /admin/jsi18n/ HTTP/1.1" 200 3342
[2025-09-04 16:01:27] [INFO] [django.server] "GET /admin/transactions/transaction/ HTTP/1.1" 200 33847
[2025-09-04 16:01:30] [INFO] [django.server] "GET /admin/risk/clientprofile/ HTTP/1.1" 200 48148
[2025-09-04 16:01:30] [INFO] [django.server] "GET /admin/jsi18n/ HTTP/1.1" 200 3342
[2025-09-04 16:01:33] [INFO] [django.server] "GET /admin/risk/clientprofile/89/change/ HTTP/1.1" 200 27955
[2025-09-04 16:01:33] [INFO] [django.server] "GET /admin/jsi18n/ HTTP/1.1" 200 3342
[2025-09-04 16:01:59] [INFO] [django.server] "OPTIONS /api/auth/login/ HTTP/1.1" 200 0
[2025-09-04 16:02:00] [WARNING] [django.request] Bad Request: /api/auth/login/
[2025-09-04 16:02:00] [WARNING] [django.server] "POST /api/auth/login/ HTTP/1.1" 400 44
[2025-09-04 16:02:06] [INFO] [django.server] "POST /api/auth/login/ HTTP/1.1" 200 638
[2025-09-04 16:02:06] [INFO] [django.server] "OPTIONS /api/admin/dashboard/stats/ HTTP/1.1" 200 0
[2025-09-04 16:02:06] [INFO] [django.server] "OPTIONS /api/admin/dashboard/recent_activity/ HTTP/1.1" 200 0
[2025-09-04 16:02:06] [INFO] [django.server] "OPTIONS /api/admin/dashboard/recent_activity/ HTTP/1.1" 200 0
[2025-09-04 16:02:06] [INFO] [system] Dashboard stats requested by admin admin@safenetai.com
[2025-09-04 16:02:06] [INFO] [django.server] "GET /api/admin/dashboard/stats/ HTTP/1.1" 200 246
[2025-09-04 16:02:06] [INFO] [system] Recent activity requested by admin admin@safenetai.com
[2025-09-04 16:02:06] [INFO] [django.server] "GET /api/admin/dashboard/recent_activity/ HTTP/1.1" 200 8181
[2025-09-04 16:02:06] [INFO] [system] Dashboard stats requested by admin admin@safenetai.com
[2025-09-04 16:02:06] [INFO] [django.server] "GET /api/admin/dashboard/stats/ HTTP/1.1" 200 246
[2025-09-04 16:02:06] [INFO] [system] Recent activity requested by admin admin@safenetai.com
[2025-09-04 16:02:06] [INFO] [django.server] "GET /api/admin/dashboard/recent_activity/ HTTP/1.1" 200 8181
[2025-09-04 16:02:13] [INFO] [django.server] "OPTIONS /api/admin/clients/ HTTP/1.1" 200 0
[2025-09-04 16:02:13] [INFO] [django.server] "OPTIONS /api/admin/clients/ HTTP/1.1" 200 0
[2025-09-04 16:02:14] [INFO] [django.server] "GET /api/admin/clients/ HTTP/1.1" 200 23930
[2025-09-04 16:02:14] [INFO] [django.server] "GET /api/admin/clients/ HTTP/1.1" 200 23930
[2025-09-04 16:02:17] [INFO] [django.server] "OPTIONS /api/admin/thresholds/ HTTP/1.1" 200 0
[2025-09-04 16:02:17] [INFO] [django.server] "OPTIONS /api/admin/rules/ HTTP/1.1" 200 0
[2025-09-04 16:02:17] [INFO] [django.server] "GET /api/admin/rules/ HTTP/1.1" 200 574
[2025-09-04 16:02:17] [INFO] [django.server] "GET /api/admin/thresholds/ HTTP/1.1" 200 1090
[2025-09-04 16:02:17] [INFO] [django.server] "GET /api/admin/rules/ HTTP/1.1" 200 574
[2025-09-04 16:02:17] [INFO] [django.server] "GET /api/admin/thresholds/ HTTP/1.1" 200 1090
[2025-09-04 16:02:34] [INFO] [django.server] "POST /api/auth/login/ HTTP/1.1" 200 647
[2025-09-04 16:02:34] [INFO] [django.server] "OPTIONS /api/client/profile/me/ HTTP/1.1" 200 0
[2025-09-04 16:02:34] [INFO] [django.server] "OPTIONS /api/client/transactions/ HTTP/1.1" 200 0
[2025-09-04 16:02:34] [INFO] [django.server] "OPTIONS /api/client/transactions/ HTTP/1.1" 200 0
[2025-09-04 16:02:34] [INFO] [django.server] "GET /api/client/profile/me/ HTTP/1.1" 200 464
[2025-09-04 16:02:34] [INFO] [django.server] "GET /api/client/profile/me/ HTTP/1.1" 200 464
[2025-09-04 16:02:34] [INFO] [django.server] "GET /api/client/transactions/ HTTP/1.1" 200 1169
[2025-09-04 16:02:34] [INFO] [django.server] "GET /api/client/transactions/ HTTP/1.1" 200 1169
[2025-09-04 16:02:56] [INFO] [system] System event: RiskEngine initialized | Component: risk_engine | Severity: INFO | Data: {"thresholds_count": 13, "rules_count": 4}
[2025-09-04 16:02:56] [INFO] [system] System event: RiskEngine initialized | Component: risk_engine | Severity: INFO | Data: {"thresholds_count": 13, "rules_count": 4}
[2025-09-04 16:02:57] [INFO] [system] System event: ML model loaded successfully | Component: fraud_ml_model | Severity: INFO | Data: {"model_path": "C:\\Users\\HP\\Desktop\\projects\\safeNetAi\\backend\\models\\fraud_isolation.joblib"}
[2025-09-04 16:02:57] [INFO] [system] System event: RiskEngine initialized | Component: risk_engine | Severity: INFO | Data: {"thresholds_count": 13, "rules_count": 4}
[2025-09-04 16:02:57] [INFO] [system] System event: RiskEngine initialized | Component: risk_engine | Severity: INFO | Data: {"thresholds_count": 13, "rules_count": 4}
[2025-09-04 16:02:57] [ERROR] [system] System event: Error making ML prediction | Component: fraud_ml_model | Severity: ERROR | Data: {"transaction_id": 322, "error": "X has 9 features, but StandardScaler is expecting 7 features as input."}
[2025-09-04 16:03:02] [INFO] [system] System event: Transaction notification sent successfully | Component: email_service | Severity: INFO | Data: {"user_email": "abassi.loay@gmail.com", "user_id": 71, "transaction_id": 322, "status": "COMPLETED", "risk_level": "LOW", "risk_score": 20}
[2025-09-04 16:03:02] [INFO] [django.server] "POST /api/client/transactions/ HTTP/1.1" 201 107
[2025-09-04 16:03:15] [INFO] [system] System event: RiskEngine initialized | Component: risk_engine | Severity: INFO | Data: {"thresholds_count": 13, "rules_count": 4}
[2025-09-04 16:03:15] [INFO] [system] System event: RiskEngine initialized | Component: risk_engine | Severity: INFO | Data: {"thresholds_count": 13, "rules_count": 4}
[2025-09-04 16:03:15] [INFO] [system] System event: ML model loaded successfully | Component: fraud_ml_model | Severity: INFO | Data: {"model_path": "C:\\Users\\HP\\Desktop\\projects\\safeNetAi\\backend\\models\\fraud_isolation.joblib"}
[2025-09-04 16:03:15] [INFO] [system] System event: RiskEngine initialized | Component: risk_engine | Severity: INFO | Data: {"thresholds_count": 13, "rules_count": 4}
[2025-09-04 16:03:15] [INFO] [system] System event: RiskEngine initialized | Component: risk_engine | Severity: INFO | Data: {"thresholds_count": 13, "rules_count": 4}
[2025-09-04 16:03:15] [ERROR] [system] System event: Error making ML prediction | Component: fraud_ml_model | Severity: ERROR | Data: {"transaction_id": 323, "error": "X has 9 features, but StandardScaler is expecting 7 features as input."}
[2025-09-04 16:03:19] [INFO] [system] System event: Security OTP email sent successfully | Component: email_service | Severity: INFO | Data: {"user_email": "abassi.loay@gmail.com", "user_id": 71, "transaction_id": 323, "otp_code": "680081"}
[2025-09-04 16:03:19] [INFO] [system] System event: Transaction OTP created and sent successfully | Component: transactions | Severity: INFO | Data: {"user_email": "abassi.loay@gmail.com", "user_id": 71, "transaction_id": 323, "otp_id": 33}
[2025-09-04 16:03:19] [WARNING] [system] System event: Transaction requires OTP verification due to risk rules or AI assessment | Component: transactions | Severity: WARNING | Data: {"transaction_id": 323, "risk_score": 75, "triggers": ["Large transfer: $5100.00 > $5000.0", "High frequency: 6 transactions in 2.0 hour(s)"], "ml_score": 0.5, "user_id": 71, "distance_violation": false, "otp_reasons": ["Business rules triggered: 2", "High risk score: 75"], "reason": "risk_rules"}
[2025-09-04 16:03:19] [INFO] [django.server] "POST /api/client/transactions/ HTTP/1.1" 201 387
[2025-09-04 16:04:22] [INFO] [django.server] "OPTIONS /api/client/transactions/323/verify_otp/ HTTP/1.1" 200 0
[2025-09-04 16:04:22] [INFO] [system] System event: Transaction OTP verified successfully | Component: transactions | Severity: INFO | Data: {"user_email": "abassi.loay@gmail.com", "user_id": 71, "transaction_id": 323, "otp_id": 33}
[2025-09-04 16:04:30] [INFO] [system] System event: Transaction notification sent successfully | Component: email_service | Severity: INFO | Data: {"user_email": "abassi.loay@gmail.com", "user_id": 71, "transaction_id": 323, "status": "COMPLETED", "risk_level": "HIGH", "risk_score": 75}
[2025-09-04 16:04:30] [INFO] [django.server] "POST /api/client/transactions/323/verify_otp/ HTTP/1.1" 200 114
[2025-09-04 16:04:36] [INFO] [django.server] "GET /api/client/profile/me/ HTTP/1.1" 200 467
[2025-09-04 16:04:36] [INFO] [django.server] "GET /api/client/profile/me/ HTTP/1.1" 200 467
[2025-09-04 16:04:36] [INFO] [django.server] "GET /api/client/transactions/ HTTP/1.1" 200 1754
[2025-09-04 16:04:36] [INFO] [django.server] "GET /api/client/transactions/ HTTP/1.1" 200 1754
